ply
format ascii 1.0
comment : MagicaVoxel @ Ephtracy
element vertex 160
property float x
property float y
property float z
property uchar red
property uchar green
property uchar blue
end_header
-2 -3 0 255 255 255
-1 -3 0 237 237 237
0 -3 0 237 237 237
1 -3 0 237 237 237
-3 -2 0 237 237 237
-2 -2 0 237 237 237
-1 -2 0 237 237 237
0 -2 0 237 237 237
1 -2 0 237 237 237
2 -2 0 237 237 237
-3 -1 0 237 237 237
-2 -1 0 237 237 237
-1 -1 0 237 237 237
0 -1 0 237 237 237
1 -1 0 237 237 237
2 -1 0 237 237 237
-3 0 0 255 255 255
-2 0 0 237 237 237
-1 0 0 237 237 237
0 0 0 237 237 237
1 0 0 237 237 237
2 0 0 255 255 255
-3 1 0 255 255 255
-2 1 0 237 237 237
-1 1 0 237 237 237
0 1 0 237 237 237
1 1 0 237 237 237
2 1 0 237 237 237
-2 2 0 237 237 237
-1 2 0 255 255 255
0 2 0 255 255 255
1 2 0 237 237 237
0 -3 1 255 255 255
-3 -2 1 255 255 255
-2 -2 1 255 255 255
-1 -2 1 237 237 237
0 -2 1 237 237 237
1 -2 1 255 255 255
-2 -1 1 237 237 237
-1 -1 1 237 237 237
0 -1 1 237 237 237
1 -1 1 237 237 237
-2 0 1 237 237 237
-1 0 1 237 237 237
0 0 1 237 237 237
1 0 1 237 237 237
2 0 1 255 255 255
-2 1 1 255 255 255
-1 1 1 237 237 237
0 1 1 237 237 237
1 1 1 237 237 237
-1 2 1 237 237 237
-1 -2 2 255 255 255
-1 -1 2 237 237 237
0 -1 2 255 255 255
-2 0 2 255 255 255
-1 0 2 237 237 237
0 0 2 237 237 237
1 0 2 255 255 255
0 1 2 255 255 255
-1 -1 3 237 237 237
0 -1 3 255 255 255
-1 0 3 237 237 237
0 0 3 237 237 237
-1 -1 4 237 237 237
0 -1 4 255 255 255
-1 0 4 237 237 237
0 0 4 255 255 255
-1 -1 5 255 255 255
0 -1 5 237 237 237
-1 0 5 255 255 255
0 0 5 237 237 237
-1 -1 6 237 237 237
0 -1 6 237 237 237
-1 0 6 255 255 255
0 0 6 255 255 255
-2 -4 7 202 78 84
-1 -4 7 237 237 237
0 -4 7 255 99 107
1 -4 7 228 88 95
-3 -3 7 228 88 95
-2 -3 7 255 99 107
-1 -3 7 255 99 107
0 -3 7 228 88 95
1 -3 7 255 99 107
2 -3 7 202 78 84
-4 -2 7 202 78 84
-3 -2 7 255 99 107
-2 -2 7 228 88 95
-1 -2 7 202 78 84
0 -2 7 228 88 95
1 -2 7 255 99 107
2 -2 7 202 78 84
3 -2 7 237 237 237
-4 -1 7 237 237 237
-3 -1 7 202 78 84
-2 -1 7 228 88 95
-1 -1 7 255 99 107
0 -1 7 255 99 107
1 -1 7 228 88 95
2 -1 7 255 99 107
3 -1 7 255 99 107
-4 0 7 255 99 107
-3 0 7 228 88 95
-2 0 7 228 88 95
-1 0 7 255 99 107
0 0 7 255 99 107
1 0 7 202 78 84
2 0 7 228 88 95
3 0 7 228 88 95
-4 1 7 228 88 95
-3 1 7 255 99 107
-2 1 7 228 88 95
-1 1 7 202 78 84
0 1 7 202 78 84
1 1 7 228 88 95
2 1 7 202 78 84
3 1 7 202 78 84
-3 2 7 228 88 95
-2 2 7 228 88 95
-1 2 7 255 99 107
0 2 7 202 78 84
1 2 7 228 88 95
2 2 7 255 99 107
-2 3 7 255 99 107
-1 3 7 202 78 84
0 3 7 228 88 95
1 3 7 237 237 237
-2 -3 8 228 88 95
-1 -3 8 202 78 84
0 -3 8 228 88 95
1 -3 8 255 99 107
-3 -2 8 255 99 107
-2 -2 8 255 255 255
-1 -2 8 237 237 237
0 -2 8 255 99 107
1 -2 8 255 255 255
2 -2 8 255 99 107
-3 -1 8 202 78 84
-2 -1 8 237 237 237
-1 -1 8 237 237 237
0 -1 8 255 99 107
1 -1 8 228 88 95
2 -1 8 202 78 84
-3 0 8 228 88 95
-2 0 8 228 88 95
-1 0 8 255 99 107
0 0 8 202 78 84
1 0 8 255 255 255
2 0 8 237 237 237
-3 1 8 255 255 255
-2 1 8 255 99 107
-1 1 8 228 88 95
0 1 8 255 99 107
1 1 8 237 237 237
2 1 8 237 237 237
-2 2 8 202 78 84
-1 2 8 237 237 237
0 2 8 255 99 107
1 2 8 228 88 95
