ply
format ascii 1.0
comment : MagicaVoxel @ Ephtracy
element vertex 17220
property float x
property float y
property float z
property uchar red
property uchar green
property uchar blue
end_header
-15 -26 6 87 87 87
-14 -26 6 87 87 87
-13 -26 6 85 85 85
-12 -26 6 85 85 85
-11 -26 6 83 83 83
-10 -26 6 87 87 87
-9 -26 6 87 87 87
-8 -26 6 83 83 83
-7 -26 6 83 83 83
-6 -26 6 85 85 85
-5 -26 6 87 87 87
-4 -26 6 85 85 85
-3 -26 6 87 87 87
-2 -26 6 83 83 83
-1 -26 6 83 83 83
0 -26 6 83 83 83
1 -26 6 87 87 87
2 -26 6 83 83 83
3 -26 6 85 85 85
4 -26 6 87 87 87
5 -26 6 85 85 85
6 -26 6 83 83 83
7 -26 6 83 83 83
8 -26 6 85 85 85
9 -26 6 85 85 85
10 -26 6 85 85 85
11 -26 6 83 83 83
12 -26 6 83 83 83
13 -26 6 85 85 85
14 -26 6 87 87 87
-15 -25 6 87 87 87
-14 -25 6 85 85 85
-13 -25 6 87 87 87
-12 -25 6 83 83 83
-11 -25 6 85 85 85
-10 -25 6 85 85 85
-9 -25 6 83 83 83
-8 -25 6 87 87 87
-7 -25 6 87 87 87
-6 -25 6 85 85 85
-5 -25 6 87 87 87
-4 -25 6 85 85 85
-3 -25 6 83 83 83
-2 -25 6 85 85 85
-1 -25 6 85 85 85
0 -25 6 83 83 83
1 -25 6 83 83 83
2 -25 6 85 85 85
3 -25 6 87 87 87
4 -25 6 87 87 87
5 -25 6 87 87 87
6 -25 6 87 87 87
7 -25 6 87 87 87
8 -25 6 87 87 87
9 -25 6 83 83 83
10 -25 6 87 87 87
11 -25 6 87 87 87
12 -25 6 85 85 85
13 -25 6 85 85 85
14 -25 6 85 85 85
-15 -24 6 85 85 85
-14 -24 6 85 85 85
-13 -24 6 87 87 87
-12 -24 6 85 85 85
-11 -24 6 83 83 83
-10 -24 6 87 87 87
-9 -24 6 83 83 83
-8 -24 6 87 87 87
-7 -24 6 85 85 85
-6 -24 6 85 85 85
-5 -24 6 87 87 87
-4 -24 6 83 83 83
-3 -24 6 87 87 87
-2 -24 6 83 83 83
-1 -24 6 87 87 87
0 -24 6 85 85 85
1 -24 6 83 83 83
2 -24 6 85 85 85
3 -24 6 85 85 85
4 -24 6 87 87 87
5 -24 6 85 85 85
6 -24 6 85 85 85
7 -24 6 83 83 83
8 -24 6 87 87 87
9 -24 6 85 85 85
10 -24 6 83 83 83
11 -24 6 87 87 87
12 -24 6 85 85 85
13 -24 6 85 85 85
14 -24 6 87 87 87
-15 -23 6 83 83 83
-14 -23 6 87 87 87
-13 -23 6 87 87 87
-12 -23 6 87 87 87
-11 -23 6 83 83 83
-10 -23 6 87 87 87
-9 -23 6 83 83 83
-8 -23 6 85 85 85
-7 -23 6 85 85 85
-6 -23 6 83 83 83
-5 -23 6 85 85 85
-4 -23 6 83 83 83
-3 -23 6 87 87 87
-2 -23 6 85 85 85
-1 -23 6 83 83 83
0 -23 6 85 85 85
1 -23 6 83 83 83
2 -23 6 87 87 87
3 -23 6 87 87 87
4 -23 6 83 83 83
5 -23 6 87 87 87
6 -23 6 87 87 87
7 -23 6 83 83 83
8 -23 6 85 85 85
9 -23 6 87 87 87
10 -23 6 87 87 87
11 -23 6 85 85 85
12 -23 6 85 85 85
13 -23 6 83 83 83
14 -23 6 85 85 85
-15 -22 6 83 83 83
-14 -22 6 83 83 83
-13 -22 6 85 85 85
-12 -22 6 83 83 83
-11 -22 6 85 85 85
-10 -22 6 87 87 87
-9 -22 6 85 85 85
-8 -22 6 87 87 87
-7 -22 6 85 85 85
-6 -22 6 87 87 87
-5 -22 6 83 83 83
-4 -22 6 87 87 87
-3 -22 6 83 83 83
-2 -22 6 83 83 83
-1 -22 6 83 83 83
0 -22 6 85 85 85
1 -22 6 87 87 87
2 -22 6 83 83 83
3 -22 6 87 87 87
4 -22 6 87 87 87
5 -22 6 85 85 85
6 -22 6 87 87 87
7 -22 6 87 87 87
8 -22 6 85 85 85
9 -22 6 87 87 87
10 -22 6 85 85 85
11 -22 6 87 87 87
12 -22 6 83 83 83
13 -22 6 87 87 87
14 -22 6 83 83 83
-15 -21 6 83 83 83
-14 -21 6 87 87 87
-13 -21 6 87 87 87
-12 -21 6 87 87 87
-11 -21 6 85 85 85
-10 -21 6 87 87 87
-9 -21 6 83 83 83
-8 -21 6 83 83 83
-7 -21 6 85 85 85
-6 -21 6 83 83 83
-5 -21 6 83 83 83
-4 -21 6 87 87 87
-3 -21 6 83 83 83
-2 -21 6 83 83 83
-1 -21 6 85 85 85
0 -21 6 87 87 87
1 -21 6 87 87 87
2 -21 6 85 85 85
3 -21 6 87 87 87
4 -21 6 85 85 85
5 -21 6 85 85 85
6 -21 6 87 87 87
7 -21 6 85 85 85
8 -21 6 83 83 83
9 -21 6 83 83 83
10 -21 6 87 87 87
11 -21 6 87 87 87
12 -21 6 85 85 85
13 -21 6 85 85 85
14 -21 6 83 83 83
-15 -20 6 85 85 85
-14 -20 6 87 87 87
-13 -20 6 83 83 83
-12 -20 6 87 87 87
-11 -20 6 87 87 87
-10 -20 6 83 83 83
-9 -20 6 85 85 85
-8 -20 6 87 87 87
-7 -20 6 83 83 83
-6 -20 6 85 85 85
-5 -20 6 83 83 83
-4 -20 6 87 87 87
-3 -20 6 85 85 85
-2 -20 6 83 83 83
-1 -20 6 87 87 87
0 -20 6 87 87 87
1 -20 6 87 87 87
2 -20 6 85 85 85
3 -20 6 83 83 83
4 -20 6 85 85 85
5 -20 6 87 87 87
6 -20 6 87 87 87
7 -20 6 83 83 83
8 -20 6 85 85 85
9 -20 6 87 87 87
10 -20 6 83 83 83
11 -20 6 85 85 85
12 -20 6 83 83 83
13 -20 6 87 87 87
14 -20 6 83 83 83
-15 -19 6 83 83 83
-14 -19 6 83 83 83
-13 -19 6 85 85 85
-12 -19 6 87 87 87
-11 -19 6 83 83 83
-10 -19 6 85 85 85
-9 -19 6 87 87 87
-8 -19 6 83 83 83
-7 -19 6 83 83 83
-6 -19 6 87 87 87
-5 -19 6 85 85 85
-4 -19 6 87 87 87
-3 -19 6 87 87 87
-2 -19 6 87 87 87
-1 -19 6 85 85 85
0 -19 6 87 87 87
1 -19 6 85 85 85
2 -19 6 85 85 85
3 -19 6 85 85 85
4 -19 6 85 85 85
5 -19 6 85 85 85
6 -19 6 87 87 87
7 -19 6 83 83 83
8 -19 6 85 85 85
9 -19 6 83 83 83
10 -19 6 85 85 85
11 -19 6 85 85 85
12 -19 6 83 83 83
13 -19 6 87 87 87
14 -19 6 83 83 83
-15 -18 6 85 85 85
-14 -18 6 87 87 87
-13 -18 6 85 85 85
-12 -18 6 83 83 83
-11 -18 6 87 87 87
-10 -18 6 83 83 83
-9 -18 6 85 85 85
-8 -18 6 87 87 87
-7 -18 6 85 85 85
-6 -18 6 83 83 83
-5 -18 6 85 85 85
-4 -18 6 85 85 85
-3 -18 6 87 87 87
-2 -18 6 83 83 83
-1 -18 6 85 85 85
0 -18 6 83 83 83
1 -18 6 83 83 83
2 -18 6 87 87 87
3 -18 6 83 83 83
4 -18 6 87 87 87
5 -18 6 83 83 83
6 -18 6 83 83 83
7 -18 6 87 87 87
8 -18 6 83 83 83
9 -18 6 83 83 83
10 -18 6 83 83 83
11 -18 6 87 87 87
12 -18 6 83 83 83
13 -18 6 85 85 85
14 -18 6 85 85 85
-15 -17 6 83 83 83
-14 -17 6 87 87 87
-13 -17 6 87 87 87
-12 -17 6 83 83 83
-11 -17 6 85 85 85
-10 -17 6 85 85 85
-9 -17 6 85 85 85
-8 -17 6 85 85 85
-7 -17 6 83 83 83
-6 -17 6 83 83 83
-5 -17 6 85 85 85
-4 -17 6 83 83 83
-3 -17 6 87 87 87
-2 -17 6 85 85 85
-1 -17 6 85 85 85
0 -17 6 85 85 85
1 -17 6 87 87 87
2 -17 6 83 83 83
3 -17 6 83 83 83
4 -17 6 85 85 85
5 -17 6 83 83 83
6 -17 6 87 87 87
7 -17 6 83 83 83
8 -17 6 87 87 87
9 -17 6 87 87 87
10 -17 6 85 85 85
11 -17 6 87 87 87
12 -17 6 83 83 83
13 -17 6 85 85 85
14 -17 6 87 87 87
-15 -16 6 85 85 85
-14 -16 6 83 83 83
-13 -16 6 83 83 83
-12 -16 6 85 85 85
-11 -16 6 85 85 85
-10 -16 6 85 85 85
-9 -16 6 87 87 87
-8 -16 6 85 85 85
-7 -16 6 87 87 87
-6 -16 6 87 87 87
-5 -16 6 83 83 83
-4 -16 6 83 83 83
-3 -16 6 87 87 87
-2 -16 6 87 87 87
-1 -16 6 87 87 87
0 -16 6 83 83 83
1 -16 6 83 83 83
2 -16 6 83 83 83
3 -16 6 83 83 83
4 -16 6 83 83 83
5 -16 6 87 87 87
6 -16 6 83 83 83
7 -16 6 87 87 87
8 -16 6 83 83 83
9 -16 6 87 87 87
10 -16 6 87 87 87
11 -16 6 87 87 87
12 -16 6 87 87 87
13 -16 6 87 87 87
14 -16 6 83 83 83
-15 -15 6 87 87 87
-14 -15 6 87 87 87
-13 -15 6 87 87 87
-12 -15 6 85 85 85
-11 -15 6 83 83 83
-10 -15 6 83 83 83
-9 -15 6 83 83 83
-8 -15 6 85 85 85
-7 -15 6 87 87 87
-6 -15 6 85 85 85
-5 -15 6 87 87 87
-4 -15 6 83 83 83
-3 -15 6 87 87 87
-2 -15 6 87 87 87
-1 -15 6 87 87 87
0 -15 6 83 83 83
1 -15 6 83 83 83
2 -15 6 87 87 87
3 -15 6 87 87 87
4 -15 6 87 87 87
5 -15 6 87 87 87
6 -15 6 85 85 85
7 -15 6 87 87 87
8 -15 6 87 87 87
9 -15 6 83 83 83
10 -15 6 83 83 83
11 -15 6 83 83 83
12 -15 6 85 85 85
13 -15 6 83 83 83
14 -15 6 85 85 85
-15 -14 6 87 87 87
-14 -14 6 87 87 87
-13 -14 6 87 87 87
-12 -14 6 87 87 87
-11 -14 6 87 87 87
-10 -14 6 87 87 87
-9 -14 6 83 83 83
-8 -14 6 83 83 83
-7 -14 6 83 83 83
-6 -14 6 85 85 85
-5 -14 6 85 85 85
-4 -14 6 85 85 85
-3 -14 6 85 85 85
-2 -14 6 87 87 87
-1 -14 6 83 83 83
0 -14 6 87 87 87
1 -14 6 83 83 83
2 -14 6 83 83 83
3 -14 6 85 85 85
4 -14 6 87 87 87
5 -14 6 87 87 87
6 -14 6 85 85 85
7 -14 6 83 83 83
8 -14 6 85 85 85
9 -14 6 87 87 87
10 -14 6 85 85 85
11 -14 6 87 87 87
12 -14 6 85 85 85
13 -14 6 87 87 87
14 -14 6 85 85 85
-15 -13 6 87 87 87
-14 -13 6 85 85 85
-13 -13 6 85 85 85
-12 -13 6 83 83 83
-11 -13 6 83 83 83
-10 -13 6 87 87 87
-9 -13 6 85 85 85
-8 -13 6 85 85 85
-7 -13 6 87 87 87
-6 -13 6 83 83 83
-5 -13 6 85 85 85
-4 -13 6 83 83 83
-3 -13 6 87 87 87
-2 -13 6 87 87 87
-1 -13 6 87 87 87
0 -13 6 83 83 83
1 -13 6 87 87 87
2 -13 6 85 85 85
3 -13 6 83 83 83
4 -13 6 87 87 87
5 -13 6 87 87 87
6 -13 6 87 87 87
7 -13 6 83 83 83
8 -13 6 83 83 83
9 -13 6 85 85 85
10 -13 6 85 85 85
11 -13 6 83 83 83
12 -13 6 83 83 83
13 -13 6 85 85 85
14 -13 6 85 85 85
-15 -12 6 83 83 83
-14 -12 6 85 85 85
-13 -12 6 87 87 87
-12 -12 6 85 85 85
-11 -12 6 87 87 87
-10 -12 6 87 87 87
-9 -12 6 87 87 87
-8 -12 6 83 83 83
-7 -12 6 85 85 85
-6 -12 6 83 83 83
-5 -12 6 87 87 87
-4 -12 6 87 87 87
-3 -12 6 87 87 87
-2 -12 6 87 87 87
-1 -12 6 87 87 87
0 -12 6 85 85 85
1 -12 6 85 85 85
2 -12 6 85 85 85
3 -12 6 87 87 87
4 -12 6 83 83 83
5 -12 6 83 83 83
6 -12 6 87 87 87
7 -12 6 83 83 83
8 -12 6 83 83 83
9 -12 6 85 85 85
10 -12 6 85 85 85
11 -12 6 87 87 87
12 -12 6 87 87 87
13 -12 6 85 85 85
14 -12 6 83 83 83
-15 -11 6 83 83 83
-14 -11 6 87 87 87
-13 -11 6 87 87 87
-12 -11 6 87 87 87
-11 -11 6 85 85 85
-10 -11 6 85 85 85
-9 -11 6 87 87 87
-8 -11 6 85 85 85
-7 -11 6 87 87 87
-6 -11 6 85 85 85
-5 -11 6 87 87 87
-4 -11 6 87 87 87
-3 -11 6 83 83 83
-2 -11 6 85 85 85
-1 -11 6 83 83 83
0 -11 6 83 83 83
1 -11 6 87 87 87
2 -11 6 87 87 87
3 -11 6 83 83 83
4 -11 6 83 83 83
5 -11 6 83 83 83
6 -11 6 85 85 85
7 -11 6 87 87 87
8 -11 6 87 87 87
9 -11 6 85 85 85
10 -11 6 87 87 87
11 -11 6 87 87 87
12 -11 6 85 85 85
13 -11 6 85 85 85
14 -11 6 85 85 85
-15 -10 6 87 87 87
-14 -10 6 85 85 85
-13 -10 6 85 85 85
-12 -10 6 87 87 87
-11 -10 6 85 85 85
-10 -10 6 83 83 83
-9 -10 6 87 87 87
-8 -10 6 85 85 85
-7 -10 6 87 87 87
-6 -10 6 87 87 87
-5 -10 6 85 85 85
-4 -10 6 85 85 85
-3 -10 6 83 83 83
-2 -10 6 85 85 85
-1 -10 6 83 83 83
0 -10 6 85 85 85
1 -10 6 87 87 87
2 -10 6 87 87 87
3 -10 6 87 87 87
4 -10 6 83 83 83
5 -10 6 83 83 83
6 -10 6 83 83 83
7 -10 6 83 83 83
8 -10 6 83 83 83
9 -10 6 83 83 83
10 -10 6 87 87 87
11 -10 6 83 83 83
12 -10 6 85 85 85
13 -10 6 87 87 87
14 -10 6 85 85 85
-15 -9 6 87 87 87
-14 -9 6 87 87 87
-13 -9 6 83 83 83
-12 -9 6 83 83 83
-11 -9 6 87 87 87
-10 -9 6 83 83 83
-9 -9 6 87 87 87
-8 -9 6 85 85 85
-7 -9 6 85 85 85
-6 -9 6 87 87 87
-5 -9 6 87 87 87
-4 -9 6 87 87 87
-3 -9 6 85 85 85
-2 -9 6 83 83 83
-1 -9 6 87 87 87
0 -9 6 87 87 87
1 -9 6 83 83 83
2 -9 6 87 87 87
3 -9 6 87 87 87
4 -9 6 83 83 83
5 -9 6 85 85 85
6 -9 6 83 83 83
7 -9 6 85 85 85
8 -9 6 87 87 87
9 -9 6 85 85 85
10 -9 6 83 83 83
11 -9 6 85 85 85
12 -9 6 85 85 85
13 -9 6 87 87 87
14 -9 6 87 87 87
-15 -8 6 83 83 83
-14 -8 6 85 85 85
-13 -8 6 85 85 85
-12 -8 6 85 85 85
-11 -8 6 85 85 85
-10 -8 6 83 83 83
-9 -8 6 85 85 85
-8 -8 6 87 87 87
-7 -8 6 87 87 87
-6 -8 6 87 87 87
-5 -8 6 85 85 85
-4 -8 6 85 85 85
-3 -8 6 87 87 87
-2 -8 6 85 85 85
-1 -8 6 87 87 87
0 -8 6 87 87 87
1 -8 6 85 85 85
2 -8 6 87 87 87
3 -8 6 83 83 83
4 -8 6 87 87 87
5 -8 6 83 83 83
6 -8 6 87 87 87
7 -8 6 87 87 87
8 -8 6 87 87 87
9 -8 6 85 85 85
10 -8 6 87 87 87
11 -8 6 87 87 87
12 -8 6 85 85 85
13 -8 6 87 87 87
14 -8 6 87 87 87
-15 -7 6 85 85 85
-14 -7 6 87 87 87
-13 -7 6 87 87 87
-12 -7 6 87 87 87
-11 -7 6 85 85 85
-10 -7 6 87 87 87
-9 -7 6 87 87 87
-8 -7 6 85 85 85
-7 -7 6 83 83 83
-6 -7 6 85 85 85
-5 -7 6 85 85 85
-4 -7 6 85 85 85
-3 -7 6 87 87 87
-2 -7 6 87 87 87
-1 -7 6 83 83 83
0 -7 6 87 87 87
1 -7 6 83 83 83
2 -7 6 83 83 83
3 -7 6 85 85 85
4 -7 6 85 85 85
5 -7 6 85 85 85
6 -7 6 85 85 85
7 -7 6 85 85 85
8 -7 6 83 83 83
9 -7 6 85 85 85
10 -7 6 83 83 83
11 -7 6 85 85 85
12 -7 6 87 87 87
13 -7 6 87 87 87
14 -7 6 85 85 85
-15 -6 6 85 85 85
-14 -6 6 87 87 87
-13 -6 6 87 87 87
-12 -6 6 87 87 87
-11 -6 6 85 85 85
-10 -6 6 85 85 85
-9 -6 6 87 87 87
-8 -6 6 85 85 85
-7 -6 6 85 85 85
-6 -6 6 87 87 87
-5 -6 6 85 85 85
-4 -6 6 85 85 85
-3 -6 6 85 85 85
-2 -6 6 83 83 83
-1 -6 6 83 83 83
0 -6 6 85 85 85
1 -6 6 87 87 87
2 -6 6 87 87 87
3 -6 6 85 85 85
4 -6 6 85 85 85
5 -6 6 83 83 83
6 -6 6 87 87 87
7 -6 6 83 83 83
8 -6 6 87 87 87
9 -6 6 83 83 83
10 -6 6 85 85 85
11 -6 6 85 85 85
12 -6 6 85 85 85
13 -6 6 83 83 83
14 -6 6 85 85 85
-15 -5 6 87 87 87
-14 -5 6 83 83 83
-13 -5 6 87 87 87
-12 -5 6 85 85 85
-11 -5 6 87 87 87
-10 -5 6 87 87 87
-9 -5 6 85 85 85
-8 -5 6 85 85 85
-7 -5 6 83 83 83
-6 -5 6 83 83 83
-5 -5 6 85 85 85
-4 -5 6 87 87 87
-3 -5 6 83 83 83
-2 -5 6 85 85 85
-1 -5 6 83 83 83
0 -5 6 85 85 85
1 -5 6 85 85 85
2 -5 6 83 83 83
3 -5 6 83 83 83
4 -5 6 85 85 85
5 -5 6 85 85 85
6 -5 6 85 85 85
7 -5 6 85 85 85
8 -5 6 83 83 83
9 -5 6 85 85 85
10 -5 6 87 87 87
11 -5 6 85 85 85
12 -5 6 83 83 83
13 -5 6 85 85 85
14 -5 6 85 85 85
-15 -4 6 87 87 87
-14 -4 6 87 87 87
-13 -4 6 85 85 85
-12 -4 6 85 85 85
-11 -4 6 83 83 83
-10 -4 6 87 87 87
-9 -4 6 87 87 87
-8 -4 6 87 87 87
-7 -4 6 85 85 85
-6 -4 6 85 85 85
-5 -4 6 87 87 87
-4 -4 6 83 83 83
-3 -4 6 85 85 85
-2 -4 6 85 85 85
-1 -4 6 83 83 83
0 -4 6 87 87 87
1 -4 6 83 83 83
2 -4 6 83 83 83
3 -4 6 85 85 85
4 -4 6 83 83 83
5 -4 6 87 87 87
6 -4 6 87 87 87
7 -4 6 83 83 83
8 -4 6 83 83 83
9 -4 6 83 83 83
10 -4 6 87 87 87
11 -4 6 87 87 87
12 -4 6 85 85 85
13 -4 6 83 83 83
14 -4 6 85 85 85
-15 -3 6 83 83 83
-14 -3 6 83 83 83
-13 -3 6 87 87 87
-12 -3 6 85 85 85
-11 -3 6 87 87 87
-10 -3 6 87 87 87
-9 -3 6 83 83 83
-8 -3 6 85 85 85
-7 -3 6 85 85 85
-6 -3 6 83 83 83
-5 -3 6 85 85 85
-4 -3 6 85 85 85
-3 -3 6 85 85 85
-2 -3 6 85 85 85
-1 -3 6 85 85 85
0 -3 6 85 85 85
1 -3 6 83 83 83
2 -3 6 87 87 87
3 -3 6 83 83 83
4 -3 6 87 87 87
5 -3 6 83 83 83
6 -3 6 83 83 83
7 -3 6 83 83 83
8 -3 6 87 87 87
9 -3 6 83 83 83
10 -3 6 85 85 85
11 -3 6 87 87 87
12 -3 6 83 83 83
13 -3 6 85 85 85
14 -3 6 87 87 87
-15 -2 6 85 85 85
-14 -2 6 87 87 87
-13 -2 6 85 85 85
-12 -2 6 85 85 85
-11 -2 6 85 85 85
-10 -2 6 85 85 85
-9 -2 6 83 83 83
-8 -2 6 83 83 83
-7 -2 6 83 83 83
-6 -2 6 85 85 85
-5 -2 6 85 85 85
-4 -2 6 85 85 85
-3 -2 6 83 83 83
-2 -2 6 85 85 85
-1 -2 6 85 85 85
0 -2 6 87 87 87
1 -2 6 85 85 85
2 -2 6 87 87 87
3 -2 6 87 87 87
4 -2 6 85 85 85
5 -2 6 85 85 85
6 -2 6 85 85 85
7 -2 6 85 85 85
8 -2 6 85 85 85
9 -2 6 87 87 87
10 -2 6 87 87 87
11 -2 6 85 85 85
12 -2 6 85 85 85
13 -2 6 85 85 85
14 -2 6 83 83 83
-15 -1 6 83 83 83
-14 -1 6 83 83 83
-13 -1 6 85 85 85
-12 -1 6 83 83 83
-11 -1 6 87 87 87
-10 -1 6 85 85 85
-9 -1 6 83 83 83
-8 -1 6 83 83 83
-7 -1 6 85 85 85
-6 -1 6 87 87 87
-5 -1 6 87 87 87
-4 -1 6 83 83 83
-3 -1 6 87 87 87
-2 -1 6 83 83 83
-1 -1 6 83 83 83
0 -1 6 87 87 87
1 -1 6 83 83 83
2 -1 6 87 87 87
3 -1 6 85 85 85
4 -1 6 87 87 87
5 -1 6 87 87 87
6 -1 6 87 87 87
7 -1 6 85 85 85
8 -1 6 83 83 83
9 -1 6 83 83 83
10 -1 6 87 87 87
11 -1 6 83 83 83
12 -1 6 85 85 85
13 -1 6 85 85 85
14 -1 6 85 85 85
-15 0 6 83 83 83
-14 0 6 83 83 83
-13 0 6 85 85 85
-12 0 6 87 87 87
-11 0 6 87 87 87
-10 0 6 83 83 83
-9 0 6 87 87 87
-8 0 6 85 85 85
-7 0 6 83 83 83
-6 0 6 87 87 87
-5 0 6 85 85 85
-4 0 6 87 87 87
-3 0 6 87 87 87
-2 0 6 87 87 87
-1 0 6 85 85 85
0 0 6 83 83 83
1 0 6 85 85 85
2 0 6 87 87 87
3 0 6 83 83 83
4 0 6 85 85 85
5 0 6 83 83 83
6 0 6 85 85 85
7 0 6 87 87 87
8 0 6 85 85 85
9 0 6 85 85 85
10 0 6 87 87 87
11 0 6 85 85 85
12 0 6 83 83 83
13 0 6 85 85 85
14 0 6 87 87 87
-15 1 6 83 83 83
-14 1 6 83 83 83
-13 1 6 87 87 87
-12 1 6 85 85 85
-11 1 6 85 85 85
-10 1 6 87 87 87
-9 1 6 87 87 87
-8 1 6 83 83 83
-7 1 6 87 87 87
-6 1 6 85 85 85
-5 1 6 85 85 85
-4 1 6 85 85 85
-3 1 6 83 83 83
-2 1 6 85 85 85
-1 1 6 83 83 83
0 1 6 85 85 85
1 1 6 83 83 83
2 1 6 83 83 83
3 1 6 87 87 87
4 1 6 87 87 87
5 1 6 87 87 87
6 1 6 83 83 83
7 1 6 87 87 87
8 1 6 87 87 87
9 1 6 87 87 87
10 1 6 83 83 83
11 1 6 87 87 87
12 1 6 85 85 85
13 1 6 83 83 83
14 1 6 87 87 87
-15 2 6 85 85 85
-14 2 6 87 87 87
-13 2 6 83 83 83
-12 2 6 83 83 83
-11 2 6 87 87 87
-10 2 6 85 85 85
-9 2 6 83 83 83
-8 2 6 85 85 85
-7 2 6 87 87 87
-6 2 6 87 87 87
-5 2 6 85 85 85
-4 2 6 83 83 83
-3 2 6 83 83 83
-2 2 6 85 85 85
-1 2 6 83 83 83
0 2 6 85 85 85
1 2 6 85 85 85
2 2 6 87 87 87
3 2 6 87 87 87
4 2 6 87 87 87
5 2 6 83 83 83
6 2 6 83 83 83
7 2 6 85 85 85
8 2 6 87 87 87
9 2 6 87 87 87
10 2 6 83 83 83
11 2 6 87 87 87
12 2 6 85 85 85
13 2 6 87 87 87
14 2 6 83 83 83
-15 3 6 87 87 87
-14 3 6 85 85 85
-13 3 6 87 87 87
-12 3 6 87 87 87
-11 3 6 83 83 83
-10 3 6 85 85 85
-9 3 6 83 83 83
-8 3 6 83 83 83
-7 3 6 85 85 85
-6 3 6 85 85 85
-5 3 6 85 85 85
-4 3 6 85 85 85
-3 3 6 87 87 87
-2 3 6 83 83 83
-1 3 6 87 87 87
0 3 6 83 83 83
1 3 6 87 87 87
2 3 6 85 85 85
3 3 6 85 85 85
4 3 6 87 87 87
5 3 6 87 87 87
6 3 6 83 83 83
7 3 6 85 85 85
8 3 6 87 87 87
9 3 6 87 87 87
10 3 6 87 87 87
11 3 6 87 87 87
12 3 6 85 85 85
13 3 6 83 83 83
14 3 6 85 85 85
-15 4 6 83 83 83
-14 4 6 87 87 87
-13 4 6 83 83 83
-12 4 6 85 85 85
-11 4 6 85 85 85
-10 4 6 87 87 87
-9 4 6 87 87 87
-8 4 6 85 85 85
-7 4 6 87 87 87
-6 4 6 83 83 83
-5 4 6 85 85 85
-4 4 6 87 87 87
-3 4 6 87 87 87
-2 4 6 85 85 85
-1 4 6 85 85 85
0 4 6 85 85 85
1 4 6 87 87 87
2 4 6 85 85 85
3 4 6 87 87 87
4 4 6 83 83 83
5 4 6 87 87 87
6 4 6 87 87 87
7 4 6 87 87 87
8 4 6 85 85 85
9 4 6 87 87 87
10 4 6 83 83 83
11 4 6 85 85 85
12 4 6 83 83 83
13 4 6 87 87 87
14 4 6 87 87 87
-15 5 6 83 83 83
-14 5 6 83 83 83
-13 5 6 83 83 83
-12 5 6 87 87 87
-11 5 6 85 85 85
-10 5 6 85 85 85
-9 5 6 83 83 83
-8 5 6 87 87 87
-7 5 6 87 87 87
-6 5 6 85 85 85
-5 5 6 85 85 85
-4 5 6 87 87 87
-3 5 6 83 83 83
-2 5 6 85 85 85
-1 5 6 87 87 87
0 5 6 85 85 85
1 5 6 87 87 87
2 5 6 85 85 85
3 5 6 85 85 85
4 5 6 83 83 83
5 5 6 87 87 87
6 5 6 87 87 87
7 5 6 87 87 87
8 5 6 87 87 87
9 5 6 85 85 85
10 5 6 85 85 85
11 5 6 85 85 85
12 5 6 87 87 87
13 5 6 87 87 87
14 5 6 87 87 87
-15 6 6 85 85 85
-14 6 6 83 83 83
-13 6 6 85 85 85
-12 6 6 83 83 83
-11 6 6 85 85 85
-10 6 6 85 85 85
-9 6 6 87 87 87
-8 6 6 87 87 87
-7 6 6 87 87 87
-6 6 6 85 85 85
-5 6 6 85 85 85
-4 6 6 85 85 85
-3 6 6 83 83 83
-2 6 6 85 85 85
-1 6 6 83 83 83
0 6 6 83 83 83
1 6 6 87 87 87
2 6 6 87 87 87
3 6 6 85 85 85
4 6 6 85 85 85
5 6 6 85 85 85
6 6 6 83 83 83
7 6 6 85 85 85
8 6 6 83 83 83
9 6 6 85 85 85
10 6 6 87 87 87
11 6 6 87 87 87
12 6 6 87 87 87
13 6 6 83 83 83
14 6 6 85 85 85
-15 7 6 87 87 87
-14 7 6 85 85 85
-13 7 6 87 87 87
-12 7 6 85 85 85
-11 7 6 85 85 85
-10 7 6 85 85 85
-9 7 6 85 85 85
-8 7 6 85 85 85
-7 7 6 87 87 87
-6 7 6 87 87 87
-5 7 6 85 85 85
-4 7 6 83 83 83
-3 7 6 87 87 87
-2 7 6 87 87 87
-1 7 6 87 87 87
0 7 6 87 87 87
1 7 6 87 87 87
2 7 6 83 83 83
3 7 6 83 83 83
4 7 6 85 85 85
5 7 6 83 83 83
6 7 6 83 83 83
7 7 6 85 85 85
8 7 6 85 85 85
9 7 6 85 85 85
10 7 6 85 85 85
11 7 6 83 83 83
12 7 6 87 87 87
13 7 6 85 85 85
14 7 6 85 85 85
-15 8 6 87 87 87
-14 8 6 87 87 87
-13 8 6 87 87 87
-12 8 6 83 83 83
-11 8 6 83 83 83
-10 8 6 87 87 87
-9 8 6 85 85 85
-8 8 6 85 85 85
-7 8 6 85 85 85
-6 8 6 85 85 85
-5 8 6 87 87 87
-4 8 6 87 87 87
-3 8 6 87 87 87
-2 8 6 85 85 85
-1 8 6 85 85 85
0 8 6 87 87 87
1 8 6 85 85 85
2 8 6 85 85 85
3 8 6 87 87 87
4 8 6 83 83 83
5 8 6 85 85 85
6 8 6 85 85 85
7 8 6 83 83 83
8 8 6 83 83 83
9 8 6 87 87 87
10 8 6 85 85 85
11 8 6 87 87 87
12 8 6 87 87 87
13 8 6 87 87 87
14 8 6 85 85 85
-15 9 6 85 85 85
-14 9 6 87 87 87
-13 9 6 85 85 85
-12 9 6 83 83 83
-11 9 6 83 83 83
-10 9 6 85 85 85
-9 9 6 85 85 85
-8 9 6 83 83 83
-7 9 6 85 85 85
-6 9 6 87 87 87
-5 9 6 87 87 87
-4 9 6 87 87 87
-3 9 6 83 83 83
-2 9 6 85 85 85
-1 9 6 87 87 87
0 9 6 87 87 87
1 9 6 83 83 83
2 9 6 83 83 83
3 9 6 87 87 87
4 9 6 83 83 83
5 9 6 87 87 87
6 9 6 83 83 83
7 9 6 85 85 85
8 9 6 85 85 85
9 9 6 85 85 85
10 9 6 83 83 83
11 9 6 87 87 87
12 9 6 87 87 87
13 9 6 85 85 85
14 9 6 83 83 83
-15 10 6 85 85 85
-14 10 6 85 85 85
-13 10 6 85 85 85
-12 10 6 85 85 85
-11 10 6 83 83 83
-10 10 6 87 87 87
-9 10 6 87 87 87
-8 10 6 87 87 87
-7 10 6 83 83 83
-6 10 6 85 85 85
-5 10 6 83 83 83
-4 10 6 85 85 85
-3 10 6 87 87 87
-2 10 6 87 87 87
-1 10 6 85 85 85
0 10 6 85 85 85
1 10 6 83 83 83
2 10 6 87 87 87
3 10 6 87 87 87
4 10 6 87 87 87
5 10 6 83 83 83
6 10 6 85 85 85
7 10 6 85 85 85
8 10 6 85 85 85
9 10 6 87 87 87
10 10 6 87 87 87
11 10 6 87 87 87
12 10 6 87 87 87
13 10 6 87 87 87
14 10 6 87 87 87
-15 11 6 87 87 87
-14 11 6 85 85 85
-13 11 6 87 87 87
-12 11 6 87 87 87
-11 11 6 87 87 87
-10 11 6 87 87 87
-9 11 6 87 87 87
-8 11 6 83 83 83
-7 11 6 83 83 83
-6 11 6 85 85 85
-5 11 6 85 85 85
-4 11 6 87 87 87
-3 11 6 83 83 83
-2 11 6 85 85 85
-1 11 6 85 85 85
0 11 6 85 85 85
1 11 6 87 87 87
2 11 6 83 83 83
3 11 6 83 83 83
4 11 6 83 83 83
5 11 6 85 85 85
6 11 6 87 87 87
7 11 6 85 85 85
8 11 6 87 87 87
9 11 6 85 85 85
10 11 6 85 85 85
11 11 6 85 85 85
12 11 6 87 87 87
13 11 6 85 85 85
14 11 6 87 87 87
-15 12 6 83 83 83
-14 12 6 87 87 87
-13 12 6 85 85 85
-12 12 6 83 83 83
-11 12 6 87 87 87
-10 12 6 83 83 83
-9 12 6 87 87 87
-8 12 6 83 83 83
-7 12 6 87 87 87
-6 12 6 87 87 87
-5 12 6 87 87 87
-4 12 6 83 83 83
-3 12 6 83 83 83
-2 12 6 87 87 87
-1 12 6 83 83 83
0 12 6 85 85 85
1 12 6 83 83 83
2 12 6 83 83 83
3 12 6 83 83 83
4 12 6 85 85 85
5 12 6 83 83 83
6 12 6 83 83 83
7 12 6 87 87 87
8 12 6 87 87 87
9 12 6 83 83 83
10 12 6 87 87 87
11 12 6 87 87 87
12 12 6 83 83 83
13 12 6 87 87 87
14 12 6 83 83 83
-15 13 6 85 85 85
-14 13 6 85 85 85
-13 13 6 87 87 87
-12 13 6 85 85 85
-11 13 6 85 85 85
-10 13 6 83 83 83
-9 13 6 83 83 83
-8 13 6 87 87 87
-7 13 6 87 87 87
-6 13 6 85 85 85
-5 13 6 85 85 85
-4 13 6 85 85 85
-3 13 6 83 83 83
-2 13 6 87 87 87
-1 13 6 83 83 83
0 13 6 87 87 87
1 13 6 87 87 87
2 13 6 87 87 87
3 13 6 83 83 83
4 13 6 85 85 85
5 13 6 85 85 85
6 13 6 87 87 87
7 13 6 83 83 83
8 13 6 83 83 83
9 13 6 87 87 87
10 13 6 87 87 87
11 13 6 83 83 83
12 13 6 85 85 85
13 13 6 85 85 85
14 13 6 85 85 85
-15 14 6 83 83 83
-14 14 6 85 85 85
-13 14 6 87 87 87
-12 14 6 85 85 85
-11 14 6 85 85 85
-10 14 6 83 83 83
-9 14 6 87 87 87
-8 14 6 85 85 85
-7 14 6 87 87 87
-6 14 6 85 85 85
-5 14 6 87 87 87
-4 14 6 83 83 83
-3 14 6 83 83 83
-2 14 6 85 85 85
-1 14 6 87 87 87
0 14 6 83 83 83
1 14 6 83 83 83
2 14 6 83 83 83
3 14 6 87 87 87
4 14 6 87 87 87
5 14 6 83 83 83
6 14 6 87 87 87
7 14 6 87 87 87
8 14 6 83 83 83
9 14 6 83 83 83
10 14 6 87 87 87
11 14 6 83 83 83
12 14 6 83 83 83
13 14 6 83 83 83
14 14 6 87 87 87
-15 15 6 87 87 87
-14 15 6 87 87 87
-13 15 6 83 83 83
-12 15 6 85 85 85
-11 15 6 85 85 85
-10 15 6 83 83 83
-9 15 6 87 87 87
-8 15 6 87 87 87
-7 15 6 85 85 85
-6 15 6 83 83 83
-5 15 6 85 85 85
-4 15 6 83 83 83
-3 15 6 85 85 85
-2 15 6 87 87 87
-1 15 6 85 85 85
0 15 6 87 87 87
1 15 6 83 83 83
2 15 6 83 83 83
3 15 6 83 83 83
4 15 6 87 87 87
5 15 6 85 85 85
6 15 6 87 87 87
7 15 6 87 87 87
8 15 6 87 87 87
9 15 6 83 83 83
10 15 6 83 83 83
11 15 6 85 85 85
12 15 6 87 87 87
13 15 6 87 87 87
14 15 6 87 87 87
-15 16 6 83 83 83
-14 16 6 83 83 83
-13 16 6 87 87 87
-12 16 6 87 87 87
-11 16 6 85 85 85
-10 16 6 85 85 85
-9 16 6 83 83 83
-8 16 6 83 83 83
-7 16 6 83 83 83
-6 16 6 85 85 85
-5 16 6 85 85 85
-4 16 6 87 87 87
-3 16 6 87 87 87
-2 16 6 87 87 87
-1 16 6 87 87 87
0 16 6 85 85 85
1 16 6 85 85 85
2 16 6 85 85 85
3 16 6 83 83 83
4 16 6 85 85 85
5 16 6 87 87 87
6 16 6 87 87 87
7 16 6 87 87 87
8 16 6 87 87 87
9 16 6 83 83 83
10 16 6 87 87 87
11 16 6 85 85 85
12 16 6 87 87 87
13 16 6 87 87 87
14 16 6 85 85 85
-15 17 6 83 83 83
-14 17 6 85 85 85
-13 17 6 87 87 87
-12 17 6 87 87 87
-11 17 6 83 83 83
-10 17 6 85 85 85
-9 17 6 87 87 87
-8 17 6 87 87 87
-7 17 6 85 85 85
-6 17 6 87 87 87
-5 17 6 87 87 87
-4 17 6 87 87 87
-3 17 6 83 83 83
-2 17 6 85 85 85
-1 17 6 83 83 83
0 17 6 83 83 83
1 17 6 87 87 87
2 17 6 85 85 85
3 17 6 83 83 83
4 17 6 83 83 83
5 17 6 83 83 83
6 17 6 87 87 87
7 17 6 83 83 83
8 17 6 85 85 85
9 17 6 83 83 83
10 17 6 87 87 87
11 17 6 83 83 83
12 17 6 83 83 83
13 17 6 83 83 83
14 17 6 85 85 85
-15 18 6 85 85 85
-14 18 6 85 85 85
-13 18 6 87 87 87
-12 18 6 85 85 85
-11 18 6 87 87 87
-10 18 6 85 85 85
-9 18 6 83 83 83
-8 18 6 83 83 83
-7 18 6 83 83 83
-6 18 6 87 87 87
-5 18 6 85 85 85
-4 18 6 83 83 83
-3 18 6 85 85 85
-2 18 6 83 83 83
-1 18 6 87 87 87
0 18 6 87 87 87
1 18 6 85 85 85
2 18 6 83 83 83
3 18 6 83 83 83
4 18 6 83 83 83
5 18 6 83 83 83
6 18 6 87 87 87
7 18 6 87 87 87
8 18 6 85 85 85
9 18 6 87 87 87
10 18 6 87 87 87
11 18 6 85 85 85
12 18 6 85 85 85
13 18 6 87 87 87
14 18 6 87 87 87
-15 19 6 85 85 85
-14 19 6 85 85 85
-13 19 6 83 83 83
-12 19 6 83 83 83
-11 19 6 85 85 85
-10 19 6 87 87 87
-9 19 6 87 87 87
-8 19 6 87 87 87
-7 19 6 85 85 85
-6 19 6 83 83 83
-5 19 6 83 83 83
-4 19 6 85 85 85
-3 19 6 87 87 87
-2 19 6 85 85 85
-1 19 6 83 83 83
0 19 6 87 87 87
1 19 6 87 87 87
2 19 6 87 87 87
3 19 6 85 85 85
4 19 6 83 83 83
5 19 6 83 83 83
6 19 6 83 83 83
7 19 6 87 87 87
8 19 6 83 83 83
9 19 6 87 87 87
10 19 6 87 87 87
11 19 6 83 83 83
12 19 6 85 85 85
13 19 6 83 83 83
14 19 6 85 85 85
-15 20 6 85 85 85
-14 20 6 87 87 87
-13 20 6 87 87 87
-12 20 6 85 85 85
-11 20 6 85 85 85
-10 20 6 85 85 85
-9 20 6 83 83 83
-8 20 6 83 83 83
-7 20 6 83 83 83
-6 20 6 85 85 85
-5 20 6 83 83 83
-4 20 6 83 83 83
-3 20 6 85 85 85
-2 20 6 85 85 85
-1 20 6 85 85 85
0 20 6 83 83 83
1 20 6 87 87 87
2 20 6 85 85 85
3 20 6 83 83 83
4 20 6 85 85 85
5 20 6 83 83 83
6 20 6 87 87 87
7 20 6 83 83 83
8 20 6 83 83 83
9 20 6 87 87 87
10 20 6 85 85 85
11 20 6 87 87 87
12 20 6 83 83 83
13 20 6 83 83 83
14 20 6 83 83 83
-15 21 6 83 83 83
-14 21 6 83 83 83
-13 21 6 85 85 85
-12 21 6 83 83 83
-11 21 6 85 85 85
-10 21 6 83 83 83
-9 21 6 85 85 85
-8 21 6 83 83 83
-7 21 6 85 85 85
-6 21 6 87 87 87
-5 21 6 87 87 87
-4 21 6 83 83 83
-3 21 6 83 83 83
-2 21 6 83 83 83
-1 21 6 83 83 83
0 21 6 87 87 87
1 21 6 83 83 83
2 21 6 87 87 87
3 21 6 85 85 85
4 21 6 85 85 85
5 21 6 85 85 85
6 21 6 85 85 85
7 21 6 83 83 83
8 21 6 83 83 83
9 21 6 83 83 83
10 21 6 83 83 83
11 21 6 87 87 87
12 21 6 87 87 87
13 21 6 87 87 87
14 21 6 85 85 85
-15 22 6 87 87 87
-14 22 6 83 83 83
-13 22 6 85 85 85
-12 22 6 83 83 83
-11 22 6 83 83 83
-10 22 6 85 85 85
-9 22 6 87 87 87
-8 22 6 85 85 85
-7 22 6 87 87 87
-6 22 6 85 85 85
-5 22 6 85 85 85
-4 22 6 83 83 83
-3 22 6 85 85 85
-2 22 6 87 87 87
-1 22 6 85 85 85
0 22 6 85 85 85
1 22 6 85 85 85
2 22 6 85 85 85
3 22 6 85 85 85
4 22 6 87 87 87
5 22 6 85 85 85
6 22 6 85 85 85
7 22 6 83 83 83
8 22 6 85 85 85
9 22 6 83 83 83
10 22 6 83 83 83
11 22 6 87 87 87
12 22 6 85 85 85
13 22 6 83 83 83
14 22 6 83 83 83
-15 23 6 83 83 83
-14 23 6 83 83 83
-13 23 6 85 85 85
-12 23 6 83 83 83
-11 23 6 85 85 85
-10 23 6 87 87 87
-9 23 6 87 87 87
-8 23 6 85 85 85
-7 23 6 83 83 83
-6 23 6 85 85 85
-5 23 6 83 83 83
-4 23 6 85 85 85
-3 23 6 83 83 83
-2 23 6 85 85 85
-1 23 6 85 85 85
0 23 6 85 85 85
1 23 6 83 83 83
2 23 6 85 85 85
3 23 6 83 83 83
4 23 6 83 83 83
5 23 6 83 83 83
6 23 6 83 83 83
7 23 6 83 83 83
8 23 6 87 87 87
9 23 6 87 87 87
10 23 6 83 83 83
11 23 6 87 87 87
12 23 6 83 83 83
13 23 6 87 87 87
14 23 6 87 87 87
-15 24 6 83 83 83
-14 24 6 87 87 87
-13 24 6 83 83 83
-12 24 6 85 85 85
-11 24 6 87 87 87
-10 24 6 85 85 85
-9 24 6 87 87 87
-8 24 6 87 87 87
-7 24 6 87 87 87
-6 24 6 87 87 87
-5 24 6 87 87 87
-4 24 6 85 85 85
-3 24 6 85 85 85
-2 24 6 87 87 87
-1 24 6 83 83 83
0 24 6 83 83 83
1 24 6 83 83 83
2 24 6 85 85 85
3 24 6 87 87 87
4 24 6 85 85 85
5 24 6 87 87 87
6 24 6 87 87 87
7 24 6 83 83 83
8 24 6 85 85 85
9 24 6 83 83 83
10 24 6 83 83 83
11 24 6 87 87 87
12 24 6 83 83 83
13 24 6 87 87 87
14 24 6 83 83 83
-15 25 6 85 85 85
-14 25 6 83 83 83
-13 25 6 87 87 87
-12 25 6 83 83 83
-11 25 6 85 85 85
-10 25 6 85 85 85
-9 25 6 87 87 87
-8 25 6 87 87 87
-7 25 6 85 85 85
-6 25 6 87 87 87
-5 25 6 87 87 87
-4 25 6 85 85 85
-3 25 6 83 83 83
-2 25 6 85 85 85
-1 25 6 83 83 83
0 25 6 85 85 85
1 25 6 83 83 83
2 25 6 85 85 85
3 25 6 85 85 85
4 25 6 83 83 83
5 25 6 85 85 85
6 25 6 83 83 83
7 25 6 87 87 87
8 25 6 83 83 83
9 25 6 83 83 83
10 25 6 83 83 83
11 25 6 83 83 83
12 25 6 83 83 83
13 25 6 83 83 83
14 25 6 85 85 85
-15 26 6 83 83 83
-14 26 6 87 87 87
-13 26 6 87 87 87
-12 26 6 85 85 85
-11 26 6 87 87 87
-10 26 6 87 87 87
-9 26 6 87 87 87
-8 26 6 87 87 87
-7 26 6 83 83 83
-6 26 6 83 83 83
-5 26 6 85 85 85
-4 26 6 87 87 87
-3 26 6 87 87 87
-2 26 6 85 85 85
-1 26 6 85 85 85
0 26 6 83 83 83
1 26 6 87 87 87
2 26 6 87 87 87
3 26 6 83 83 83
4 26 6 83 83 83
5 26 6 85 85 85
6 26 6 85 85 85
7 26 6 87 87 87
8 26 6 83 83 83
9 26 6 85 85 85
10 26 6 87 87 87
11 26 6 85 85 85
12 26 6 85 85 85
13 26 6 85 85 85
14 26 6 87 87 87
-15 27 6 85 85 85
-14 27 6 83 83 83
-13 27 6 87 87 87
-12 27 6 85 85 85
-11 27 6 83 83 83
-10 27 6 87 87 87
-9 27 6 85 85 85
-8 27 6 85 85 85
-7 27 6 85 85 85
-6 27 6 85 85 85
-5 27 6 83 83 83
-4 27 6 85 85 85
-3 27 6 83 83 83
-2 27 6 85 85 85
-1 27 6 83 83 83
0 27 6 85 85 85
1 27 6 85 85 85
2 27 6 85 85 85
3 27 6 83 83 83
4 27 6 85 85 85
5 27 6 83 83 83
6 27 6 83 83 83
7 27 6 87 87 87
8 27 6 87 87 87
9 27 6 83 83 83
10 27 6 83 83 83
11 27 6 87 87 87
12 27 6 83 83 83
13 27 6 87 87 87
14 27 6 85 85 85
-15 28 6 87 87 87
-14 28 6 87 87 87
-13 28 6 85 85 85
-12 28 6 83 83 83
-11 28 6 85 85 85
-10 28 6 83 83 83
-9 28 6 85 85 85
-8 28 6 87 87 87
-7 28 6 85 85 85
-6 28 6 87 87 87
-5 28 6 87 87 87
-4 28 6 87 87 87
-3 28 6 83 83 83
-2 28 6 87 87 87
-1 28 6 83 83 83
0 28 6 83 83 83
1 28 6 87 87 87
2 28 6 83 83 83
3 28 6 85 85 85
4 28 6 83 83 83
5 28 6 83 83 83
6 28 6 85 85 85
7 28 6 85 85 85
8 28 6 83 83 83
9 28 6 87 87 87
10 28 6 85 85 85
11 28 6 85 85 85
12 28 6 87 87 87
13 28 6 87 87 87
14 28 6 83 83 83
-15 29 6 85 85 85
-14 29 6 83 83 83
-13 29 6 83 83 83
-12 29 6 83 83 83
-11 29 6 85 85 85
-10 29 6 85 85 85
-9 29 6 85 85 85
-8 29 6 85 85 85
-7 29 6 87 87 87
-6 29 6 87 87 87
-5 29 6 85 85 85
-4 29 6 83 83 83
-3 29 6 87 87 87
-2 29 6 83 83 83
-1 29 6 87 87 87
0 29 6 83 83 83
1 29 6 85 85 85
2 29 6 85 85 85
3 29 6 83 83 83
4 29 6 83 83 83
5 29 6 87 87 87
6 29 6 85 85 85
7 29 6 85 85 85
8 29 6 87 87 87
9 29 6 83 83 83
10 29 6 83 83 83
11 29 6 85 85 85
12 29 6 85 85 85
13 29 6 83 83 83
14 29 6 87 87 87
-15 30 6 83 83 83
-14 30 6 85 85 85
-13 30 6 87 87 87
-12 30 6 87 87 87
-11 30 6 87 87 87
-10 30 6 87 87 87
-9 30 6 83 83 83
-8 30 6 87 87 87
-7 30 6 83 83 83
-6 30 6 83 83 83
-5 30 6 83 83 83
-4 30 6 83 83 83
-3 30 6 87 87 87
-2 30 6 85 85 85
-1 30 6 85 85 85
0 30 6 83 83 83
1 30 6 83 83 83
2 30 6 83 83 83
3 30 6 83 83 83
4 30 6 83 83 83
5 30 6 85 85 85
6 30 6 83 83 83
7 30 6 87 87 87
8 30 6 83 83 83
9 30 6 87 87 87
10 30 6 85 85 85
11 30 6 85 85 85
12 30 6 83 83 83
13 30 6 87 87 87
14 30 6 83 83 83
-15 31 6 87 87 87
-14 31 6 87 87 87
-13 31 6 85 85 85
-12 31 6 83 83 83
-11 31 6 85 85 85
-10 31 6 87 87 87
-9 31 6 83 83 83
-8 31 6 87 87 87
-7 31 6 83 83 83
-6 31 6 85 85 85
-5 31 6 83 83 83
-4 31 6 87 87 87
-3 31 6 85 85 85
-2 31 6 87 87 87
-1 31 6 87 87 87
0 31 6 87 87 87
1 31 6 85 85 85
2 31 6 87 87 87
3 31 6 87 87 87
4 31 6 83 83 83
5 31 6 83 83 83
6 31 6 87 87 87
7 31 6 85 85 85
8 31 6 87 87 87
9 31 6 83 83 83
10 31 6 83 83 83
11 31 6 85 85 85
12 31 6 87 87 87
13 31 6 87 87 87
14 31 6 85 85 85
-15 32 6 83 83 83
-14 32 6 83 83 83
-13 32 6 85 85 85
-12 32 6 87 87 87
-11 32 6 87 87 87
-10 32 6 87 87 87
-9 32 6 83 83 83
-8 32 6 85 85 85
-7 32 6 85 85 85
-6 32 6 85 85 85
-5 32 6 83 83 83
-4 32 6 85 85 85
-3 32 6 85 85 85
-2 32 6 83 83 83
-1 32 6 85 85 85
0 32 6 85 85 85
1 32 6 85 85 85
2 32 6 85 85 85
3 32 6 85 85 85
4 32 6 85 85 85
5 32 6 83 83 83
6 32 6 83 83 83
7 32 6 83 83 83
8 32 6 87 87 87
9 32 6 85 85 85
10 32 6 85 85 85
11 32 6 83 83 83
12 32 6 85 85 85
13 32 6 85 85 85
14 32 6 85 85 85
-15 33 6 87 87 87
-14 33 6 87 87 87
-13 33 6 85 85 85
-12 33 6 87 87 87
-11 33 6 83 83 83
-10 33 6 85 85 85
-9 33 6 87 87 87
-8 33 6 83 83 83
-7 33 6 83 83 83
-6 33 6 83 83 83
-5 33 6 85 85 85
-4 33 6 85 85 85
-3 33 6 87 87 87
-2 33 6 87 87 87
-1 33 6 87 87 87
0 33 6 83 83 83
1 33 6 83 83 83
2 33 6 85 85 85
3 33 6 85 85 85
4 33 6 87 87 87
5 33 6 85 85 85
6 33 6 87 87 87
7 33 6 87 87 87
8 33 6 87 87 87
9 33 6 83 83 83
10 33 6 83 83 83
11 33 6 83 83 83
12 33 6 87 87 87
13 33 6 87 87 87
14 33 6 83 83 83
-15 34 6 83 83 83
-14 34 6 87 87 87
-13 34 6 83 83 83
-12 34 6 85 85 85
-11 34 6 85 85 85
-10 34 6 85 85 85
-9 34 6 87 87 87
-8 34 6 87 87 87
-7 34 6 87 87 87
-6 34 6 85 85 85
-5 34 6 85 85 85
-4 34 6 87 87 87
-3 34 6 85 85 85
-2 34 6 83 83 83
-1 34 6 87 87 87
0 34 6 85 85 85
1 34 6 87 87 87
2 34 6 85 85 85
3 34 6 87 87 87
4 34 6 87 87 87
5 34 6 87 87 87
6 34 6 85 85 85
7 34 6 85 85 85
8 34 6 87 87 87
9 34 6 87 87 87
10 34 6 83 83 83
11 34 6 85 85 85
12 34 6 83 83 83
13 34 6 85 85 85
14 34 6 87 87 87
-15 35 6 85 85 85
-14 35 6 87 87 87
-13 35 6 87 87 87
-12 35 6 87 87 87
-11 35 6 87 87 87
-10 35 6 85 85 85
-9 35 6 85 85 85
-8 35 6 83 83 83
-7 35 6 87 87 87
-6 35 6 87 87 87
-5 35 6 83 83 83
-4 35 6 83 83 83
-3 35 6 85 85 85
-2 35 6 87 87 87
-1 35 6 83 83 83
0 35 6 85 85 85
1 35 6 83 83 83
2 35 6 83 83 83
3 35 6 87 87 87
4 35 6 87 87 87
5 35 6 85 85 85
6 35 6 85 85 85
7 35 6 85 85 85
8 35 6 85 85 85
9 35 6 83 83 83
10 35 6 83 83 83
11 35 6 85 85 85
12 35 6 83 83 83
13 35 6 87 87 87
14 35 6 85 85 85
-15 36 6 87 87 87
-14 36 6 87 87 87
-13 36 6 83 83 83
-12 36 6 87 87 87
-11 36 6 83 83 83
-10 36 6 87 87 87
-9 36 6 87 87 87
-8 36 6 83 83 83
-7 36 6 87 87 87
-6 36 6 85 85 85
-5 36 6 85 85 85
-4 36 6 85 85 85
-3 36 6 83 83 83
-2 36 6 83 83 83
-1 36 6 87 87 87
0 36 6 83 83 83
1 36 6 87 87 87
2 36 6 83 83 83
3 36 6 85 85 85
4 36 6 85 85 85
5 36 6 87 87 87
6 36 6 83 83 83
7 36 6 83 83 83
8 36 6 85 85 85
9 36 6 87 87 87
10 36 6 85 85 85
11 36 6 85 85 85
12 36 6 87 87 87
13 36 6 87 87 87
14 36 6 85 85 85
-15 37 6 85 85 85
-14 37 6 85 85 85
-13 37 6 83 83 83
-12 37 6 83 83 83
-11 37 6 85 85 85
-10 37 6 87 87 87
-9 37 6 83 83 83
-8 37 6 83 83 83
-7 37 6 83 83 83
-6 37 6 83 83 83
-5 37 6 87 87 87
-4 37 6 85 85 85
-3 37 6 85 85 85
-2 37 6 83 83 83
-1 37 6 83 83 83
0 37 6 85 85 85
1 37 6 85 85 85
2 37 6 85 85 85
3 37 6 87 87 87
4 37 6 87 87 87
5 37 6 87 87 87
6 37 6 83 83 83
7 37 6 83 83 83
8 37 6 87 87 87
9 37 6 83 83 83
10 37 6 83 83 83
11 37 6 87 87 87
12 37 6 83 83 83
13 37 6 85 85 85
14 37 6 87 87 87
-15 38 6 87 87 87
-14 38 6 85 85 85
-13 38 6 87 87 87
-12 38 6 87 87 87
-11 38 6 87 87 87
-10 38 6 87 87 87
-9 38 6 85 85 85
-8 38 6 85 85 85
-7 38 6 83 83 83
-6 38 6 87 87 87
-5 38 6 87 87 87
-4 38 6 83 83 83
-3 38 6 87 87 87
-2 38 6 85 85 85
-1 38 6 83 83 83
0 38 6 85 85 85
1 38 6 85 85 85
2 38 6 83 83 83
3 38 6 87 87 87
4 38 6 83 83 83
5 38 6 83 83 83
6 38 6 83 83 83
7 38 6 83 83 83
8 38 6 87 87 87
9 38 6 85 85 85
10 38 6 85 85 85
11 38 6 85 85 85
12 38 6 87 87 87
13 38 6 83 83 83
14 38 6 85 85 85
-15 39 6 83 83 83
-14 39 6 83 83 83
-13 39 6 87 87 87
-12 39 6 83 83 83
-11 39 6 87 87 87
-10 39 6 83 83 83
-9 39 6 83 83 83
-8 39 6 83 83 83
-7 39 6 83 83 83
-6 39 6 85 85 85
-5 39 6 83 83 83
-4 39 6 87 87 87
-3 39 6 87 87 87
-2 39 6 83 83 83
-1 39 6 85 85 85
0 39 6 87 87 87
1 39 6 87 87 87
2 39 6 83 83 83
3 39 6 83 83 83
4 39 6 83 83 83
5 39 6 85 85 85
6 39 6 85 85 85
7 39 6 83 83 83
8 39 6 85 85 85
9 39 6 87 87 87
10 39 6 85 85 85
11 39 6 87 87 87
12 39 6 83 83 83
13 39 6 87 87 87
14 39 6 85 85 85
-15 40 6 87 87 87
-14 40 6 87 87 87
-13 40 6 85 85 85
-12 40 6 87 87 87
-11 40 6 83 83 83
-10 40 6 83 83 83
-9 40 6 83 83 83
-8 40 6 83 83 83
-7 40 6 87 87 87
-6 40 6 87 87 87
-5 40 6 85 85 85
-4 40 6 85 85 85
-3 40 6 85 85 85
-2 40 6 87 87 87
-1 40 6 83 83 83
0 40 6 85 85 85
1 40 6 87 87 87
2 40 6 87 87 87
3 40 6 87 87 87
4 40 6 85 85 85
5 40 6 87 87 87
6 40 6 87 87 87
7 40 6 85 85 85
8 40 6 85 85 85
9 40 6 83 83 83
10 40 6 83 83 83
11 40 6 83 83 83
12 40 6 87 87 87
13 40 6 83 83 83
14 40 6 87 87 87
-15 41 6 85 85 85
-14 41 6 83 83 83
-13 41 6 85 85 85
-12 41 6 85 85 85
-11 41 6 83 83 83
-10 41 6 85 85 85
-9 41 6 83 83 83
-8 41 6 83 83 83
-7 41 6 83 83 83
-6 41 6 87 87 87
-5 41 6 83 83 83
-4 41 6 85 85 85
-3 41 6 83 83 83
-2 41 6 83 83 83
-1 41 6 85 85 85
0 41 6 87 87 87
1 41 6 83 83 83
2 41 6 83 83 83
3 41 6 85 85 85
4 41 6 85 85 85
5 41 6 83 83 83
6 41 6 85 85 85
7 41 6 87 87 87
8 41 6 85 85 85
9 41 6 87 87 87
10 41 6 85 85 85
11 41 6 87 87 87
12 41 6 83 83 83
13 41 6 85 85 85
14 41 6 87 87 87
-15 42 6 85 85 85
-14 42 6 83 83 83
-13 42 6 85 85 85
-12 42 6 87 87 87
-11 42 6 85 85 85
-10 42 6 83 83 83
-9 42 6 87 87 87
-8 42 6 83 83 83
-7 42 6 87 87 87
-6 42 6 85 85 85
-5 42 6 87 87 87
-4 42 6 85 85 85
-3 42 6 83 83 83
-2 42 6 83 83 83
-1 42 6 83 83 83
0 42 6 85 85 85
1 42 6 85 85 85
2 42 6 85 85 85
3 42 6 83 83 83
4 42 6 87 87 87
5 42 6 87 87 87
6 42 6 83 83 83
7 42 6 87 87 87
8 42 6 83 83 83
9 42 6 85 85 85
10 42 6 85 85 85
11 42 6 83 83 83
12 42 6 87 87 87
13 42 6 83 83 83
14 42 6 85 85 85
-15 43 6 85 85 85
-14 43 6 85 85 85
-13 43 6 85 85 85
-12 43 6 83 83 83
-11 43 6 83 83 83
-10 43 6 87 87 87
-9 43 6 83 83 83
-8 43 6 87 87 87
-7 43 6 85 85 85
-6 43 6 85 85 85
-5 43 6 85 85 85
-4 43 6 85 85 85
-3 43 6 85 85 85
-2 43 6 87 87 87
-1 43 6 85 85 85
0 43 6 85 85 85
1 43 6 85 85 85
2 43 6 85 85 85
3 43 6 83 83 83
4 43 6 87 87 87
5 43 6 85 85 85
6 43 6 83 83 83
7 43 6 87 87 87
8 43 6 85 85 85
9 43 6 83 83 83
10 43 6 83 83 83
11 43 6 87 87 87
12 43 6 85 85 85
13 43 6 85 85 85
14 43 6 83 83 83
-15 44 6 85 85 85
-14 44 6 87 87 87
-13 44 6 87 87 87
-12 44 6 83 83 83
-11 44 6 83 83 83
-10 44 6 83 83 83
-9 44 6 83 83 83
-8 44 6 85 85 85
-7 44 6 83 83 83
-6 44 6 87 87 87
-5 44 6 83 83 83
-4 44 6 87 87 87
-3 44 6 83 83 83
-2 44 6 85 85 85
-1 44 6 85 85 85
0 44 6 85 85 85
1 44 6 85 85 85
2 44 6 85 85 85
3 44 6 83 83 83
4 44 6 85 85 85
5 44 6 87 87 87
6 44 6 87 87 87
7 44 6 85 85 85
8 44 6 87 87 87
9 44 6 83 83 83
10 44 6 83 83 83
11 44 6 85 85 85
12 44 6 87 87 87
13 44 6 85 85 85
14 44 6 85 85 85
-15 45 6 83 83 83
-14 45 6 87 87 87
-13 45 6 83 83 83
-12 45 6 87 87 87
-11 45 6 83 83 83
-10 45 6 87 87 87
-9 45 6 83 83 83
-8 45 6 85 85 85
-7 45 6 83 83 83
-6 45 6 85 85 85
-5 45 6 87 87 87
-4 45 6 85 85 85
-3 45 6 87 87 87
-2 45 6 87 87 87
-1 45 6 87 87 87
0 45 6 85 85 85
1 45 6 85 85 85
2 45 6 83 83 83
3 45 6 83 83 83
4 45 6 85 85 85
5 45 6 83 83 83
6 45 6 83 83 83
7 45 6 85 85 85
8 45 6 87 87 87
9 45 6 87 87 87
10 45 6 83 83 83
11 45 6 87 87 87
12 45 6 83 83 83
13 45 6 85 85 85
14 45 6 85 85 85
-15 46 6 83 83 83
-14 46 6 85 85 85
-13 46 6 83 83 83
-12 46 6 85 85 85
-11 46 6 83 83 83
-10 46 6 83 83 83
-9 46 6 87 87 87
-8 46 6 87 87 87
-7 46 6 87 87 87
-6 46 6 85 85 85
-5 46 6 85 85 85
-4 46 6 87 87 87
-3 46 6 83 83 83
-2 46 6 87 87 87
-1 46 6 87 87 87
0 46 6 85 85 85
1 46 6 83 83 83
2 46 6 83 83 83
3 46 6 85 85 85
4 46 6 87 87 87
5 46 6 87 87 87
6 46 6 85 85 85
7 46 6 87 87 87
8 46 6 83 83 83
9 46 6 87 87 87
10 46 6 87 87 87
11 46 6 85 85 85
12 46 6 85 85 85
13 46 6 85 85 85
14 46 6 83 83 83
-15 47 6 85 85 85
-14 47 6 85 85 85
-13 47 6 83 83 83
-12 47 6 83 83 83
-11 47 6 87 87 87
-10 47 6 87 87 87
-9 47 6 83 83 83
-8 47 6 85 85 85
-7 47 6 85 85 85
-6 47 6 83 83 83
-5 47 6 83 83 83
-4 47 6 87 87 87
-3 47 6 85 85 85
-2 47 6 83 83 83
-1 47 6 83 83 83
0 47 6 85 85 85
1 47 6 85 85 85
2 47 6 87 87 87
3 47 6 85 85 85
4 47 6 83 83 83
5 47 6 85 85 85
6 47 6 85 85 85
7 47 6 85 85 85
8 47 6 83 83 83
9 47 6 83 83 83
10 47 6 83 83 83
11 47 6 83 83 83
12 47 6 87 87 87
13 47 6 87 87 87
14 47 6 85 85 85
-15 48 6 83 83 83
-14 48 6 83 83 83
-13 48 6 83 83 83
-12 48 6 85 85 85
-11 48 6 87 87 87
-10 48 6 83 83 83
-9 48 6 83 83 83
-8 48 6 87 87 87
-7 48 6 87 87 87
-6 48 6 87 87 87
-5 48 6 83 83 83
-4 48 6 85 85 85
-3 48 6 87 87 87
-2 48 6 85 85 85
-1 48 6 87 87 87
0 48 6 83 83 83
1 48 6 85 85 85
2 48 6 87 87 87
3 48 6 83 83 83
4 48 6 87 87 87
5 48 6 87 87 87
6 48 6 87 87 87
7 48 6 85 85 85
8 48 6 87 87 87
9 48 6 83 83 83
10 48 6 85 85 85
11 48 6 83 83 83
12 48 6 85 85 85
13 48 6 83 83 83
14 48 6 83 83 83
-15 49 6 83 83 83
-14 49 6 83 83 83
-13 49 6 83 83 83
-12 49 6 83 83 83
-11 49 6 87 87 87
-10 49 6 85 85 85
-9 49 6 87 87 87
-8 49 6 85 85 85
-7 49 6 83 83 83
-6 49 6 85 85 85
-5 49 6 85 85 85
-4 49 6 87 87 87
-3 49 6 87 87 87
-2 49 6 85 85 85
-1 49 6 85 85 85
0 49 6 83 83 83
1 49 6 87 87 87
2 49 6 83 83 83
3 49 6 87 87 87
4 49 6 83 83 83
5 49 6 85 85 85
6 49 6 87 87 87
7 49 6 83 83 83
8 49 6 83 83 83
9 49 6 87 87 87
10 49 6 83 83 83
11 49 6 83 83 83
12 49 6 87 87 87
13 49 6 87 87 87
14 49 6 85 85 85
-15 50 6 87 87 87
-14 50 6 85 85 85
-13 50 6 85 85 85
-12 50 6 87 87 87
-11 50 6 85 85 85
-10 50 6 85 85 85
-9 50 6 83 83 83
-8 50 6 87 87 87
-7 50 6 87 87 87
-6 50 6 85 85 85
-5 50 6 85 85 85
-4 50 6 87 87 87
-3 50 6 85 85 85
-2 50 6 85 85 85
-1 50 6 85 85 85
0 50 6 87 87 87
1 50 6 83 83 83
2 50 6 85 85 85
3 50 6 83 83 83
4 50 6 83 83 83
5 50 6 87 87 87
6 50 6 85 85 85
7 50 6 87 87 87
8 50 6 83 83 83
9 50 6 87 87 87
10 50 6 83 83 83
11 50 6 85 85 85
12 50 6 85 85 85
13 50 6 85 85 85
14 50 6 85 85 85
-15 51 6 85 85 85
-14 51 6 83 83 83
-13 51 6 87 87 87
-12 51 6 83 83 83
-11 51 6 83 83 83
-10 51 6 87 87 87
-9 51 6 87 87 87
-8 51 6 87 87 87
-7 51 6 83 83 83
-6 51 6 87 87 87
-5 51 6 87 87 87
-4 51 6 87 87 87
-3 51 6 87 87 87
-2 51 6 87 87 87
-1 51 6 83 83 83
0 51 6 85 85 85
1 51 6 87 87 87
2 51 6 87 87 87
3 51 6 87 87 87
4 51 6 85 85 85
5 51 6 87 87 87
6 51 6 87 87 87
7 51 6 87 87 87
8 51 6 85 85 85
9 51 6 87 87 87
10 51 6 83 83 83
11 51 6 83 83 83
12 51 6 85 85 85
13 51 6 87 87 87
14 51 6 87 87 87
-15 52 6 85 85 85
-14 52 6 87 87 87
-13 52 6 87 87 87
-12 52 6 87 87 87
-11 52 6 85 85 85
-10 52 6 85 85 85
-9 52 6 85 85 85
-8 52 6 87 87 87
-7 52 6 83 83 83
-6 52 6 87 87 87
-5 52 6 85 85 85
-4 52 6 85 85 85
-3 52 6 87 87 87
-2 52 6 87 87 87
-1 52 6 87 87 87
0 52 6 87 87 87
1 52 6 87 87 87
2 52 6 83 83 83
3 52 6 83 83 83
4 52 6 85 85 85
5 52 6 87 87 87
6 52 6 85 85 85
7 52 6 87 87 87
8 52 6 85 85 85
9 52 6 83 83 83
10 52 6 83 83 83
11 52 6 83 83 83
12 52 6 85 85 85
13 52 6 87 87 87
14 52 6 87 87 87
-15 -27 7 85 85 85
-14 -27 7 83 83 83
-13 -27 7 87 87 87
-12 -27 7 87 87 87
-11 -27 7 83 83 83
-10 -27 7 85 85 85
-9 -27 7 85 85 85
-8 -27 7 85 85 85
-7 -27 7 87 87 87
-6 -27 7 85 85 85
-5 -27 7 83 83 83
-4 -27 7 87 87 87
-3 -27 7 87 87 87
-2 -27 7 85 85 85
-1 -27 7 83 83 83
0 -27 7 83 83 83
1 -27 7 87 87 87
2 -27 7 83 83 83
3 -27 7 83 83 83
4 -27 7 85 85 85
5 -27 7 85 85 85
6 -27 7 83 83 83
7 -27 7 85 85 85
8 -27 7 83 83 83
9 -27 7 83 83 83
10 -27 7 85 85 85
11 -27 7 85 85 85
12 -27 7 87 87 87
13 -27 7 85 85 85
14 -27 7 87 87 87
-15 -26 7 83 83 83
-14 -26 7 85 85 85
13 -26 7 85 85 85
14 -26 7 83 83 83
-15 -25 7 87 87 87
-14 -25 7 83 83 83
13 -25 7 87 87 87
14 -25 7 83 83 83
-15 -24 7 85 85 85
-14 -24 7 87 87 87
13 -24 7 85 85 85
14 -24 7 83 83 83
-15 -23 7 85 85 85
-14 -23 7 85 85 85
13 -23 7 85 85 85
14 -23 7 85 85 85
-15 -22 7 83 83 83
14 -22 7 87 87 87
-15 -21 7 87 87 87
14 -21 7 85 85 85
-15 -20 7 85 85 85
14 -20 7 85 85 85
-15 -19 7 83 83 83
14 -19 7 83 83 83
-15 -18 7 83 83 83
14 -18 7 87 87 87
-15 -17 7 85 85 85
14 -17 7 85 85 85
-15 -16 7 87 87 87
14 -16 7 87 87 87
-15 -15 7 85 85 85
14 -15 7 83 83 83
-15 -14 7 83 83 83
14 -14 7 83 83 83
-15 -13 7 83 83 83
14 -13 7 87 87 87
-15 -12 7 83 83 83
14 -12 7 87 87 87
-15 -11 7 85 85 85
14 -11 7 83 83 83
-15 -10 7 87 87 87
14 -10 7 87 87 87
-15 -9 7 85 85 85
14 -9 7 85 85 85
-15 -8 7 83 83 83
14 -8 7 83 83 83
-15 -7 7 85 85 85
14 -7 7 83 83 83
-15 -6 7 83 83 83
14 -6 7 87 87 87
-15 -5 7 83 83 83
14 -5 7 87 87 87
-15 -4 7 83 83 83
14 -4 7 85 85 85
-15 -3 7 87 87 87
14 -3 7 83 83 83
-15 -2 7 85 85 85
14 -2 7 85 85 85
-15 -1 7 87 87 87
14 -1 7 83 83 83
-15 0 7 83 83 83
14 0 7 83 83 83
-15 1 7 85 85 85
14 1 7 87 87 87
-15 2 7 83 83 83
14 2 7 83 83 83
-15 3 7 87 87 87
14 3 7 83 83 83
-15 4 7 87 87 87
14 4 7 85 85 85
-15 5 7 87 87 87
14 5 7 83 83 83
-15 6 7 85 85 85
14 6 7 83 83 83
-15 7 7 87 87 87
14 7 7 85 85 85
-15 8 7 87 87 87
14 8 7 83 83 83
-15 9 7 85 85 85
14 9 7 85 85 85
-15 10 7 85 85 85
14 10 7 87 87 87
-15 11 7 85 85 85
14 11 7 83 83 83
-15 12 7 83 83 83
14 12 7 87 87 87
-15 13 7 85 85 85
14 13 7 83 83 83
-15 14 7 83 83 83
14 14 7 85 85 85
-15 15 7 87 87 87
14 15 7 85 85 85
-15 16 7 83 83 83
14 16 7 85 85 85
-15 17 7 85 85 85
14 17 7 85 85 85
-15 18 7 87 87 87
14 18 7 83 83 83
-15 19 7 83 83 83
14 19 7 87 87 87
-15 20 7 87 87 87
14 20 7 83 83 83
-15 21 7 83 83 83
14 21 7 85 85 85
-15 22 7 87 87 87
14 22 7 85 85 85
-15 23 7 85 85 85
14 23 7 83 83 83
-15 24 7 83 83 83
14 24 7 85 85 85
-15 25 7 85 85 85
14 25 7 83 83 83
-15 26 7 85 85 85
14 26 7 87 87 87
-15 27 7 87 87 87
14 27 7 83 83 83
-15 28 7 83 83 83
14 28 7 83 83 83
-15 29 7 83 83 83
14 29 7 87 87 87
-15 30 7 83 83 83
14 30 7 85 85 85
-15 31 7 87 87 87
14 31 7 85 85 85
-15 32 7 87 87 87
14 32 7 87 87 87
-15 33 7 87 87 87
14 33 7 83 83 83
-15 34 7 87 87 87
14 34 7 87 87 87
-15 35 7 87 87 87
14 35 7 87 87 87
-15 36 7 87 87 87
14 36 7 87 87 87
-15 37 7 85 85 85
14 37 7 85 85 85
-15 38 7 87 87 87
14 38 7 87 87 87
-15 39 7 83 83 83
14 39 7 87 87 87
-15 40 7 87 87 87
14 40 7 83 83 83
-15 41 7 87 87 87
14 41 7 87 87 87
-15 42 7 83 83 83
14 42 7 87 87 87
-15 43 7 85 85 85
14 43 7 85 85 85
-15 44 7 85 85 85
14 44 7 87 87 87
-15 45 7 85 85 85
14 45 7 85 85 85
-15 46 7 83 83 83
14 46 7 87 87 87
-15 47 7 87 87 87
14 47 7 87 87 87
-15 48 7 83 83 83
14 48 7 85 85 85
-15 49 7 85 85 85
14 49 7 87 87 87
-15 50 7 87 87 87
14 50 7 85 85 85
-15 51 7 83 83 83
14 51 7 87 87 87
-15 52 7 83 83 83
-14 52 7 83 83 83
-13 52 7 83 83 83
-12 52 7 87 87 87
-11 52 7 87 87 87
-10 52 7 87 87 87
-9 52 7 87 87 87
-8 52 7 87 87 87
-7 52 7 83 83 83
-6 52 7 87 87 87
-5 52 7 87 87 87
-4 52 7 87 87 87
-3 52 7 87 87 87
-2 52 7 83 83 83
-1 52 7 87 87 87
0 52 7 85 85 85
1 52 7 85 85 85
2 52 7 85 85 85
3 52 7 87 87 87
4 52 7 83 83 83
5 52 7 87 87 87
6 52 7 83 83 83
7 52 7 87 87 87
8 52 7 87 87 87
9 52 7 83 83 83
10 52 7 83 83 83
11 52 7 87 87 87
12 52 7 85 85 85
13 52 7 83 83 83
14 52 7 85 85 85
-15 53 7 87 87 87
-14 53 7 83 83 83
-13 53 7 87 87 87
-12 53 7 83 83 83
-11 53 7 83 83 83
-10 53 7 85 85 85
-9 53 7 87 87 87
-8 53 7 87 87 87
-7 53 7 85 85 85
-6 53 7 83 83 83
-5 53 7 85 85 85
-4 53 7 87 87 87
-3 53 7 85 85 85
-2 53 7 85 85 85
-1 53 7 83 83 83
0 53 7 85 85 85
1 53 7 87 87 87
2 53 7 85 85 85
3 53 7 87 87 87
4 53 7 83 83 83
5 53 7 85 85 85
6 53 7 85 85 85
7 53 7 87 87 87
8 53 7 85 85 85
9 53 7 87 87 87
10 53 7 87 87 87
11 53 7 83 83 83
12 53 7 87 87 87
13 53 7 83 83 83
14 53 7 87 87 87
-15 -28 8 85 85 85
-14 -28 8 83 83 83
-11 -28 8 46 46 46
-10 -28 8 46 46 46
-9 -28 8 54 48 45
-8 -28 8 46 46 46
-7 -28 8 46 46 46
-6 -28 8 54 48 45
-5 -28 8 46 46 46
-4 -28 8 46 46 46
-3 -28 8 46 46 46
-2 -28 8 46 46 46
-1 -28 8 46 46 46
0 -28 8 46 46 46
1 -28 8 46 46 46
2 -28 8 54 48 45
3 -28 8 46 46 46
4 -28 8 46 46 46
5 -28 8 46 46 46
6 -28 8 46 46 46
7 -28 8 54 48 45
8 -28 8 46 46 46
9 -28 8 46 46 46
10 -28 8 46 46 46
13 -28 8 85 85 85
14 -28 8 87 87 87
-15 -27 8 87 87 87
-14 -27 8 83 83 83
-13 -27 8 83 83 83
-12 -27 8 85 85 85
-11 -27 8 83 83 83
-10 -27 8 83 83 83
-9 -27 8 85 85 85
-8 -27 8 83 83 83
-7 -27 8 87 87 87
-6 -27 8 83 83 83
-5 -27 8 85 85 85
-4 -27 8 87 87 87
-3 -27 8 85 85 85
-2 -27 8 85 85 85
-1 -27 8 83 83 83
0 -27 8 85 85 85
1 -27 8 85 85 85
2 -27 8 83 83 83
3 -27 8 83 83 83
4 -27 8 87 87 87
5 -27 8 87 87 87
6 -27 8 83 83 83
7 -27 8 83 83 83
8 -27 8 85 85 85
9 -27 8 87 87 87
10 -27 8 87 87 87
11 -27 8 83 83 83
12 -27 8 87 87 87
13 -27 8 87 87 87
14 -27 8 83 83 83
-15 -26 8 83 83 83
-14 -26 8 87 87 87
13 -26 8 83 83 83
14 -26 8 83 83 83
-15 -25 8 87 87 87
-14 -25 8 87 87 87
13 -25 8 83 83 83
14 -25 8 85 85 85
-15 -24 8 83 83 83
-14 -24 8 83 83 83
13 -24 8 85 85 85
14 -24 8 87 87 87
-15 -23 8 83 83 83
-14 -23 8 87 87 87
13 -23 8 85 85 85
14 -23 8 87 87 87
-15 -22 8 87 87 87
-14 -22 8 87 87 87
13 -22 8 87 87 87
14 -22 8 85 85 85
-15 -21 8 87 87 87
14 -21 8 83 83 83
-15 -20 8 85 85 85
14 -20 8 83 83 83
-15 -19 8 83 83 83
14 -19 8 87 87 87
-15 -18 8 83 83 83
14 -18 8 87 87 87
-15 -17 8 83 83 83
14 -17 8 85 85 85
-15 -16 8 83 83 83
14 -16 8 87 87 87
-15 -15 8 87 87 87
14 -15 8 85 85 85
-15 -14 8 87 87 87
14 -14 8 85 85 85
-15 -13 8 85 85 85
14 -13 8 83 83 83
-15 -12 8 87 87 87
14 -12 8 87 87 87
-15 -11 8 83 83 83
14 -11 8 87 87 87
-15 -10 8 85 85 85
14 -10 8 85 85 85
-15 -9 8 85 85 85
14 -9 8 85 85 85
-15 -8 8 83 83 83
14 -8 8 83 83 83
-15 -7 8 83 83 83
14 -7 8 85 85 85
-15 -6 8 83 83 83
14 -6 8 85 85 85
-15 -5 8 85 85 85
14 -5 8 87 87 87
-15 -4 8 87 87 87
14 -4 8 87 87 87
-15 -3 8 83 83 83
14 -3 8 85 85 85
-15 -2 8 83 83 83
14 -2 8 85 85 85
-15 -1 8 83 83 83
14 -1 8 85 85 85
-15 0 8 83 83 83
14 0 8 87 87 87
-15 1 8 87 87 87
14 1 8 87 87 87
-15 2 8 83 83 83
14 2 8 87 87 87
-15 3 8 83 83 83
14 3 8 83 83 83
-15 4 8 85 85 85
14 4 8 83 83 83
-15 5 8 85 85 85
14 5 8 87 87 87
-15 6 8 85 85 85
14 6 8 83 83 83
-15 7 8 83 83 83
14 7 8 87 87 87
-15 8 8 83 83 83
14 8 8 83 83 83
-15 9 8 87 87 87
14 9 8 87 87 87
-15 10 8 85 85 85
14 10 8 85 85 85
-15 11 8 83 83 83
14 11 8 87 87 87
-15 12 8 85 85 85
14 12 8 85 85 85
-15 13 8 83 83 83
14 13 8 83 83 83
-15 14 8 83 83 83
14 14 8 87 87 87
-15 15 8 87 87 87
14 15 8 85 85 85
-15 16 8 85 85 85
14 16 8 85 85 85
-15 17 8 87 87 87
14 17 8 83 83 83
-15 18 8 87 87 87
14 18 8 83 83 83
-15 19 8 87 87 87
14 19 8 87 87 87
-15 20 8 87 87 87
14 20 8 85 85 85
-15 21 8 83 83 83
14 21 8 85 85 85
-15 22 8 83 83 83
14 22 8 85 85 85
-15 23 8 85 85 85
14 23 8 83 83 83
-15 24 8 85 85 85
14 24 8 83 83 83
-15 25 8 83 83 83
14 25 8 83 83 83
-15 26 8 85 85 85
14 26 8 85 85 85
-15 27 8 85 85 85
14 27 8 87 87 87
-15 28 8 87 87 87
14 28 8 85 85 85
-15 29 8 85 85 85
14 29 8 85 85 85
-15 30 8 85 85 85
14 30 8 83 83 83
-15 31 8 87 87 87
14 31 8 83 83 83
-15 32 8 85 85 85
14 32 8 85 85 85
-15 33 8 83 83 83
14 33 8 85 85 85
-15 34 8 85 85 85
14 34 8 87 87 87
-15 35 8 87 87 87
14 35 8 83 83 83
-15 36 8 83 83 83
14 36 8 83 83 83
-15 37 8 87 87 87
14 37 8 87 87 87
-15 38 8 83 83 83
14 38 8 83 83 83
-15 39 8 87 87 87
14 39 8 87 87 87
-15 40 8 87 87 87
14 40 8 85 85 85
-15 41 8 85 85 85
14 41 8 85 85 85
-15 42 8 83 83 83
14 42 8 83 83 83
-15 43 8 83 83 83
14 43 8 87 87 87
-15 44 8 83 83 83
14 44 8 87 87 87
-15 45 8 83 83 83
14 45 8 87 87 87
-15 46 8 85 85 85
14 46 8 87 87 87
-15 47 8 85 85 85
14 47 8 83 83 83
-15 48 8 87 87 87
14 48 8 87 87 87
-15 49 8 83 83 83
14 49 8 85 85 85
-15 50 8 87 87 87
14 50 8 83 83 83
-15 51 8 85 85 85
14 51 8 83 83 83
-15 52 8 87 87 87
14 52 8 87 87 87
-15 53 8 83 83 83
-14 53 8 87 87 87
-13 53 8 83 83 83
-12 53 8 85 85 85
-11 53 8 85 85 85
-10 53 8 85 85 85
-9 53 8 85 85 85
-8 53 8 83 83 83
-7 53 8 87 87 87
-6 53 8 85 85 85
-5 53 8 83 83 83
-4 53 8 87 87 87
-3 53 8 87 87 87
-2 53 8 87 87 87
-1 53 8 83 83 83
0 53 8 87 87 87
1 53 8 85 85 85
2 53 8 83 83 83
3 53 8 85 85 85
4 53 8 87 87 87
5 53 8 87 87 87
6 53 8 85 85 85
7 53 8 83 83 83
8 53 8 85 85 85
9 53 8 83 83 83
10 53 8 83 83 83
11 53 8 87 87 87
12 53 8 85 85 85
13 53 8 87 87 87
14 53 8 87 87 87
-15 54 8 83 83 83
-14 54 8 87 87 87
-13 54 8 83 83 83
-12 54 8 85 85 85
-11 54 8 87 87 87
-10 54 8 87 87 87
-9 54 8 83 83 83
-8 54 8 85 85 85
-7 54 8 87 87 87
-6 54 8 85 85 85
-5 54 8 83 83 83
-4 54 8 87 87 87
-3 54 8 85 85 85
-2 54 8 85 85 85
-1 54 8 83 83 83
0 54 8 83 83 83
1 54 8 87 87 87
2 54 8 87 87 87
3 54 8 87 87 87
4 54 8 83 83 83
5 54 8 85 85 85
6 54 8 87 87 87
7 54 8 83 83 83
8 54 8 87 87 87
9 54 8 83 83 83
10 54 8 85 85 85
11 54 8 87 87 87
12 54 8 87 87 87
13 54 8 87 87 87
14 54 8 85 85 85
-15 -33 9 100 100 100
-14 -33 9 113 113 113
13 -33 9 125 125 125
14 -33 9 100 100 100
-15 -30 9 87 87 87
-14 -30 9 87 87 87
-12 -30 9 85 85 85
-11 -30 9 85 85 85
-10 -30 9 87 87 87
-9 -30 9 87 87 87
-8 -30 9 83 83 83
-7 -30 9 83 83 83
-6 -30 9 85 85 85
-5 -30 9 87 87 87
-4 -30 9 87 87 87
-3 -30 9 83 83 83
-2 -30 9 85 85 85
-1 -30 9 83 83 83
0 -30 9 87 87 87
1 -30 9 83 83 83
2 -30 9 87 87 87
3 -30 9 83 83 83
4 -30 9 87 87 87
5 -30 9 85 85 85
6 -30 9 87 87 87
7 -30 9 83 83 83
8 -30 9 87 87 87
9 -30 9 87 87 87
10 -30 9 85 85 85
11 -30 9 83 83 83
13 -30 9 83 83 83
14 -30 9 87 87 87
-15 -29 9 83 83 83
-14 -29 9 85 85 85
-12 -29 9 85 85 85
-11 -29 9 46 46 46
-10 -29 9 46 46 46
-9 -29 9 54 48 45
-8 -29 9 46 46 46
-7 -29 9 46 46 46
-6 -29 9 46 46 46
-5 -29 9 54 48 45
-4 -29 9 46 46 46
-3 -29 9 46 46 46
-2 -29 9 46 46 46
-1 -29 9 46 46 46
0 -29 9 46 46 46
1 -29 9 46 46 46
2 -29 9 54 48 45
3 -29 9 46 46 46
4 -29 9 46 46 46
5 -29 9 46 46 46
6 -29 9 46 46 46
7 -29 9 46 46 46
8 -29 9 46 46 46
9 -29 9 46 46 46
10 -29 9 46 46 46
11 -29 9 85 85 85
13 -29 9 85 85 85
14 -29 9 87 87 87
-15 -28 9 85 85 85
-14 -28 9 85 85 85
-13 -28 9 83 83 83
-12 -28 9 85 85 85
-11 -28 9 87 87 87
-10 -28 9 87 87 87
-9 -28 9 87 87 87
-8 -28 9 85 85 85
-7 -28 9 87 87 87
-6 -28 9 85 85 85
-5 -28 9 83 83 83
-4 -28 9 85 85 85
-3 -28 9 87 87 87
-2 -28 9 83 83 83
-1 -28 9 83 83 83
0 -28 9 83 83 83
1 -28 9 87 87 87
2 -28 9 85 85 85
3 -28 9 83 83 83
4 -28 9 83 83 83
5 -28 9 87 87 87
6 -28 9 87 87 87
7 -28 9 85 85 85
8 -28 9 85 85 85
9 -28 9 83 83 83
10 -28 9 87 87 87
11 -28 9 83 83 83
12 -28 9 85 85 85
13 -28 9 85 85 85
14 -28 9 85 85 85
-15 -27 9 87 87 87
-14 -27 9 85 85 85
13 -27 9 85 85 85
14 -27 9 85 85 85
-15 -26 9 83 83 83
-14 -26 9 87 87 87
13 -26 9 87 87 87
14 -26 9 87 87 87
-15 -25 9 87 87 87
-14 -25 9 83 83 83
13 -25 9 83 83 83
14 -25 9 87 87 87
-15 -24 9 85 85 85
-14 -24 9 83 83 83
13 -24 9 85 85 85
14 -24 9 83 83 83
-15 -23 9 83 83 83
-14 -23 9 85 85 85
13 -23 9 85 85 85
14 -23 9 87 87 87
-15 -22 9 85 85 85
-14 -22 9 83 83 83
13 -22 9 85 85 85
14 -22 9 85 85 85
-15 -21 9 87 87 87
-14 -21 9 83 83 83
13 -21 9 85 85 85
14 -21 9 85 85 85
-15 -20 9 85 85 85
14 -20 9 83 83 83
-15 -19 9 85 85 85
14 -19 9 85 85 85
-15 -18 9 87 87 87
14 -18 9 85 85 85
-15 -17 9 83 83 83
14 -17 9 85 85 85
-15 -16 9 87 87 87
14 -16 9 87 87 87
-15 -15 9 83 83 83
14 -15 9 85 85 85
-15 -14 9 87 87 87
14 -14 9 83 83 83
-15 -13 9 87 87 87
14 -13 9 85 85 85
-15 -12 9 85 85 85
14 -12 9 83 83 83
-15 -11 9 85 85 85
14 -11 9 87 87 87
-15 -10 9 85 85 85
14 -10 9 87 87 87
-15 -9 9 83 83 83
14 -9 9 85 85 85
-15 -8 9 87 87 87
14 -8 9 83 83 83
-15 -7 9 85 85 85
14 -7 9 87 87 87
-15 -6 9 83 83 83
14 -6 9 87 87 87
-15 -5 9 85 85 85
14 -5 9 83 83 83
-15 -4 9 85 85 85
14 -4 9 85 85 85
-15 -3 9 85 85 85
14 -3 9 85 85 85
-15 -2 9 85 85 85
14 -2 9 83 83 83
-15 -1 9 87 87 87
14 -1 9 85 85 85
-15 0 9 87 87 87
14 0 9 87 87 87
-15 1 9 87 87 87
14 1 9 87 87 87
-15 2 9 83 83 83
14 2 9 83 83 83
-15 3 9 87 87 87
14 3 9 87 87 87
-15 4 9 87 87 87
14 4 9 87 87 87
-15 5 9 83 83 83
14 5 9 85 85 85
-15 6 9 85 85 85
14 6 9 83 83 83
-15 7 9 87 87 87
14 7 9 85 85 85
-15 8 9 85 85 85
14 8 9 87 87 87
-15 9 9 87 87 87
14 9 9 85 85 85
-15 10 9 85 85 85
14 10 9 83 83 83
-15 11 9 85 85 85
14 11 9 85 85 85
-15 12 9 85 85 85
14 12 9 85 85 85
-15 13 9 85 85 85
14 13 9 87 87 87
-15 14 9 87 87 87
14 14 9 83 83 83
-15 15 9 85 85 85
14 15 9 83 83 83
-15 16 9 85 85 85
14 16 9 85 85 85
-15 17 9 83 83 83
14 17 9 85 85 85
-15 18 9 87 87 87
14 18 9 83 83 83
-15 19 9 83 83 83
14 19 9 83 83 83
-15 20 9 85 85 85
14 20 9 87 87 87
-15 21 9 85 85 85
14 21 9 87 87 87
-15 22 9 87 87 87
14 22 9 85 85 85
-15 23 9 83 83 83
14 23 9 85 85 85
-15 24 9 87 87 87
14 24 9 87 87 87
-15 25 9 83 83 83
14 25 9 87 87 87
-15 26 9 87 87 87
14 26 9 83 83 83
-15 27 9 85 85 85
14 27 9 85 85 85
-15 28 9 85 85 85
14 28 9 83 83 83
-15 29 9 85 85 85
14 29 9 83 83 83
-15 30 9 87 87 87
14 30 9 87 87 87
-15 31 9 87 87 87
14 31 9 83 83 83
-15 32 9 87 87 87
14 32 9 87 87 87
-15 33 9 87 87 87
14 33 9 85 85 85
-15 34 9 83 83 83
14 34 9 87 87 87
-15 35 9 83 83 83
14 35 9 87 87 87
-15 36 9 87 87 87
14 36 9 87 87 87
-15 37 9 87 87 87
14 37 9 83 83 83
-15 38 9 87 87 87
14 38 9 83 83 83
-15 39 9 87 87 87
14 39 9 83 83 83
-15 40 9 85 85 85
14 40 9 83 83 83
-15 41 9 85 85 85
14 41 9 83 83 83
-15 42 9 83 83 83
14 42 9 87 87 87
-15 43 9 87 87 87
14 43 9 87 87 87
-15 44 9 87 87 87
14 44 9 85 85 85
-15 45 9 83 83 83
14 45 9 87 87 87
-15 46 9 87 87 87
14 46 9 87 87 87
-15 47 9 87 87 87
14 47 9 85 85 85
-15 48 9 85 85 85
14 48 9 83 83 83
-15 49 9 83 83 83
14 49 9 87 87 87
-15 50 9 87 87 87
14 50 9 83 83 83
-15 51 9 87 87 87
14 51 9 83 83 83
-15 52 9 87 87 87
14 52 9 83 83 83
-15 53 9 87 87 87
14 53 9 87 87 87
-15 54 9 85 85 85
-14 54 9 87 87 87
-13 54 9 87 87 87
-12 54 9 83 83 83
-11 54 9 87 87 87
-10 54 9 85 85 85
-9 54 9 85 85 85
-8 54 9 87 87 87
-7 54 9 87 87 87
-6 54 9 87 87 87
-5 54 9 87 87 87
-4 54 9 85 85 85
-3 54 9 83 83 83
-2 54 9 85 85 85
-1 54 9 83 83 83
0 54 9 87 87 87
1 54 9 87 87 87
2 54 9 83 83 83
3 54 9 85 85 85
4 54 9 83 83 83
5 54 9 87 87 87
6 54 9 83 83 83
7 54 9 83 83 83
8 54 9 83 83 83
9 54 9 83 83 83
10 54 9 83 83 83
11 54 9 87 87 87
12 54 9 85 85 85
13 54 9 85 85 85
14 54 9 85 85 85
-15 55 9 85 85 85
-14 55 9 83 83 83
-13 55 9 85 85 85
-12 55 9 83 83 83
-11 55 9 85 85 85
-10 55 9 87 87 87
-9 55 9 85 85 85
-8 55 9 83 83 83
-7 55 9 85 85 85
-6 55 9 83 83 83
-5 55 9 85 85 85
-4 55 9 83 83 83
-3 55 9 87 87 87
-2 55 9 87 87 87
-1 55 9 83 83 83
0 55 9 83 83 83
1 55 9 87 87 87
2 55 9 83 83 83
3 55 9 87 87 87
4 55 9 87 87 87
5 55 9 87 87 87
6 55 9 85 85 85
7 55 9 87 87 87
8 55 9 83 83 83
9 55 9 87 87 87
10 55 9 83 83 83
11 55 9 83 83 83
12 55 9 83 83 83
13 55 9 87 87 87
14 55 9 83 83 83
-16 -33 10 125 125 125
-13 -33 10 100 100 100
12 -33 10 100 100 100
15 -33 10 113 113 113
-15 -31 10 87 87 87
-14 -31 10 87 87 87
-12 -31 10 83 83 83
-11 -31 10 85 85 85
-10 -31 10 85 85 85
-9 -31 10 87 87 87
-8 -31 10 83 83 83
-7 -31 10 85 85 85
-6 -31 10 85 85 85
-5 -31 10 85 85 85
-4 -31 10 87 87 87
-3 -31 10 87 87 87
-2 -31 10 83 83 83
-1 -31 10 83 83 83
0 -31 10 83 83 83
1 -31 10 85 85 85
2 -31 10 87 87 87
3 -31 10 83 83 83
4 -31 10 83 83 83
5 -31 10 85 85 85
6 -31 10 85 85 85
7 -31 10 83 83 83
8 -31 10 83 83 83
9 -31 10 83 83 83
10 -31 10 85 85 85
11 -31 10 85 85 85
13 -31 10 85 85 85
14 -31 10 87 87 87
-15 -30 10 83 83 83
-14 -30 10 85 85 85
-12 -30 10 87 87 87
11 -30 10 87 87 87
13 -30 10 85 85 85
14 -30 10 83 83 83
-15 -29 10 85 85 85
-14 -29 10 87 87 87
-12 -29 10 87 87 87
-11 -29 10 49 49 49
-10 -29 10 46 46 46
-9 -29 10 54 48 45
-8 -29 10 49 49 49
-7 -29 10 46 46 46
-6 -29 10 46 46 46
-5 -29 10 54 48 45
-4 -29 10 46 46 46
-3 -29 10 49 49 49
-2 -29 10 46 46 46
-1 -29 10 54 48 45
0 -29 10 49 49 49
1 -29 10 46 46 46
2 -29 10 54 48 45
3 -29 10 54 48 45
4 -29 10 49 49 49
5 -29 10 49 49 49
6 -29 10 46 46 46
7 -29 10 54 48 45
8 -29 10 46 46 46
9 -29 10 49 49 49
10 -29 10 49 49 49
11 -29 10 87 87 87
13 -29 10 87 87 87
14 -29 10 87 87 87
-15 -28 10 87 87 87
-14 -28 10 87 87 87
-13 -28 10 87 87 87
-12 -28 10 87 87 87
-11 -28 10 87 87 87
-10 -28 10 85 85 85
-9 -28 10 85 85 85
-8 -28 10 85 85 85
-7 -28 10 85 85 85
-6 -28 10 85 85 85
-5 -28 10 85 85 85
-4 -28 10 87 87 87
-3 -28 10 85 85 85
-2 -28 10 85 85 85
-1 -28 10 83 83 83
0 -28 10 87 87 87
1 -28 10 83 83 83
2 -28 10 83 83 83
3 -28 10 83 83 83
4 -28 10 87 87 87
5 -28 10 87 87 87
6 -28 10 85 85 85
7 -28 10 87 87 87
8 -28 10 87 87 87
9 -28 10 87 87 87
10 -28 10 87 87 87
11 -28 10 87 87 87
12 -28 10 83 83 83
13 -28 10 87 87 87
14 -28 10 87 87 87
-15 -27 10 85 85 85
-14 -27 10 85 85 85
13 -27 10 87 87 87
14 -27 10 83 83 83
-15 -26 10 83 83 83
-14 -26 10 85 85 85
13 -26 10 83 83 83
14 -26 10 83 83 83
-15 -25 10 87 87 87
-14 -25 10 85 85 85
13 -25 10 83 83 83
14 -25 10 83 83 83
-15 -24 10 87 87 87
-14 -24 10 85 85 85
13 -24 10 87 87 87
14 -24 10 87 87 87
-15 -23 10 83 83 83
-14 -23 10 85 85 85
13 -23 10 83 83 83
14 -23 10 83 83 83
-15 -22 10 85 85 85
-14 -22 10 85 85 85
13 -22 10 83 83 83
14 -22 10 85 85 85
-15 -21 10 85 85 85
-14 -21 10 83 83 83
13 -21 10 87 87 87
14 -21 10 83 83 83
-15 -20 10 83 83 83
14 -20 10 83 83 83
-15 -19 10 83 83 83
14 -19 10 83 83 83
-15 -18 10 83 83 83
14 -18 10 85 85 85
-15 -17 10 83 83 83
14 -17 10 85 85 85
-15 -16 10 87 87 87
14 -16 10 87 87 87
-15 -15 10 87 87 87
14 -15 10 85 85 85
-15 -14 10 83 83 83
14 -14 10 83 83 83
-15 -13 10 85 85 85
14 -13 10 83 83 83
-15 -12 10 85 85 85
14 -12 10 83 83 83
-15 -11 10 85 85 85
14 -11 10 85 85 85
-15 -10 10 87 87 87
14 -10 10 87 87 87
-15 -9 10 87 87 87
14 -9 10 87 87 87
-15 -8 10 85 85 85
14 -8 10 83 83 83
-15 -7 10 87 87 87
14 -7 10 83 83 83
-15 -6 10 87 87 87
14 -6 10 83 83 83
-15 -5 10 83 83 83
14 -5 10 85 85 85
-15 -4 10 85 85 85
14 -4 10 87 87 87
-15 -3 10 83 83 83
14 -3 10 85 85 85
-15 -2 10 85 85 85
14 -2 10 83 83 83
-15 -1 10 87 87 87
14 -1 10 85 85 85
-15 0 10 87 87 87
14 0 10 87 87 87
-15 1 10 83 83 83
14 1 10 85 85 85
-15 2 10 85 85 85
14 2 10 85 85 85
-15 3 10 87 87 87
14 3 10 83 83 83
-15 4 10 87 87 87
14 4 10 87 87 87
-15 5 10 85 85 85
14 5 10 83 83 83
-15 6 10 85 85 85
14 6 10 83 83 83
-15 7 10 85 85 85
14 7 10 87 87 87
-15 8 10 83 83 83
14 8 10 85 85 85
-15 9 10 85 85 85
14 9 10 83 83 83
-15 10 10 87 87 87
14 10 10 87 87 87
-15 11 10 83 83 83
14 11 10 85 85 85
-15 12 10 83 83 83
14 12 10 87 87 87
-15 13 10 83 83 83
14 13 10 85 85 85
-15 14 10 87 87 87
14 14 10 87 87 87
-15 15 10 87 87 87
14 15 10 83 83 83
-15 16 10 87 87 87
14 16 10 85 85 85
-15 17 10 83 83 83
14 17 10 83 83 83
-15 18 10 85 85 85
14 18 10 83 83 83
-15 19 10 85 85 85
14 19 10 87 87 87
-15 20 10 87 87 87
14 20 10 87 87 87
-15 21 10 85 85 85
14 21 10 85 85 85
-15 22 10 83 83 83
14 22 10 85 85 85
-15 23 10 85 85 85
14 23 10 87 87 87
-15 24 10 87 87 87
14 24 10 87 87 87
-15 25 10 85 85 85
14 25 10 83 83 83
-15 26 10 87 87 87
14 26 10 83 83 83
-15 27 10 87 87 87
14 27 10 87 87 87
-15 28 10 87 87 87
14 28 10 87 87 87
-15 29 10 85 85 85
14 29 10 87 87 87
-15 30 10 85 85 85
14 30 10 87 87 87
-15 31 10 85 85 85
14 31 10 85 85 85
-15 32 10 87 87 87
14 32 10 87 87 87
-15 33 10 85 85 85
14 33 10 83 83 83
-15 34 10 85 85 85
14 34 10 83 83 83
-15 35 10 85 85 85
14 35 10 87 87 87
-15 36 10 85 85 85
14 36 10 85 85 85
-15 37 10 87 87 87
14 37 10 85 85 85
-15 38 10 85 85 85
14 38 10 85 85 85
-15 39 10 85 85 85
14 39 10 87 87 87
-15 40 10 85 85 85
14 40 10 83 83 83
-15 41 10 87 87 87
14 41 10 87 87 87
-15 42 10 87 87 87
14 42 10 83 83 83
-15 43 10 83 83 83
14 43 10 83 83 83
-15 44 10 85 85 85
14 44 10 83 83 83
-15 45 10 85 85 85
14 45 10 85 85 85
-15 46 10 85 85 85
14 46 10 85 85 85
-15 47 10 85 85 85
14 47 10 87 87 87
-15 48 10 85 85 85
14 48 10 83 83 83
-15 49 10 85 85 85
14 49 10 87 87 87
-15 50 10 83 83 83
14 50 10 85 85 85
-15 51 10 87 87 87
14 51 10 85 85 85
-15 52 10 83 83 83
14 52 10 87 87 87
-15 53 10 85 85 85
14 53 10 85 85 85
-15 54 10 83 83 83
14 54 10 83 83 83
-15 55 10 87 87 87
-14 55 10 85 85 85
-13 55 10 83 83 83
-12 55 10 83 83 83
-11 55 10 87 87 87
-10 55 10 87 87 87
-9 55 10 83 83 83
-8 55 10 83 83 83
-7 55 10 85 85 85
-6 55 10 87 87 87
-5 55 10 85 85 85
-4 55 10 87 87 87
-3 55 10 83 83 83
-2 55 10 85 85 85
-1 55 10 85 85 85
0 55 10 83 83 83
1 55 10 87 87 87
2 55 10 87 87 87
3 55 10 87 87 87
4 55 10 83 83 83
5 55 10 85 85 85
6 55 10 87 87 87
7 55 10 87 87 87
8 55 10 85 85 85
9 55 10 87 87 87
10 55 10 85 85 85
11 55 10 87 87 87
12 55 10 83 83 83
13 55 10 85 85 85
14 55 10 85 85 85
-16 -33 11 100 100 100
-13 -33 11 113 113 113
12 -33 11 100 100 100
15 -33 11 113 113 113
-15 -32 11 87 87 87
-14 -32 11 87 87 87
-11 -32 11 46 46 46
-9 -32 11 54 48 45
-7 -32 11 49 49 49
-5 -32 11 54 48 45
-3 -32 11 46 46 46
-1 -32 11 49 49 49
1 -32 11 49 49 49
3 -32 11 49 49 49
5 -32 11 46 46 46
7 -32 11 54 48 45
9 -32 11 46 46 46
13 -32 11 85 85 85
14 -32 11 87 87 87
-15 -31 11 85 85 85
-14 -31 11 85 85 85
-11 -31 11 46 46 46
-10 -31 11 54 48 45
-9 -31 11 54 48 45
-8 -31 11 46 46 46
-7 -31 11 46 46 46
-6 -31 11 46 46 46
-5 -31 11 54 48 45
-4 -31 11 49 49 49
-3 -31 11 49 49 49
-2 -31 11 46 46 46
-1 -31 11 46 46 46
0 -31 11 49 49 49
1 -31 11 46 46 46
2 -31 11 54 48 45
3 -31 11 46 46 46
4 -31 11 49 49 49
5 -31 11 46 46 46
6 -31 11 54 48 45
7 -31 11 54 48 45
8 -31 11 46 46 46
9 -31 11 49 49 49
10 -31 11 46 46 46
13 -31 11 83 83 83
14 -31 11 87 87 87
-15 -30 11 87 87 87
-14 -30 11 83 83 83
-11 -30 11 46 46 46
-10 -30 11 54 48 45
-9 -30 11 46 46 46
-8 -30 11 46 46 46
-7 -30 11 49 49 49
-6 -30 11 54 48 45
-5 -30 11 46 46 46
-4 -30 11 49 49 49
-3 -30 11 54 48 45
-2 -30 11 54 48 45
-1 -30 11 49 49 49
0 -30 11 46 46 46
1 -30 11 49 49 49
2 -30 11 54 48 45
3 -30 11 49 49 49
4 -30 11 46 46 46
5 -30 11 46 46 46
6 -30 11 54 48 45
7 -30 11 49 49 49
8 -30 11 46 46 46
9 -30 11 46 46 46
10 -30 11 46 46 46
13 -30 11 85 85 85
14 -30 11 85 85 85
-15 -29 11 87 87 87
-14 -29 11 85 85 85
-13 -29 11 85 85 85
-12 -29 11 87 87 87
-11 -29 11 87 87 87
-10 -29 11 87 87 87
-9 -29 11 87 87 87
-8 -29 11 85 85 85
-7 -29 11 87 87 87
-6 -29 11 87 87 87
-5 -29 11 85 85 85
-4 -29 11 83 83 83
-3 -29 11 85 85 85
-2 -29 11 85 85 85
-1 -29 11 85 85 85
0 -29 11 85 85 85
1 -29 11 83 83 83
2 -29 11 85 85 85
3 -29 11 85 85 85
4 -29 11 85 85 85
5 -29 11 87 87 87
6 -29 11 87 87 87
7 -29 11 85 85 85
8 -29 11 87 87 87
9 -29 11 85 85 85
10 -29 11 87 87 87
11 -29 11 83 83 83
12 -29 11 87 87 87
13 -29 11 83 83 83
14 -29 11 83 83 83
-15 -28 11 85 85 85
-14 -28 11 83 83 83
13 -28 11 85 85 85
14 -28 11 87 87 87
-15 -27 11 87 87 87
-14 -27 11 83 83 83
13 -27 11 85 85 85
14 -27 11 83 83 83
-15 -26 11 87 87 87
-14 -26 11 85 85 85
13 -26 11 87 87 87
14 -26 11 83 83 83
-15 -25 11 87 87 87
-14 -25 11 85 85 85
13 -25 11 87 87 87
14 -25 11 83 83 83
-15 -24 11 85 85 85
-14 -24 11 83 83 83
13 -24 11 83 83 83
14 -24 11 85 85 85
-15 -23 11 83 83 83
-14 -23 11 85 85 85
13 -23 11 85 85 85
14 -23 11 85 85 85
-15 -22 11 85 85 85
-14 -22 11 87 87 87
13 -22 11 87 87 87
14 -22 11 85 85 85
-15 -21 11 83 83 83
-14 -21 11 83 83 83
13 -21 11 85 85 85
14 -21 11 87 87 87
-15 -20 11 85 85 85
14 -20 11 87 87 87
-15 -19 11 83 83 83
14 -19 11 87 87 87
-15 -18 11 85 85 85
14 -18 11 83 83 83
-15 -17 11 83 83 83
14 -17 11 85 85 85
-15 -16 11 83 83 83
14 -16 11 87 87 87
-15 -15 11 85 85 85
14 -15 11 87 87 87
-15 -14 11 83 83 83
14 -14 11 87 87 87
-15 -13 11 85 85 85
14 -13 11 85 85 85
-15 -12 11 85 85 85
14 -12 11 83 83 83
-15 -11 11 87 87 87
14 -11 11 83 83 83
-15 -10 11 87 87 87
14 -10 11 85 85 85
-15 -9 11 87 87 87
14 -9 11 85 85 85
-15 -8 11 87 87 87
14 -8 11 83 83 83
-15 -7 11 83 83 83
14 -7 11 87 87 87
-15 -6 11 85 85 85
14 -6 11 83 83 83
-15 -5 11 83 83 83
14 -5 11 85 85 85
-15 -4 11 87 87 87
14 -4 11 87 87 87
-15 -3 11 83 83 83
14 -3 11 87 87 87
-15 -2 11 85 85 85
14 -2 11 85 85 85
-15 -1 11 83 83 83
14 -1 11 87 87 87
-15 0 11 85 85 85
14 0 11 85 85 85
-15 1 11 87 87 87
14 1 11 87 87 87
-15 2 11 87 87 87
14 2 11 85 85 85
-15 3 11 85 85 85
14 3 11 87 87 87
-15 4 11 85 85 85
14 4 11 87 87 87
-15 5 11 83 83 83
14 5 11 85 85 85
-15 6 11 83 83 83
14 6 11 85 85 85
-15 7 11 87 87 87
14 7 11 87 87 87
-15 8 11 85 85 85
14 8 11 83 83 83
-15 9 11 83 83 83
14 9 11 87 87 87
-15 10 11 83 83 83
14 10 11 83 83 83
-15 11 11 85 85 85
14 11 11 85 85 85
-15 12 11 83 83 83
14 12 11 83 83 83
-15 13 11 83 83 83
14 13 11 87 87 87
-15 14 11 87 87 87
14 14 11 85 85 85
-15 15 11 85 85 85
14 15 11 87 87 87
-15 16 11 83 83 83
14 16 11 87 87 87
-15 17 11 87 87 87
14 17 11 83 83 83
-15 18 11 83 83 83
14 18 11 85 85 85
-15 19 11 83 83 83
14 19 11 85 85 85
-15 20 11 87 87 87
14 20 11 87 87 87
-15 21 11 85 85 85
14 21 11 87 87 87
-15 22 11 83 83 83
14 22 11 83 83 83
-15 23 11 83 83 83
14 23 11 87 87 87
-15 24 11 83 83 83
14 24 11 83 83 83
-15 25 11 85 85 85
14 25 11 83 83 83
-15 26 11 85 85 85
14 26 11 87 87 87
-15 27 11 87 87 87
14 27 11 83 83 83
-15 28 11 87 87 87
14 28 11 87 87 87
-15 29 11 83 83 83
14 29 11 83 83 83
-15 30 11 83 83 83
14 30 11 83 83 83
-15 31 11 87 87 87
14 31 11 85 85 85
-15 32 11 85 85 85
14 32 11 83 83 83
-15 33 11 83 83 83
14 33 11 83 83 83
-15 34 11 83 83 83
14 34 11 87 87 87
-15 35 11 85 85 85
14 35 11 83 83 83
-15 36 11 85 85 85
14 36 11 87 87 87
-15 37 11 87 87 87
14 37 11 87 87 87
-15 38 11 85 85 85
14 38 11 83 83 83
-15 39 11 85 85 85
14 39 11 85 85 85
-15 40 11 83 83 83
14 40 11 85 85 85
-15 41 11 87 87 87
14 41 11 87 87 87
-15 42 11 85 85 85
14 42 11 87 87 87
-15 43 11 87 87 87
14 43 11 83 83 83
-15 44 11 83 83 83
14 44 11 85 85 85
-15 45 11 85 85 85
14 45 11 87 87 87
-15 46 11 87 87 87
14 46 11 87 87 87
-15 47 11 83 83 83
14 47 11 85 85 85
-15 48 11 87 87 87
14 48 11 87 87 87
-15 49 11 83 83 83
14 49 11 85 85 85
-15 50 11 83 83 83
14 50 11 87 87 87
-15 51 11 83 83 83
14 51 11 83 83 83
-15 52 11 85 85 85
14 52 11 83 83 83
-15 53 11 83 83 83
14 53 11 83 83 83
-15 54 11 87 87 87
14 54 11 83 83 83
-15 55 11 87 87 87
-14 55 11 87 87 87
-13 55 11 85 85 85
-12 55 11 83 83 83
-11 55 11 87 87 87
-10 55 11 87 87 87
-9 55 11 85 85 85
-8 55 11 83 83 83
-7 55 11 85 85 85
-6 55 11 83 83 83
-5 55 11 83 83 83
-4 55 11 87 87 87
-3 55 11 85 85 85
-2 55 11 83 83 83
-1 55 11 85 85 85
0 55 11 85 85 85
1 55 11 87 87 87
2 55 11 87 87 87
3 55 11 83 83 83
4 55 11 85 85 85
5 55 11 85 85 85
6 55 11 85 85 85
7 55 11 83 83 83
8 55 11 87 87 87
9 55 11 85 85 85
10 55 11 85 85 85
11 55 11 83 83 83
12 55 11 85 85 85
13 55 11 83 83 83
14 55 11 85 85 85
-16 -33 12 113 113 113
-13 -33 12 125 125 125
12 -33 12 113 113 113
15 -33 12 125 125 125
-15 -32 12 87 87 87
-14 -32 12 85 85 85
13 -32 12 83 83 83
14 -32 12 87 87 87
-15 -31 12 83 83 83
-14 -31 12 83 83 83
13 -31 12 85 85 85
14 -31 12 83 83 83
-15 -30 12 85 85 85
-14 -30 12 83 83 83
-11 -30 12 46 46 46
-10 -30 12 54 48 45
-9 -30 12 54 48 45
-8 -30 12 49 49 49
-7 -30 12 54 48 45
-6 -30 12 54 48 45
-5 -30 12 54 48 45
-4 -30 12 49 49 49
-3 -30 12 46 46 46
-2 -30 12 54 48 45
-1 -30 12 46 46 46
0 -30 12 49 49 49
1 -30 12 54 48 45
2 -30 12 54 48 45
3 -30 12 46 46 46
4 -30 12 49 49 49
5 -30 12 46 46 46
6 -30 12 54 48 45
7 -30 12 54 48 45
8 -30 12 46 46 46
9 -30 12 49 49 49
10 -30 12 46 46 46
13 -30 12 83 83 83
14 -30 12 87 87 87
-15 -29 12 85 85 85
-14 -29 12 83 83 83
-13 -29 12 83 83 83
-12 -29 12 85 85 85
-11 -29 12 85 85 85
-10 -29 12 87 87 87
-9 -29 12 87 87 87
-8 -29 12 85 85 85
-7 -29 12 87 87 87
-6 -29 12 83 83 83
-5 -29 12 87 87 87
-4 -29 12 87 87 87
-3 -29 12 83 83 83
-2 -29 12 87 87 87
-1 -29 12 83 83 83
0 -29 12 83 83 83
1 -29 12 87 87 87
2 -29 12 87 87 87
3 -29 12 83 83 83
4 -29 12 83 83 83
5 -29 12 85 85 85
6 -29 12 87 87 87
7 -29 12 83 83 83
8 -29 12 87 87 87
9 -29 12 83 83 83
10 -29 12 85 85 85
11 -29 12 83 83 83
12 -29 12 83 83 83
13 -29 12 87 87 87
14 -29 12 85 85 85
-15 -28 12 87 87 87
-14 -28 12 85 85 85
13 -28 12 87 87 87
14 -28 12 83 83 83
-15 -27 12 83 83 83
-14 -27 12 83 83 83
13 -27 12 83 83 83
14 -27 12 85 85 85
-15 -26 12 87 87 87
-14 -26 12 83 83 83
13 -26 12 83 83 83
14 -26 12 83 83 83
-15 -25 12 83 83 83
-14 -25 12 83 83 83
13 -25 12 87 87 87
14 -25 12 83 83 83
-15 -24 12 85 85 85
-14 -24 12 83 83 83
13 -24 12 83 83 83
14 -24 12 85 85 85
-15 -23 12 83 83 83
-14 -23 12 83 83 83
13 -23 12 83 83 83
14 -23 12 83 83 83
-15 -22 12 85 85 85
-14 -22 12 85 85 85
13 -22 12 85 85 85
14 -22 12 83 83 83
-15 -21 12 87 87 87
-14 -21 12 83 83 83
13 -21 12 85 85 85
14 -21 12 85 85 85
-15 -20 12 85 85 85
14 -20 12 83 83 83
-15 -19 12 85 85 85
14 -19 12 83 83 83
-15 -18 12 83 83 83
14 -18 12 83 83 83
-15 -17 12 83 83 83
14 -17 12 85 85 85
-15 -16 12 87 87 87
14 -16 12 87 87 87
-15 -15 12 83 83 83
14 -15 12 83 83 83
-15 -14 12 87 87 87
14 -14 12 83 83 83
-15 -13 12 87 87 87
14 -13 12 83 83 83
-15 -12 12 87 87 87
14 -12 12 83 83 83
-15 -11 12 85 85 85
14 -11 12 87 87 87
-15 -10 12 87 87 87
14 -10 12 85 85 85
-15 -9 12 83 83 83
14 -9 12 85 85 85
-15 -8 12 83 83 83
14 -8 12 87 87 87
-15 -7 12 83 83 83
14 -7 12 85 85 85
-15 -6 12 87 87 87
14 -6 12 83 83 83
-15 -5 12 83 83 83
14 -5 12 83 83 83
-15 -4 12 85 85 85
14 -4 12 85 85 85
-15 -3 12 83 83 83
14 -3 12 83 83 83
-15 -2 12 85 85 85
14 -2 12 83 83 83
-15 -1 12 85 85 85
14 -1 12 85 85 85
-15 0 12 87 87 87
14 0 12 87 87 87
-15 1 12 85 85 85
14 1 12 85 85 85
-15 2 12 83 83 83
14 2 12 87 87 87
-15 3 12 83 83 83
14 3 12 87 87 87
-15 4 12 85 85 85
14 4 12 85 85 85
-15 5 12 87 87 87
14 5 12 85 85 85
-15 6 12 83 83 83
14 6 12 85 85 85
-15 7 12 85 85 85
14 7 12 83 83 83
-15 8 12 85 85 85
14 8 12 85 85 85
-15 9 12 85 85 85
14 9 12 83 83 83
-15 10 12 85 85 85
14 10 12 87 87 87
-15 11 12 85 85 85
14 11 12 87 87 87
-15 12 12 85 85 85
14 12 12 87 87 87
-15 13 12 87 87 87
14 13 12 83 83 83
-15 14 12 87 87 87
14 14 12 87 87 87
-15 15 12 87 87 87
14 15 12 85 85 85
-15 16 12 87 87 87
14 16 12 83 83 83
-15 17 12 83 83 83
14 17 12 85 85 85
-15 18 12 83 83 83
14 18 12 87 87 87
-15 19 12 85 85 85
14 19 12 83 83 83
-15 20 12 87 87 87
14 20 12 85 85 85
-15 21 12 87 87 87
14 21 12 83 83 83
-15 22 12 83 83 83
14 22 12 85 85 85
-15 23 12 83 83 83
14 23 12 87 87 87
-15 24 12 87 87 87
14 24 12 85 85 85
-15 25 12 83 83 83
14 25 12 87 87 87
-15 26 12 87 87 87
14 26 12 87 87 87
-15 27 12 87 87 87
14 27 12 85 85 85
-15 28 12 85 85 85
14 28 12 83 83 83
-15 29 12 83 83 83
14 29 12 83 83 83
-15 30 12 85 85 85
14 30 12 83 83 83
-15 31 12 83 83 83
14 31 12 85 85 85
-15 32 12 85 85 85
14 32 12 87 87 87
-15 33 12 83 83 83
14 33 12 87 87 87
-15 34 12 85 85 85
14 34 12 87 87 87
-15 35 12 83 83 83
14 35 12 85 85 85
-15 36 12 85 85 85
14 36 12 87 87 87
-15 37 12 85 85 85
14 37 12 85 85 85
-15 38 12 85 85 85
14 38 12 85 85 85
-15 39 12 87 87 87
14 39 12 85 85 85
-15 40 12 83 83 83
14 40 12 83 83 83
-15 41 12 87 87 87
14 41 12 87 87 87
-15 42 12 87 87 87
14 42 12 87 87 87
-15 43 12 85 85 85
14 43 12 85 85 85
-15 44 12 83 83 83
14 44 12 87 87 87
-15 45 12 85 85 85
14 45 12 85 85 85
-15 46 12 85 85 85
14 46 12 83 83 83
-15 47 12 83 83 83
14 47 12 87 87 87
-15 48 12 83 83 83
14 48 12 83 83 83
-15 49 12 87 87 87
14 49 12 83 83 83
-15 50 12 83 83 83
14 50 12 83 83 83
-15 51 12 87 87 87
14 51 12 85 85 85
-15 52 12 85 85 85
14 52 12 85 85 85
-15 53 12 87 87 87
14 53 12 83 83 83
-15 54 12 85 85 85
14 54 12 85 85 85
-15 55 12 83 83 83
-14 55 12 87 87 87
-13 55 12 87 87 87
-12 55 12 83 83 83
-11 55 12 83 83 83
-10 55 12 87 87 87
-9 55 12 85 85 85
-8 55 12 87 87 87
-7 55 12 87 87 87
-6 55 12 83 83 83
-5 55 12 85 85 85
-4 55 12 85 85 85
-3 55 12 83 83 83
-2 55 12 87 87 87
-1 55 12 83 83 83
0 55 12 83 83 83
1 55 12 85 85 85
2 55 12 83 83 83
3 55 12 87 87 87
4 55 12 87 87 87
5 55 12 85 85 85
6 55 12 83 83 83
7 55 12 87 87 87
8 55 12 85 85 85
9 55 12 87 87 87
10 55 12 87 87 87
11 55 12 83 83 83
12 55 12 87 87 87
13 55 12 87 87 87
14 55 12 85 85 85
-15 56 12 87 87 87
-14 56 12 83 83 83
-13 56 12 85 85 85
-12 56 12 83 83 83
-11 56 12 85 85 85
-10 56 12 83 83 83
-9 56 12 85 85 85
-8 56 12 83 83 83
-7 56 12 85 85 85
-6 56 12 87 87 87
-5 56 12 87 87 87
-4 56 12 85 85 85
-3 56 12 87 87 87
-2 56 12 85 85 85
-1 56 12 85 85 85
0 56 12 83 83 83
1 56 12 85 85 85
2 56 12 83 83 83
3 56 12 87 87 87
4 56 12 87 87 87
5 56 12 83 83 83
6 56 12 83 83 83
7 56 12 83 83 83
8 56 12 85 85 85
9 56 12 83 83 83
10 56 12 85 85 85
11 56 12 83 83 83
12 56 12 83 83 83
13 56 12 83 83 83
14 56 12 85 85 85
-16 -33 13 113 113 113
-15 -33 13 113 113 113
-14 -33 13 100 100 100
-13 -33 13 100 100 100
12 -33 13 125 125 125
13 -33 13 113 113 113
14 -33 13 113 113 113
15 -33 13 100 100 100
-15 -32 13 85 85 85
-14 -32 13 83 83 83
13 -32 13 83 83 83
14 -32 13 85 85 85
-15 -31 13 85 85 85
-14 -31 13 83 83 83
-11 -31 13 49 49 49
-10 -31 13 46 46 46
-9 -31 13 46 46 46
-8 -31 13 49 49 49
-7 -31 13 54 48 45
-6 -31 13 46 46 46
-5 -31 13 46 46 46
-4 -31 13 49 49 49
-3 -31 13 46 46 46
-2 -31 13 54 48 45
-1 -31 13 46 46 46
0 -31 13 46 46 46
1 -31 13 49 49 49
2 -31 13 54 48 45
3 -31 13 46 46 46
4 -31 13 46 46 46
5 -31 13 49 49 49
6 -31 13 46 46 46
7 -31 13 54 48 45
8 -31 13 49 49 49
9 -31 13 46 46 46
10 -31 13 49 49 49
13 -31 13 85 85 85
14 -31 13 87 87 87
-15 -30 13 83 83 83
-14 -30 13 85 85 85
-13 -30 13 83 83 83
-12 -30 13 87 87 87
-11 -30 13 87 87 87
-10 -30 13 83 83 83
-9 -30 13 85 85 85
-8 -30 13 87 87 87
-7 -30 13 85 85 85
-6 -30 13 87 87 87
-5 -30 13 83 83 83
-4 -30 13 87 87 87
-3 -30 13 85 85 85
-2 -30 13 83 83 83
-1 -30 13 83 83 83
0 -30 13 85 85 85
1 -30 13 85 85 85
2 -30 13 83 83 83
3 -30 13 83 83 83
4 -30 13 85 85 85
5 -30 13 87 87 87
6 -30 13 83 83 83
7 -30 13 83 83 83
8 -30 13 85 85 85
9 -30 13 85 85 85
10 -30 13 87 87 87
11 -30 13 87 87 87
12 -30 13 83 83 83
13 -30 13 83 83 83
14 -30 13 83 83 83
-15 -29 13 83 83 83
14 -29 13 87 87 87
-15 -28 13 87 87 87
-14 -28 13 87 87 87
13 -28 13 87 87 87
14 -28 13 85 85 85
-15 -27 13 83 83 83
-14 -27 13 87 87 87
13 -27 13 85 85 85
14 -27 13 83 83 83
-15 -26 13 87 87 87
-14 -26 13 83 83 83
13 -26 13 87 87 87
14 -26 13 83 83 83
-15 -25 13 83 83 83
-14 -25 13 83 83 83
13 -25 13 83 83 83
14 -25 13 83 83 83
-15 -24 13 85 85 85
-14 -24 13 85 85 85
13 -24 13 87 87 87
14 -24 13 85 85 85
-15 -23 13 87 87 87
-14 -23 13 83 83 83
13 -23 13 87 87 87
14 -23 13 83 83 83
-15 -22 13 87 87 87
-14 -22 13 87 87 87
13 -22 13 83 83 83
14 -22 13 85 85 85
-15 -21 13 83 83 83
-14 -21 13 85 85 85
13 -21 13 83 83 83
14 -21 13 87 87 87
-15 -20 13 83 83 83
14 -20 13 87 87 87
-15 -19 13 83 83 83
14 -19 13 85 85 85
-15 -18 13 87 87 87
14 -18 13 87 87 87
-15 -17 13 83 83 83
14 -17 13 87 87 87
-15 -16 13 85 85 85
14 -16 13 85 85 85
-15 -15 13 85 85 85
14 -15 13 87 87 87
-15 -14 13 87 87 87
14 -14 13 87 87 87
-15 -13 13 87 87 87
14 -13 13 83 83 83
-15 -12 13 85 85 85
14 -12 13 83 83 83
-15 -11 13 85 85 85
14 -11 13 85 85 85
-15 -10 13 85 85 85
14 -10 13 85 85 85
-15 -9 13 83 83 83
14 -9 13 87 87 87
-15 -8 13 85 85 85
14 -8 13 87 87 87
-15 -7 13 87 87 87
14 -7 13 85 85 85
-15 -6 13 87 87 87
14 -6 13 85 85 85
-15 -5 13 85 85 85
14 -5 13 87 87 87
-15 -4 13 87 87 87
14 -4 13 85 85 85
-15 -3 13 83 83 83
14 -3 13 87 87 87
-15 -2 13 83 83 83
14 -2 13 85 85 85
-15 -1 13 83 83 83
14 -1 13 83 83 83
-15 0 13 85 85 85
14 0 13 85 85 85
-15 1 13 87 87 87
14 1 13 83 83 83
-15 2 13 87 87 87
14 2 13 87 87 87
-15 3 13 83 83 83
14 3 13 83 83 83
-15 4 13 87 87 87
14 4 13 85 85 85
-15 5 13 85 85 85
14 5 13 87 87 87
-15 6 13 85 85 85
14 6 13 87 87 87
-15 7 13 87 87 87
14 7 13 85 85 85
-15 8 13 85 85 85
14 8 13 85 85 85
-15 9 13 85 85 85
14 9 13 83 83 83
-15 10 13 85 85 85
14 10 13 87 87 87
-15 11 13 85 85 85
14 11 13 83 83 83
-15 12 13 85 85 85
14 12 13 83 83 83
-15 13 13 85 85 85
14 13 13 85 85 85
-15 14 13 85 85 85
14 14 13 87 87 87
-15 15 13 83 83 83
14 15 13 83 83 83
-15 16 13 87 87 87
14 16 13 85 85 85
-15 17 13 87 87 87
14 17 13 87 87 87
-15 18 13 85 85 85
14 18 13 83 83 83
-15 19 13 87 87 87
14 19 13 85 85 85
-15 20 13 87 87 87
14 20 13 83 83 83
-15 21 13 85 85 85
14 21 13 85 85 85
-15 22 13 83 83 83
14 22 13 83 83 83
-15 23 13 85 85 85
14 23 13 85 85 85
-15 24 13 83 83 83
14 24 13 83 83 83
-15 25 13 85 85 85
14 25 13 83 83 83
-15 26 13 87 87 87
14 26 13 87 87 87
-15 27 13 85 85 85
14 27 13 83 83 83
-15 28 13 87 87 87
14 28 13 85 85 85
-15 29 13 87 87 87
14 29 13 83 83 83
-15 30 13 83 83 83
14 30 13 87 87 87
-15 31 13 87 87 87
14 31 13 87 87 87
-15 32 13 87 87 87
14 32 13 83 83 83
-15 33 13 83 83 83
14 33 13 85 85 85
-15 34 13 85 85 85
14 34 13 83 83 83
-15 35 13 83 83 83
14 35 13 85 85 85
-15 36 13 87 87 87
14 36 13 85 85 85
-15 37 13 87 87 87
14 37 13 85 85 85
-15 38 13 87 87 87
14 38 13 87 87 87
-15 39 13 85 85 85
14 39 13 85 85 85
-15 40 13 87 87 87
14 40 13 83 83 83
-15 41 13 87 87 87
14 41 13 83 83 83
-15 42 13 83 83 83
14 42 13 85 85 85
-15 43 13 87 87 87
14 43 13 85 85 85
-15 44 13 85 85 85
14 44 13 83 83 83
-15 45 13 85 85 85
14 45 13 85 85 85
-15 46 13 85 85 85
14 46 13 87 87 87
-15 47 13 83 83 83
14 47 13 83 83 83
-15 48 13 83 83 83
14 48 13 87 87 87
-15 49 13 87 87 87
14 49 13 83 83 83
-15 50 13 87 87 87
14 50 13 83 83 83
-15 51 13 85 85 85
14 51 13 85 85 85
-15 52 13 83 83 83
14 52 13 85 85 85
-15 53 13 85 85 85
14 53 13 83 83 83
-15 54 13 85 85 85
14 54 13 85 85 85
-15 55 13 87 87 87
-14 55 13 87 87 87
-13 55 13 85 85 85
-12 55 13 83 83 83
-11 55 13 83 83 83
-10 55 13 83 83 83
-9 55 13 87 87 87
-8 55 13 85 85 85
-7 55 13 85 85 85
-6 55 13 87 87 87
-5 55 13 83 83 83
-4 55 13 83 83 83
-3 55 13 85 85 85
-2 55 13 87 87 87
-1 55 13 87 87 87
0 55 13 85 85 85
1 55 13 87 87 87
2 55 13 83 83 83
3 55 13 87 87 87
4 55 13 85 85 85
5 55 13 85 85 85
6 55 13 85 85 85
7 55 13 87 87 87
8 55 13 83 83 83
9 55 13 83 83 83
10 55 13 85 85 85
11 55 13 83 83 83
12 55 13 85 85 85
13 55 13 83 83 83
14 55 13 83 83 83
-15 56 13 87 87 87
-14 56 13 85 85 85
-13 56 13 85 85 85
-12 56 13 83 83 83
-11 56 13 87 87 87
-10 56 13 85 85 85
-9 56 13 85 85 85
-8 56 13 87 87 87
-7 56 13 83 83 83
-6 56 13 85 85 85
-5 56 13 85 85 85
-4 56 13 83 83 83
-3 56 13 87 87 87
-2 56 13 87 87 87
-1 56 13 87 87 87
0 56 13 83 83 83
1 56 13 83 83 83
2 56 13 87 87 87
3 56 13 87 87 87
4 56 13 87 87 87
5 56 13 87 87 87
6 56 13 85 85 85
7 56 13 85 85 85
8 56 13 87 87 87
9 56 13 83 83 83
10 56 13 85 85 85
11 56 13 87 87 87
12 56 13 85 85 85
13 56 13 83 83 83
14 56 13 87 87 87
-10 57 13 85 85 85
-3 57 13 83 83 83
2 57 13 83 83 83
9 57 13 85 85 85
-10 58 13 83 83 83
-3 58 13 87 87 87
2 58 13 85 85 85
9 58 13 87 87 87
-10 59 13 85 85 85
-3 59 13 87 87 87
2 59 13 87 87 87
9 59 13 83 83 83
-10 60 13 87 87 87
-3 60 13 83 83 83
2 60 13 85 85 85
9 60 13 83 83 83
-9 61 13 83 83 83
-8 61 13 83 83 83
-7 61 13 83 83 83
-6 61 13 83 83 83
-5 61 13 87 87 87
-4 61 13 87 87 87
3 61 13 85 85 85
4 61 13 83 83 83
5 61 13 83 83 83
6 61 13 85 85 85
7 61 13 85 85 85
8 61 13 83 83 83
-15 -33 14 87 87 87
-14 -33 14 85 85 85
13 -33 14 85 85 85
14 -33 14 83 83 83
-15 -32 14 85 85 85
-14 -32 14 85 85 85
13 -32 14 87 87 87
14 -32 14 85 85 85
-15 -31 14 87 87 87
-14 -31 14 83 83 83
-11 -31 14 46 46 46
-10 -31 14 49 49 49
-9 -31 14 49 49 49
-8 -31 14 46 46 46
-7 -31 14 54 48 45
-6 -31 14 49 49 49
-5 -31 14 49 49 49
-4 -31 14 46 46 46
-3 -31 14 49 49 49
-2 -31 14 54 48 45
-1 -31 14 54 48 45
0 -31 14 49 49 49
1 -31 14 46 46 46
2 -31 14 54 48 45
3 -31 14 54 48 45
4 -31 14 49 49 49
5 -31 14 46 46 46
6 -31 14 49 49 49
7 -31 14 54 48 45
8 -31 14 46 46 46
9 -31 14 49 49 49
10 -31 14 46 46 46
13 -31 14 83 83 83
14 -31 14 85 85 85
-15 -30 14 87 87 87
-14 -30 14 87 87 87
-13 -30 14 83 83 83
-12 -30 14 85 85 85
-11 -30 14 83 83 83
-10 -30 14 83 83 83
-9 -30 14 83 83 83
-8 -30 14 83 83 83
-7 -30 14 87 87 87
-6 -30 14 85 85 85
-5 -30 14 87 87 87
-4 -30 14 87 87 87
-3 -30 14 87 87 87
-2 -30 14 83 83 83
-1 -30 14 87 87 87
0 -30 14 85 85 85
1 -30 14 85 85 85
2 -30 14 85 85 85
3 -30 14 87 87 87
4 -30 14 85 85 85
5 -30 14 83 83 83
6 -30 14 83 83 83
7 -30 14 87 87 87
8 -30 14 87 87 87
9 -30 14 85 85 85
10 -30 14 83 83 83
11 -30 14 85 85 85
12 -30 14 85 85 85
13 -30 14 83 83 83
14 -30 14 85 85 85
-15 -29 14 83 83 83
14 -29 14 85 85 85
-15 -28 14 85 85 85
-14 -28 14 87 87 87
13 -28 14 83 83 83
14 -28 14 87 87 87
-15 -27 14 85 85 85
-14 -27 14 85 85 85
13 -27 14 87 87 87
14 -27 14 85 85 85
-15 -26 14 83 83 83
-14 -26 14 83 83 83
13 -26 14 83 83 83
14 -26 14 87 87 87
-15 -25 14 83 83 83
-14 -25 14 83 83 83
13 -25 14 87 87 87
14 -25 14 83 83 83
-15 -24 14 87 87 87
-14 -24 14 83 83 83
13 -24 14 85 85 85
14 -24 14 87 87 87
-15 -23 14 83 83 83
-14 -23 14 83 83 83
13 -23 14 83 83 83
14 -23 14 87 87 87
-15 -22 14 87 87 87
-14 -22 14 83 83 83
13 -22 14 85 85 85
14 -22 14 85 85 85
-15 -21 14 83 83 83
14 -21 14 85 85 85
-15 -20 14 85 85 85
14 -20 14 83 83 83
-15 -19 14 85 85 85
14 -19 14 85 85 85
-15 -18 14 87 87 87
14 -18 14 87 87 87
-15 -17 14 87 87 87
14 -17 14 85 85 85
-15 -16 14 87 87 87
14 -16 14 85 85 85
-15 -15 14 83 83 83
14 -15 14 83 83 83
-15 -14 14 85 85 85
14 -14 14 83 83 83
-15 -13 14 85 85 85
14 -13 14 85 85 85
-15 -12 14 85 85 85
14 -12 14 87 87 87
-15 -11 14 87 87 87
14 -11 14 83 83 83
-15 -10 14 87 87 87
14 -10 14 83 83 83
-15 -9 14 87 87 87
14 -9 14 87 87 87
-15 -8 14 83 83 83
14 -8 14 85 85 85
-15 -7 14 87 87 87
14 -7 14 85 85 85
-15 -6 14 83 83 83
14 -6 14 83 83 83
-15 -5 14 85 85 85
14 -5 14 85 85 85
-15 -4 14 83 83 83
14 -4 14 85 85 85
-15 -3 14 85 85 85
14 -3 14 85 85 85
-15 -2 14 83 83 83
14 -2 14 83 83 83
-15 -1 14 83 83 83
14 -1 14 83 83 83
-15 0 14 83 83 83
14 0 14 83 83 83
-15 1 14 83 83 83
14 1 14 85 85 85
-15 2 14 87 87 87
14 2 14 83 83 83
-15 3 14 83 83 83
14 3 14 85 85 85
-15 4 14 87 87 87
14 4 14 83 83 83
-15 5 14 85 85 85
14 5 14 85 85 85
-15 6 14 83 83 83
14 6 14 87 87 87
-15 7 14 85 85 85
14 7 14 83 83 83
-15 8 14 83 83 83
14 8 14 87 87 87
-15 9 14 85 85 85
14 9 14 87 87 87
-15 10 14 83 83 83
14 10 14 87 87 87
-15 11 14 87 87 87
14 11 14 85 85 85
-15 12 14 87 87 87
14 12 14 83 83 83
-15 13 14 83 83 83
14 13 14 85 85 85
-15 14 14 83 83 83
14 14 14 87 87 87
-15 15 14 85 85 85
14 15 14 83 83 83
-15 16 14 87 87 87
14 16 14 83 83 83
-15 17 14 83 83 83
14 17 14 87 87 87
-15 18 14 83 83 83
14 18 14 87 87 87
-15 19 14 85 85 85
14 19 14 87 87 87
-15 20 14 87 87 87
14 20 14 85 85 85
-15 21 14 87 87 87
14 21 14 83 83 83
-15 22 14 87 87 87
14 22 14 85 85 85
-15 23 14 83 83 83
14 23 14 85 85 85
-15 24 14 83 83 83
14 24 14 85 85 85
-15 25 14 87 87 87
14 25 14 83 83 83
-15 26 14 87 87 87
14 26 14 83 83 83
-15 27 14 85 85 85
14 27 14 87 87 87
-15 28 14 87 87 87
14 28 14 83 83 83
-15 29 14 83 83 83
14 29 14 83 83 83
-15 30 14 83 83 83
14 30 14 83 83 83
-15 31 14 87 87 87
14 31 14 85 85 85
-15 32 14 85 85 85
14 32 14 87 87 87
-15 33 14 85 85 85
14 33 14 87 87 87
-15 34 14 87 87 87
14 34 14 85 85 85
-15 35 14 83 83 83
14 35 14 85 85 85
-15 36 14 83 83 83
14 36 14 83 83 83
-15 37 14 85 85 85
14 37 14 87 87 87
-15 38 14 87 87 87
14 38 14 85 85 85
-15 39 14 85 85 85
14 39 14 83 83 83
-15 40 14 85 85 85
14 40 14 85 85 85
-15 41 14 83 83 83
14 41 14 87 87 87
-15 42 14 85 85 85
14 42 14 85 85 85
-15 43 14 83 83 83
14 43 14 87 87 87
-15 44 14 85 85 85
14 44 14 83 83 83
-15 45 14 85 85 85
14 45 14 83 83 83
-15 46 14 83 83 83
14 46 14 87 87 87
-15 47 14 83 83 83
14 47 14 87 87 87
-15 48 14 85 85 85
14 48 14 87 87 87
-15 49 14 87 87 87
14 49 14 87 87 87
-15 50 14 83 83 83
14 50 14 85 85 85
-15 51 14 83 83 83
14 51 14 85 85 85
-15 52 14 87 87 87
14 52 14 87 87 87
-15 53 14 87 87 87
14 53 14 85 85 85
-15 54 14 85 85 85
14 54 14 85 85 85
-15 55 14 85 85 85
-14 55 14 85 85 85
-13 55 14 87 87 87
-12 55 14 87 87 87
-11 55 14 85 85 85
-10 55 14 85 85 85
-9 55 14 87 87 87
-8 55 14 83 83 83
-7 55 14 85 85 85
-6 55 14 87 87 87
-5 55 14 85 85 85
-4 55 14 87 87 87
-3 55 14 83 83 83
-2 55 14 85 85 85
-1 55 14 87 87 87
0 55 14 87 87 87
1 55 14 83 83 83
2 55 14 83 83 83
3 55 14 85 85 85
4 55 14 83 83 83
5 55 14 85 85 85
6 55 14 83 83 83
7 55 14 87 87 87
8 55 14 85 85 85
9 55 14 85 85 85
10 55 14 87 87 87
11 55 14 87 87 87
12 55 14 83 83 83
13 55 14 87 87 87
14 55 14 87 87 87
-15 56 14 85 85 85
-14 56 14 87 87 87
-13 56 14 85 85 85
-12 56 14 83 83 83
-11 56 14 83 83 83
-10 56 14 87 87 87
-9 56 14 87 87 87
-8 56 14 83 83 83
-7 56 14 87 87 87
-6 56 14 83 83 83
-5 56 14 85 85 85
-4 56 14 85 85 85
-3 56 14 85 85 85
-2 56 14 83 83 83
-1 56 14 87 87 87
0 56 14 87 87 87
1 56 14 87 87 87
2 56 14 83 83 83
3 56 14 87 87 87
4 56 14 87 87 87
5 56 14 83 83 83
6 56 14 83 83 83
7 56 14 83 83 83
8 56 14 83 83 83
9 56 14 85 85 85
10 56 14 85 85 85
11 56 14 83 83 83
12 56 14 85 85 85
13 56 14 85 85 85
14 56 14 83 83 83
-10 57 14 83 83 83
-8 57 14 85 85 85
-7 57 14 87 87 87
-6 57 14 87 87 87
-5 57 14 85 85 85
-3 57 14 83 83 83
2 57 14 87 87 87
4 57 14 83 83 83
5 57 14 85 85 85
6 57 14 85 85 85
7 57 14 85 85 85
9 57 14 83 83 83
-10 58 14 85 85 85
-8 58 14 87 87 87
-7 58 14 87 87 87
-6 58 14 87 87 87
-5 58 14 87 87 87
-3 58 14 85 85 85
2 58 14 87 87 87
4 58 14 87 87 87
5 58 14 83 83 83
6 58 14 85 85 85
7 58 14 87 87 87
9 58 14 87 87 87
-10 59 14 87 87 87
-7 59 14 87 87 87
-6 59 14 83 83 83
-3 59 14 85 85 85
2 59 14 85 85 85
5 59 14 83 83 83
6 59 14 87 87 87
9 59 14 87 87 87
-27 60 14 85 85 85
-26 60 14 85 85 85
-25 60 14 85 85 85
-24 60 14 85 85 85
-23 60 14 85 85 85
-22 60 14 87 87 87
-21 60 14 83 83 83
-20 60 14 85 85 85
-19 60 14 87 87 87
-18 60 14 85 85 85
-17 60 14 83 83 83
-16 60 14 83 83 83
-10 60 14 87 87 87
-3 60 14 87 87 87
2 60 14 87 87 87
9 60 14 87 87 87
15 60 14 87 87 87
16 60 14 83 83 83
17 60 14 87 87 87
18 60 14 85 85 85
19 60 14 83 83 83
20 60 14 83 83 83
21 60 14 85 85 85
22 60 14 83 83 83
23 60 14 83 83 83
24 60 14 83 83 83
25 60 14 83 83 83
26 60 14 83 83 83
-23 61 14 87 87 87
-16 61 14 83 83 83
-9 61 14 83 83 83
-8 61 14 87 87 87
-5 61 14 85 85 85
-4 61 14 85 85 85
3 61 14 83 83 83
4 61 14 85 85 85
7 61 14 85 85 85
8 61 14 85 85 85
15 61 14 83 83 83
22 61 14 83 83 83
-7 62 14 83 83 83
-6 62 14 83 83 83
5 62 14 85 85 85
6 62 14 83 83 83
-11 -34 15 54 48 45
-9 -34 15 46 46 46
-7 -34 15 54 48 45
-5 -34 15 46 46 46
-3 -34 15 49 49 49
-1 -34 15 46 46 46
1 -34 15 49 49 49
3 -34 15 46 46 46
5 -34 15 46 46 46
7 -34 15 54 48 45
9 -34 15 46 46 46
-15 -33 15 85 85 85
-14 -33 15 83 83 83
-11 -33 15 54 48 45
-10 -33 15 46 46 46
-9 -33 15 46 46 46
-8 -33 15 49 49 49
-7 -33 15 54 48 45
-6 -33 15 46 46 46
-5 -33 15 46 46 46
-4 -33 15 49 49 49
-3 -33 15 46 46 46
-2 -33 15 54 48 45
-1 -33 15 46 46 46
0 -33 15 49 49 49
1 -33 15 46 46 46
2 -33 15 54 48 45
3 -33 15 46 46 46
4 -33 15 49 49 49
5 -33 15 46 46 46
6 -33 15 49 49 49
7 -33 15 54 48 45
8 -33 15 46 46 46
9 -33 15 46 46 46
10 -33 15 49 49 49
13 -33 15 87 87 87
14 -33 15 83 83 83
-15 -32 15 87 87 87
-14 -32 15 87 87 87
-11 -32 15 46 46 46
-10 -32 15 46 46 46
-9 -32 15 46 46 46
-8 -32 15 46 46 46
-7 -32 15 54 48 45
-6 -32 15 46 46 46
-5 -32 15 46 46 46
-4 -32 15 46 46 46
-3 -32 15 46 46 46
-2 -32 15 54 48 45
-1 -32 15 46 46 46
0 -32 15 46 46 46
1 -32 15 46 46 46
2 -32 15 54 48 45
3 -32 15 46 46 46
4 -32 15 46 46 46
5 -32 15 46 46 46
6 -32 15 46 46 46
7 -32 15 54 48 45
8 -32 15 46 46 46
9 -32 15 46 46 46
10 -32 15 46 46 46
13 -32 15 87 87 87
14 -32 15 83 83 83
-15 -31 15 87 87 87
-14 -31 15 83 83 83
-13 -31 15 83 83 83
-12 -31 15 87 87 87
-11 -31 15 85 85 85
-10 -31 15 87 87 87
-9 -31 15 83 83 83
-8 -31 15 85 85 85
-7 -31 15 85 85 85
-6 -31 15 83 83 83
-5 -31 15 85 85 85
-4 -31 15 87 87 87
-3 -31 15 87 87 87
-2 -31 15 83 83 83
-1 -31 15 85 85 85
0 -31 15 83 83 83
1 -31 15 85 85 85
2 -31 15 85 85 85
3 -31 15 85 85 85
4 -31 15 83 83 83
5 -31 15 85 85 85
6 -31 15 87 87 87
7 -31 15 83 83 83
8 -31 15 85 85 85
9 -31 15 83 83 83
10 -31 15 85 85 85
11 -31 15 83 83 83
12 -31 15 83 83 83
13 -31 15 87 87 87
14 -31 15 85 85 85
-15 -30 15 85 85 85
14 -30 15 87 87 87
-15 -29 15 85 85 85
14 -29 15 87 87 87
-15 -28 15 83 83 83
14 -28 15 83 83 83
-15 -27 15 83 83 83
-14 -27 15 85 85 85
13 -27 15 85 85 85
14 -27 15 83 83 83
-15 -26 15 85 85 85
-14 -26 15 87 87 87
13 -26 15 85 85 85
14 -26 15 83 83 83
-15 -25 15 85 85 85
-14 -25 15 83 83 83
13 -25 15 85 85 85
14 -25 15 83 83 83
-15 -24 15 87 87 87
-14 -24 15 85 85 85
13 -24 15 87 87 87
14 -24 15 87 87 87
-15 -23 15 83 83 83
-14 -23 15 87 87 87
13 -23 15 85 85 85
14 -23 15 83 83 83
-15 -22 15 87 87 87
14 -22 15 85 85 85
-15 -21 15 83 83 83
14 -21 15 87 87 87
-15 -20 15 87 87 87
14 -20 15 85 85 85
-15 -19 15 87 87 87
14 -19 15 85 85 85
-15 -18 15 87 87 87
14 -18 15 83 83 83
-15 -17 15 87 87 87
14 -17 15 83 83 83
-15 -16 15 83 83 83
14 -16 15 85 85 85
-15 -15 15 87 87 87
14 -15 15 87 87 87
-15 -14 15 85 85 85
14 -14 15 85 85 85
-15 -13 15 87 87 87
14 -13 15 87 87 87
-15 -12 15 85 85 85
14 -12 15 85 85 85
-15 -11 15 83 83 83
14 -11 15 85 85 85
-15 -10 15 85 85 85
14 -10 15 85 85 85
-15 -9 15 87 87 87
14 -9 15 87 87 87
-15 -8 15 85 85 85
14 -8 15 87 87 87
-15 -7 15 83 83 83
14 -7 15 87 87 87
-15 -6 15 83 83 83
14 -6 15 85 85 85
-15 -5 15 87 87 87
14 -5 15 85 85 85
-15 -4 15 87 87 87
14 -4 15 85 85 85
-15 -3 15 85 85 85
14 -3 15 83 83 83
-15 -2 15 83 83 83
14 -2 15 85 85 85
-15 -1 15 87 87 87
14 -1 15 83 83 83
-15 0 15 87 87 87
14 0 15 87 87 87
-15 1 15 83 83 83
14 1 15 87 87 87
-15 2 15 83 83 83
14 2 15 83 83 83
-15 3 15 87 87 87
14 3 15 85 85 85
-15 4 15 85 85 85
14 4 15 87 87 87
-15 5 15 85 85 85
14 5 15 85 85 85
-15 6 15 87 87 87
14 6 15 87 87 87
-15 7 15 83 83 83
14 7 15 87 87 87
-15 8 15 85 85 85
14 8 15 83 83 83
-15 9 15 87 87 87
14 9 15 87 87 87
-15 10 15 85 85 85
14 10 15 85 85 85
-15 11 15 83 83 83
14 11 15 83 83 83
-15 12 15 87 87 87
14 12 15 87 87 87
-15 13 15 85 85 85
14 13 15 83 83 83
-15 14 15 85 85 85
14 14 15 87 87 87
-15 15 15 85 85 85
14 15 15 85 85 85
-15 16 15 85 85 85
14 16 15 87 87 87
-15 17 15 87 87 87
14 17 15 83 83 83
-15 18 15 87 87 87
14 18 15 87 87 87
-15 19 15 85 85 85
14 19 15 87 87 87
-15 20 15 87 87 87
14 20 15 87 87 87
-15 21 15 83 83 83
14 21 15 87 87 87
-15 22 15 85 85 85
14 22 15 87 87 87
-15 23 15 85 85 85
14 23 15 87 87 87
-15 24 15 87 87 87
14 24 15 85 85 85
-15 25 15 83 83 83
14 25 15 83 83 83
-15 26 15 85 85 85
14 26 15 87 87 87
-15 27 15 87 87 87
14 27 15 85 85 85
-15 28 15 83 83 83
14 28 15 85 85 85
-15 29 15 83 83 83
14 29 15 87 87 87
-15 30 15 85 85 85
14 30 15 87 87 87
-15 31 15 87 87 87
14 31 15 87 87 87
-15 32 15 83 83 83
14 32 15 85 85 85
-15 33 15 87 87 87
14 33 15 85 85 85
-15 34 15 87 87 87
14 34 15 87 87 87
-15 35 15 85 85 85
14 35 15 83 83 83
-15 36 15 87 87 87
14 36 15 83 83 83
-15 37 15 85 85 85
14 37 15 85 85 85
28 37 15 87 87 87
-15 38 15 87 87 87
14 38 15 85 85 85
28 38 15 85 85 85
-15 39 15 83 83 83
14 39 15 85 85 85
28 39 15 87 87 87
-15 40 15 87 87 87
14 40 15 87 87 87
28 40 15 85 85 85
-15 41 15 87 87 87
14 41 15 85 85 85
28 41 15 87 87 87
-15 42 15 83 83 83
14 42 15 83 83 83
28 42 15 83 83 83
-15 43 15 83 83 83
14 43 15 83 83 83
28 43 15 85 85 85
-29 44 15 85 85 85
-15 44 15 87 87 87
14 44 15 87 87 87
28 44 15 85 85 85
-29 45 15 87 87 87
-15 45 15 85 85 85
14 45 15 83 83 83
28 45 15 85 85 85
-29 46 15 87 87 87
-15 46 15 87 87 87
14 46 15 83 83 83
28 46 15 87 87 87
-29 47 15 83 83 83
-15 47 15 85 85 85
14 47 15 85 85 85
28 47 15 85 85 85
-29 48 15 87 87 87
-15 48 15 87 87 87
14 48 15 87 87 87
28 48 15 85 85 85
-29 49 15 85 85 85
-15 49 15 87 87 87
14 49 15 87 87 87
28 49 15 87 87 87
-29 50 15 83 83 83
-15 50 15 85 85 85
14 50 15 85 85 85
28 50 15 85 85 85
-29 51 15 87 87 87
-15 51 15 85 85 85
14 51 15 83 83 83
28 51 15 85 85 85
-29 52 15 83 83 83
-15 52 15 83 83 83
14 52 15 87 87 87
28 52 15 85 85 85
-29 53 15 83 83 83
-15 53 15 87 87 87
14 53 15 85 85 85
28 53 15 83 83 83
-29 54 15 87 87 87
-15 54 15 87 87 87
14 54 15 83 83 83
28 54 15 83 83 83
-29 55 15 85 85 85
-15 55 15 85 85 85
14 55 15 87 87 87
28 55 15 85 85 85
-29 56 15 83 83 83
-15 56 15 87 87 87
-14 56 15 85 85 85
-13 56 15 85 85 85
-12 56 15 85 85 85
-11 56 15 85 85 85
-10 56 15 85 85 85
-9 56 15 87 87 87
-8 56 15 83 83 83
-7 56 15 87 87 87
-6 56 15 83 83 83
-5 56 15 87 87 87
-4 56 15 87 87 87
-3 56 15 85 85 85
-2 56 15 87 87 87
-1 56 15 87 87 87
0 56 15 87 87 87
1 56 15 87 87 87
2 56 15 83 83 83
3 56 15 83 83 83
4 56 15 85 85 85
5 56 15 83 83 83
6 56 15 83 83 83
7 56 15 83 83 83
8 56 15 87 87 87
9 56 15 87 87 87
10 56 15 83 83 83
11 56 15 87 87 87
12 56 15 87 87 87
13 56 15 83 83 83
14 56 15 87 87 87
28 56 15 83 83 83
-10 57 15 83 83 83
-8 57 15 83 83 83
-7 57 15 85 85 85
-6 57 15 83 83 83
-5 57 15 85 85 85
-3 57 15 83 83 83
2 57 15 85 85 85
4 57 15 85 85 85
5 57 15 83 83 83
6 57 15 85 85 85
7 57 15 85 85 85
9 57 15 87 87 87
-10 58 15 87 87 87
-8 58 15 87 87 87
-7 58 15 83 83 83
-6 58 15 85 85 85
-5 58 15 83 83 83
-3 58 15 87 87 87
2 58 15 87 87 87
4 58 15 83 83 83
5 58 15 85 85 85
6 58 15 83 83 83
7 58 15 87 87 87
9 58 15 83 83 83
-27 59 15 85 85 85
-26 59 15 83 83 83
-25 59 15 83 83 83
-24 59 15 87 87 87
-23 59 15 83 83 83
-22 59 15 87 87 87
-21 59 15 83 83 83
-20 59 15 83 83 83
-19 59 15 85 85 85
-18 59 15 83 83 83
-17 59 15 85 85 85
-16 59 15 87 87 87
-10 59 15 87 87 87
-7 59 15 85 85 85
-6 59 15 87 87 87
-3 59 15 83 83 83
2 59 15 87 87 87
5 59 15 85 85 85
6 59 15 87 87 87
9 59 15 87 87 87
15 59 15 83 83 83
16 59 15 87 87 87
17 59 15 87 87 87
18 59 15 87 87 87
19 59 15 83 83 83
20 59 15 87 87 87
21 59 15 87 87 87
22 59 15 87 87 87
23 59 15 85 85 85
24 59 15 85 85 85
25 59 15 87 87 87
26 59 15 87 87 87
-23 60 15 87 87 87
-16 60 15 85 85 85
-10 60 15 85 85 85
-3 60 15 83 83 83
2 60 15 85 85 85
9 60 15 87 87 87
15 60 15 83 83 83
22 60 15 83 83 83
-9 61 15 83 83 83
-8 61 15 85 85 85
-5 61 15 87 87 87
-4 61 15 85 85 85
3 61 15 87 87 87
4 61 15 87 87 87
7 61 15 85 85 85
8 61 15 83 83 83
-7 62 15 87 87 87
-6 62 15 83 83 83
5 62 15 83 83 83
6 62 15 87 87 87
-15 -33 16 83 83 83
-14 -33 16 87 87 87
13 -33 16 87 87 87
14 -33 16 85 85 85
-15 -32 16 83 83 83
-14 -32 16 83 83 83
-11 -32 16 46 46 46
-10 -32 16 49 49 49
-9 -32 16 49 49 49
-8 -32 16 46 46 46
-7 -32 16 54 48 45
-6 -32 16 49 49 49
-5 -32 16 49 49 49
-4 -32 16 46 46 46
-3 -32 16 49 49 49
-2 -32 16 54 48 45
-1 -32 16 54 48 45
0 -32 16 49 49 49
1 -32 16 46 46 46
2 -32 16 54 48 45
3 -32 16 54 48 45
4 -32 16 49 49 49
5 -32 16 46 46 46
6 -32 16 49 49 49
7 -32 16 54 48 45
8 -32 16 46 46 46
9 -32 16 49 49 49
10 -32 16 46 46 46
13 -32 16 83 83 83
14 -32 16 85 85 85
-15 -31 16 87 87 87
-14 -31 16 83 83 83
-13 -31 16 85 85 85
-12 -31 16 87 87 87
-11 -31 16 85 85 85
-10 -31 16 83 83 83
-9 -31 16 85 85 85
-8 -31 16 85 85 85
-7 -31 16 87 87 87
-6 -31 16 85 85 85
-5 -31 16 87 87 87
-4 -31 16 87 87 87
-3 -31 16 87 87 87
-2 -31 16 87 87 87
-1 -31 16 83 83 83
0 -31 16 83 83 83
1 -31 16 87 87 87
2 -31 16 87 87 87
3 -31 16 83 83 83
4 -31 16 83 83 83
5 -31 16 85 85 85
6 -31 16 83 83 83
7 -31 16 85 85 85
8 -31 16 85 85 85
9 -31 16 83 83 83
10 -31 16 85 85 85
11 -31 16 87 87 87
12 -31 16 83 83 83
13 -31 16 85 85 85
14 -31 16 87 87 87
-15 -30 16 85 85 85
14 -30 16 85 85 85
-15 -29 16 83 83 83
14 -29 16 83 83 83
-15 -28 16 85 85 85
14 -28 16 83 83 83
-15 -27 16 85 85 85
14 -27 16 87 87 87
-15 -26 16 87 87 87
14 -26 16 87 87 87
-15 -25 16 85 85 85
14 -25 16 87 87 87
-15 -24 16 87 87 87
14 -24 16 85 85 85
-15 -23 16 85 85 85
14 -23 16 83 83 83
-15 -22 16 83 83 83
14 -22 16 83 83 83
-15 -21 16 87 87 87
14 -21 16 85 85 85
-15 -20 16 85 85 85
14 -20 16 87 87 87
-15 -19 16 85 85 85
14 -19 16 85 85 85
-15 -18 16 85 85 85
14 -18 16 85 85 85
-15 -17 16 83 83 83
14 -17 16 83 83 83
-15 -16 16 87 87 87
14 -16 16 85 85 85
-15 -15 16 85 85 85
14 -15 16 85 85 85
-15 -14 16 87 87 87
14 -14 16 85 85 85
-15 -13 16 87 87 87
14 -13 16 85 85 85
-15 -12 16 85 85 85
14 -12 16 83 83 83
-15 -11 16 87 87 87
14 -11 16 87 87 87
-15 -10 16 87 87 87
14 -10 16 85 85 85
-15 -9 16 85 85 85
14 -9 16 87 87 87
-15 -8 16 87 87 87
14 -8 16 85 85 85
-15 -7 16 83 83 83
14 -7 16 85 85 85
-15 -6 16 87 87 87
14 -6 16 87 87 87
-15 -5 16 85 85 85
14 -5 16 85 85 85
-15 -4 16 83 83 83
14 -4 16 85 85 85
-15 -3 16 83 83 83
14 -3 16 85 85 85
-15 -2 16 85 85 85
14 -2 16 87 87 87
-15 -1 16 85 85 85
14 -1 16 85 85 85
-15 0 16 87 87 87
14 0 16 85 85 85
-15 1 16 85 85 85
14 1 16 85 85 85
-15 2 16 83 83 83
14 2 16 85 85 85
-15 3 16 87 87 87
14 3 16 87 87 87
-15 4 16 83 83 83
14 4 16 85 85 85
-15 5 16 85 85 85
14 5 16 87 87 87
-15 6 16 85 85 85
14 6 16 85 85 85
-15 7 16 83 83 83
14 7 16 87 87 87
-15 8 16 85 85 85
14 8 16 87 87 87
-15 9 16 87 87 87
14 9 16 85 85 85
-29 10 16 85 85 85
-15 10 16 85 85 85
14 10 16 83 83 83
28 10 16 87 87 87
-29 11 16 87 87 87
-15 11 16 83 83 83
14 11 16 85 85 85
28 11 16 85 85 85
-29 12 16 83 83 83
-15 12 16 85 85 85
14 12 16 85 85 85
28 12 16 83 83 83
-29 13 16 85 85 85
-15 13 16 83 83 83
14 13 16 87 87 87
28 13 16 85 85 85
-29 14 16 87 87 87
-15 14 16 85 85 85
14 14 16 83 83 83
28 14 16 87 87 87
-29 15 16 87 87 87
-28 15 16 87 87 87
-15 15 16 85 85 85
14 15 16 85 85 85
28 15 16 87 87 87
-29 16 16 83 83 83
-28 16 16 85 85 85
-15 16 16 83 83 83
14 16 16 85 85 85
28 16 16 83 83 83
-29 17 16 83 83 83
-28 17 16 83 83 83
-15 17 16 85 85 85
14 17 16 85 85 85
28 17 16 85 85 85
-29 18 16 85 85 85
-28 18 16 85 85 85
-15 18 16 83 83 83
14 18 16 85 85 85
28 18 16 87 87 87
-29 19 16 83 83 83
-28 19 16 83 83 83
-15 19 16 87 87 87
14 19 16 87 87 87
28 19 16 83 83 83
-29 20 16 83 83 83
-28 20 16 87 87 87
-15 20 16 83 83 83
14 20 16 87 87 87
28 20 16 87 87 87
-29 21 16 87 87 87
-28 21 16 87 87 87
-15 21 16 87 87 87
14 21 16 85 85 85
28 21 16 85 85 85
-29 22 16 83 83 83
-28 22 16 87 87 87
-15 22 16 85 85 85
14 22 16 83 83 83
28 22 16 85 85 85
-29 23 16 85 85 85
-28 23 16 87 87 87
-15 23 16 83 83 83
14 23 16 85 85 85
28 23 16 85 85 85
-29 24 16 85 85 85
-28 24 16 83 83 83
-15 24 16 85 85 85
14 24 16 87 87 87
28 24 16 87 87 87
-29 25 16 85 85 85
-28 25 16 87 87 87
-15 25 16 87 87 87
14 25 16 83 83 83
28 25 16 87 87 87
-29 26 16 85 85 85
-28 26 16 87 87 87
-15 26 16 87 87 87
14 26 16 85 85 85
28 26 16 83 83 83
-29 27 16 83 83 83
-28 27 16 83 83 83
-15 27 16 85 85 85
14 27 16 87 87 87
28 27 16 83 83 83
-29 28 16 83 83 83
-28 28 16 83 83 83
-15 28 16 85 85 85
14 28 16 83 83 83
28 28 16 85 85 85
-29 29 16 85 85 85
-28 29 16 85 85 85
-15 29 16 85 85 85
14 29 16 85 85 85
28 29 16 87 87 87
-29 30 16 83 83 83
-28 30 16 87 87 87
-15 30 16 87 87 87
14 30 16 85 85 85
28 30 16 85 85 85
-29 31 16 87 87 87
-28 31 16 83 83 83
-15 31 16 83 83 83
14 31 16 85 85 85
28 31 16 87 87 87
-29 32 16 85 85 85
-28 32 16 83 83 83
-15 32 16 87 87 87
14 32 16 85 85 85
28 32 16 85 85 85
-29 33 16 83 83 83
-28 33 16 87 87 87
-15 33 16 83 83 83
14 33 16 85 85 85
28 33 16 85 85 85
-29 34 16 85 85 85
-28 34 16 85 85 85
-15 34 16 87 87 87
14 34 16 87 87 87
27 34 16 87 87 87
28 34 16 85 85 85
-29 35 16 83 83 83
-28 35 16 83 83 83
-15 35 16 85 85 85
14 35 16 85 85 85
27 35 16 85 85 85
28 35 16 87 87 87
-29 36 16 85 85 85
-28 36 16 87 87 87
-15 36 16 83 83 83
14 36 16 83 83 83
27 36 16 87 87 87
28 36 16 87 87 87
-29 37 16 85 85 85
-28 37 16 85 85 85
-15 37 16 85 85 85
14 37 16 83 83 83
27 37 16 83 83 83
-29 38 16 85 85 85
-28 38 16 83 83 83
-15 38 16 87 87 87
14 38 16 85 85 85
27 38 16 87 87 87
-29 39 16 87 87 87
-28 39 16 85 85 85
-15 39 16 87 87 87
14 39 16 87 87 87
27 39 16 83 83 83
-29 40 16 83 83 83
-28 40 16 83 83 83
-15 40 16 85 85 85
14 40 16 87 87 87
27 40 16 83 83 83
-29 41 16 83 83 83
-28 41 16 83 83 83
-15 41 16 85 85 85
14 41 16 85 85 85
27 41 16 83 83 83
-29 42 16 85 85 85
-28 42 16 83 83 83
-15 42 16 85 85 85
14 42 16 83 83 83
27 42 16 87 87 87
-29 43 16 83 83 83
-28 43 16 87 87 87
-15 43 16 83 83 83
14 43 16 83 83 83
27 43 16 83 83 83
-28 44 16 87 87 87
-15 44 16 83 83 83
14 44 16 83 83 83
27 44 16 87 87 87
-28 45 16 87 87 87
-15 45 16 85 85 85
14 45 16 85 85 85
27 45 16 83 83 83
-28 46 16 83 83 83
-15 46 16 87 87 87
14 46 16 85 85 85
27 46 16 83 83 83
-28 47 16 87 87 87
-15 47 16 87 87 87
14 47 16 87 87 87
27 47 16 87 87 87
-28 48 16 85 85 85
-15 48 16 87 87 87
14 48 16 83 83 83
27 48 16 83 83 83
