ply
format ascii 1.0
comment : MagicaVoxel @ Ephtracy
element vertex 5020
property float x
property float y
property float z
property uchar red
property uchar green
property uchar blue
end_header
124 1 28 87 87 87
125 1 28 83 83 83
126 1 28 87 87 87
127 1 28 83 83 83
128 1 28 87 87 87
129 1 28 87 87 87
130 1 28 85 85 85
131 1 28 83 83 83
121 2 28 83 83 83
122 2 28 85 85 85
123 2 28 85 85 85
132 2 28 87 87 87
133 2 28 83 83 83
134 2 28 83 83 83
119 3 28 87 87 87
120 3 28 87 87 87
135 3 28 83 83 83
136 3 28 83 83 83
118 4 28 87 87 87
137 4 28 87 87 87
116 5 28 83 83 83
117 5 28 83 83 83
138 5 28 87 87 87
139 5 28 85 85 85
115 6 28 87 87 87
140 6 28 85 85 85
114 7 28 87 87 87
141 7 28 83 83 83
114 8 28 87 87 87
141 8 28 87 87 87
113 9 28 83 83 83
142 9 28 87 87 87
112 10 28 83 83 83
143 10 28 85 85 85
112 11 28 83 83 83
143 11 28 87 87 87
111 12 28 83 83 83
144 12 28 87 87 87
111 13 28 87 87 87
144 13 28 83 83 83
111 14 28 85 85 85
144 14 28 85 85 85
110 15 28 87 87 87
145 15 28 85 85 85
110 16 28 85 85 85
145 16 28 83 83 83
110 17 28 85 85 85
145 17 28 85 85 85
110 18 28 87 87 87
145 18 28 87 87 87
110 19 28 85 85 85
145 19 28 83 83 83
110 20 28 87 87 87
145 20 28 83 83 83
110 21 28 83 83 83
145 21 28 87 87 87
111 22 28 83 83 83
144 22 28 87 87 87
111 23 28 87 87 87
144 23 28 87 87 87
111 24 28 87 87 87
144 24 28 83 83 83
112 25 28 85 85 85
143 25 28 85 85 85
112 26 28 85 85 85
143 26 28 85 85 85
113 27 28 83 83 83
142 27 28 85 85 85
114 28 28 87 87 87
141 28 28 85 85 85
115 29 28 83 83 83
140 29 28 85 85 85
116 30 28 87 87 87
139 30 28 83 83 83
117 31 28 87 87 87
138 31 28 87 87 87
118 32 28 85 85 85
137 32 28 83 83 83
119 33 28 85 85 85
120 33 28 83 83 83
121 33 28 85 85 85
122 33 28 85 85 85
123 33 28 87 87 87
124 33 28 85 85 85
125 33 28 85 85 85
126 33 28 83 83 83
127 33 28 85 85 85
128 33 28 85 85 85
129 33 28 87 87 87
130 33 28 83 83 83
131 33 28 87 87 87
132 33 28 87 87 87
133 33 28 83 83 83
134 33 28 87 87 87
135 33 28 85 85 85
136 33 28 83 83 83
124 1 29 87 87 87
125 1 29 83 83 83
126 1 29 85 85 85
127 1 29 87 87 87
128 1 29 85 85 85
129 1 29 85 85 85
130 1 29 87 87 87
131 1 29 87 87 87
121 2 29 87 87 87
122 2 29 87 87 87
123 2 29 83 83 83
132 2 29 83 83 83
133 2 29 85 85 85
134 2 29 87 87 87
119 3 29 85 85 85
120 3 29 87 87 87
135 3 29 87 87 87
136 3 29 87 87 87
118 4 29 87 87 87
137 4 29 85 85 85
116 5 29 85 85 85
117 5 29 85 85 85
138 5 29 87 87 87
139 5 29 87 87 87
115 6 29 85 85 85
140 6 29 83 83 83
114 7 29 87 87 87
141 7 29 85 85 85
114 8 29 85 85 85
141 8 29 85 85 85
113 9 29 85 85 85
142 9 29 87 87 87
112 10 29 85 85 85
143 10 29 87 87 87
112 11 29 85 85 85
143 11 29 85 85 85
111 12 29 87 87 87
144 12 29 83 83 83
111 13 29 87 87 87
144 13 29 85 85 85
111 14 29 85 85 85
144 14 29 87 87 87
110 15 29 87 87 87
145 15 29 83 83 83
110 16 29 83 83 83
145 16 29 83 83 83
110 17 29 85 85 85
145 17 29 85 85 85
110 18 29 85 85 85
145 18 29 87 87 87
110 19 29 83 83 83
145 19 29 87 87 87
110 20 29 87 87 87
145 20 29 87 87 87
110 21 29 87 87 87
145 21 29 87 87 87
111 22 29 85 85 85
144 22 29 83 83 83
111 23 29 87 87 87
144 23 29 85 85 85
111 24 29 87 87 87
144 24 29 83 83 83
112 25 29 83 83 83
143 25 29 87 87 87
112 26 29 83 83 83
143 26 29 85 85 85
113 27 29 83 83 83
142 27 29 87 87 87
114 28 29 83 83 83
141 28 29 83 83 83
115 29 29 87 87 87
140 29 29 83 83 83
116 30 29 83 83 83
139 30 29 85 85 85
117 31 29 85 85 85
138 31 29 83 83 83
118 32 29 83 83 83
137 32 29 87 87 87
119 33 29 85 85 85
120 33 29 83 83 83
121 33 29 87 87 87
122 33 29 87 87 87
123 33 29 87 87 87
124 33 29 83 83 83
125 33 29 85 85 85
126 33 29 85 85 85
127 33 29 87 87 87
128 33 29 87 87 87
129 33 29 87 87 87
130 33 29 85 85 85
131 33 29 85 85 85
132 33 29 83 83 83
133 33 29 85 85 85
134 33 29 83 83 83
135 33 29 83 83 83
136 33 29 87 87 87
116 -12 30 83 83 83
117 -12 30 87 87 87
118 -12 30 83 83 83
124 -12 30 85 85 85
125 -12 30 83 83 83
126 -12 30 85 85 85
127 -12 30 87 87 87
128 -12 30 83 83 83
129 -12 30 87 87 87
130 -12 30 83 83 83
131 -12 30 87 87 87
137 -12 30 83 83 83
138 -12 30 83 83 83
139 -12 30 83 83 83
116 -11 30 83 83 83
117 -11 30 83 83 83
118 -11 30 87 87 87
119 -11 30 85 85 85
120 -11 30 83 83 83
121 -11 30 85 85 85
122 -11 30 83 83 83
123 -11 30 85 85 85
124 -11 30 87 87 87
125 -11 30 87 87 87
126 -11 30 87 87 87
127 -11 30 83 83 83
128 -11 30 83 83 83
129 -11 30 85 85 85
130 -11 30 85 85 85
131 -11 30 83 83 83
132 -11 30 87 87 87
133 -11 30 83 83 83
134 -11 30 85 85 85
135 -11 30 85 85 85
136 -11 30 85 85 85
137 -11 30 85 85 85
138 -11 30 83 83 83
139 -11 30 85 85 85
115 -4 30 83 83 83
140 -4 30 85 85 85
115 -3 30 87 87 87
116 -3 30 83 83 83
117 -3 30 85 85 85
118 -3 30 87 87 87
119 -3 30 87 87 87
120 -3 30 85 85 85
121 -3 30 85 85 85
122 -3 30 83 83 83
123 -3 30 83 83 83
124 -3 30 85 85 85
125 -3 30 83 83 83
126 -3 30 87 87 87
127 -3 30 85 85 85
128 -3 30 85 85 85
129 -3 30 85 85 85
130 -3 30 85 85 85
131 -3 30 85 85 85
132 -3 30 85 85 85
133 -3 30 85 85 85
134 -3 30 87 87 87
135 -3 30 83 83 83
136 -3 30 85 85 85
137 -3 30 87 87 87
138 -3 30 85 85 85
139 -3 30 83 83 83
140 -3 30 85 85 85
115 -2 30 85 85 85
116 -2 30 83 83 83
117 -2 30 85 85 85
118 -2 30 87 87 87
119 -2 30 83 83 83
120 -2 30 83 83 83
121 -2 30 85 85 85
122 -2 30 87 87 87
123 -2 30 85 85 85
124 -2 30 85 85 85
125 -2 30 83 83 83
126 -2 30 87 87 87
127 -2 30 83 83 83
128 -2 30 87 87 87
129 -2 30 85 85 85
130 -2 30 85 85 85
131 -2 30 87 87 87
132 -2 30 87 87 87
133 -2 30 83 83 83
134 -2 30 85 85 85
135 -2 30 85 85 85
136 -2 30 87 87 87
137 -2 30 83 83 83
138 -2 30 83 83 83
139 -2 30 85 85 85
140 -2 30 87 87 87
115 -1 30 83 83 83
116 -1 30 83 83 83
117 -1 30 83 83 83
118 -1 30 83 83 83
119 -1 30 83 83 83
120 -1 30 83 83 83
121 -1 30 87 87 87
122 -1 30 83 83 83
123 -1 30 83 83 83
124 -1 30 83 83 83
125 -1 30 85 85 85
126 -1 30 83 83 83
127 -1 30 85 85 85
128 -1 30 85 85 85
129 -1 30 87 87 87
130 -1 30 87 87 87
131 -1 30 87 87 87
132 -1 30 87 87 87
133 -1 30 83 83 83
134 -1 30 85 85 85
135 -1 30 83 83 83
136 -1 30 87 87 87
137 -1 30 83 83 83
138 -1 30 85 85 85
139 -1 30 87 87 87
140 -1 30 87 87 87
114 0 30 83 83 83
115 0 30 87 87 87
116 0 30 87 87 87
117 0 30 85 85 85
118 0 30 87 87 87
119 0 30 85 85 85
120 0 30 85 85 85
121 0 30 87 87 87
122 0 30 83 83 83
123 0 30 87 87 87
124 0 30 87 87 87
125 0 30 85 85 85
126 0 30 83 83 83
127 0 30 85 85 85
128 0 30 85 85 85
129 0 30 83 83 83
130 0 30 87 87 87
131 0 30 85 85 85
132 0 30 87 87 87
133 0 30 83 83 83
134 0 30 85 85 85
135 0 30 87 87 87
136 0 30 85 85 85
137 0 30 85 85 85
138 0 30 87 87 87
139 0 30 87 87 87
140 0 30 85 85 85
141 0 30 83 83 83
114 1 30 87 87 87
115 1 30 85 85 85
116 1 30 85 85 85
117 1 30 87 87 87
118 1 30 87 87 87
119 1 30 85 85 85
120 1 30 85 85 85
121 1 30 87 87 87
122 1 30 87 87 87
123 1 30 85 85 85
124 1 30 83 83 83
125 1 30 87 87 87
126 1 30 85 85 85
127 1 30 85 85 85
128 1 30 85 85 85
129 1 30 85 85 85
130 1 30 85 85 85
131 1 30 83 83 83
132 1 30 83 83 83
133 1 30 87 87 87
134 1 30 87 87 87
135 1 30 83 83 83
136 1 30 83 83 83
137 1 30 83 83 83
138 1 30 83 83 83
139 1 30 83 83 83
140 1 30 87 87 87
141 1 30 83 83 83
114 2 30 87 87 87
115 2 30 87 87 87
116 2 30 87 87 87
117 2 30 83 83 83
118 2 30 87 87 87
119 2 30 83 83 83
120 2 30 87 87 87
121 2 30 83 83 83
122 2 30 85 85 85
123 2 30 87 87 87
132 2 30 83 83 83
133 2 30 87 87 87
134 2 30 85 85 85
135 2 30 85 85 85
136 2 30 85 85 85
137 2 30 85 85 85
138 2 30 83 83 83
139 2 30 83 83 83
140 2 30 83 83 83
141 2 30 83 83 83
114 3 30 87 87 87
115 3 30 83 83 83
116 3 30 83 83 83
117 3 30 85 85 85
118 3 30 87 87 87
119 3 30 87 87 87
120 3 30 85 85 85
135 3 30 83 83 83
136 3 30 85 85 85
137 3 30 85 85 85
138 3 30 87 87 87
139 3 30 83 83 83
140 3 30 85 85 85
141 3 30 85 85 85
113 4 30 85 85 85
114 4 30 83 83 83
115 4 30 87 87 87
116 4 30 87 87 87
117 4 30 87 87 87
118 4 30 83 83 83
137 4 30 83 83 83
138 4 30 87 87 87
139 4 30 85 85 85
140 4 30 87 87 87
141 4 30 83 83 83
142 4 30 85 85 85
113 5 30 85 85 85
114 5 30 87 87 87
115 5 30 83 83 83
116 5 30 85 85 85
117 5 30 85 85 85
138 5 30 87 87 87
139 5 30 85 85 85
140 5 30 87 87 87
141 5 30 87 87 87
142 5 30 83 83 83
113 6 30 85 85 85
114 6 30 85 85 85
115 6 30 87 87 87
140 6 30 83 83 83
141 6 30 85 85 85
142 6 30 85 85 85
112 7 30 85 85 85
113 7 30 85 85 85
114 7 30 83 83 83
141 7 30 85 85 85
142 7 30 87 87 87
143 7 30 87 87 87
112 8 30 87 87 87
113 8 30 87 87 87
114 8 30 85 85 85
141 8 30 87 87 87
142 8 30 83 83 83
143 8 30 85 85 85
112 9 30 87 87 87
113 9 30 85 85 85
142 9 30 83 83 83
143 9 30 85 85 85
111 10 30 85 85 85
112 10 30 85 85 85
143 10 30 85 85 85
144 10 30 87 87 87
111 11 30 87 87 87
112 11 30 87 87 87
143 11 30 83 83 83
144 11 30 85 85 85
111 12 30 85 85 85
144 12 30 87 87 87
111 13 30 83 83 83
144 13 30 83 83 83
111 14 30 83 83 83
144 14 30 85 85 85
110 15 30 87 87 87
145 15 30 87 87 87
110 16 30 87 87 87
145 16 30 87 87 87
110 17 30 83 83 83
145 17 30 85 85 85
110 18 30 87 87 87
145 18 30 85 85 85
110 19 30 87 87 87
145 19 30 87 87 87
110 20 30 85 85 85
145 20 30 85 85 85
110 21 30 85 85 85
145 21 30 87 87 87
111 22 30 83 83 83
144 22 30 87 87 87
111 23 30 85 85 85
144 23 30 85 85 85
111 24 30 83 83 83
144 24 30 87 87 87
112 25 30 85 85 85
143 25 30 83 83 83
112 26 30 83 83 83
143 26 30 85 85 85
113 27 30 83 83 83
142 27 30 85 85 85
114 28 30 85 85 85
141 28 30 85 85 85
115 29 30 85 85 85
140 29 30 83 83 83
116 30 30 83 83 83
139 30 30 85 85 85
117 31 30 83 83 83
138 31 30 85 85 85
118 32 30 83 83 83
119 32 30 85 85 85
136 32 30 87 87 87
137 32 30 85 85 85
118 33 30 83 83 83
119 33 30 83 83 83
120 33 30 83 83 83
121 33 30 85 85 85
122 33 30 85 85 85
123 33 30 87 87 87
124 33 30 83 83 83
125 33 30 83 83 83
126 33 30 83 83 83
127 33 30 87 87 87
128 33 30 85 85 85
129 33 30 85 85 85
130 33 30 83 83 83
131 33 30 83 83 83
132 33 30 83 83 83
133 33 30 83 83 83
134 33 30 85 85 85
135 33 30 85 85 85
136 33 30 83 83 83
137 33 30 87 87 87
118 34 30 85 85 85
119 34 30 85 85 85
120 34 30 85 85 85
121 34 30 83 83 83
122 34 30 85 85 85
123 34 30 85 85 85
124 34 30 85 85 85
125 34 30 87 87 87
130 34 30 85 85 85
131 34 30 83 83 83
132 34 30 87 87 87
133 34 30 83 83 83
134 34 30 85 85 85
135 34 30 85 85 85
136 34 30 87 87 87
137 34 30 85 85 85
117 35 30 87 87 87
118 35 30 85 85 85
119 35 30 87 87 87
120 35 30 87 87 87
121 35 30 87 87 87
122 35 30 87 87 87
123 35 30 87 87 87
124 35 30 83 83 83
125 35 30 85 85 85
130 35 30 85 85 85
131 35 30 85 85 85
132 35 30 87 87 87
133 35 30 87 87 87
134 35 30 87 87 87
135 35 30 83 83 83
136 35 30 85 85 85
137 35 30 87 87 87
138 35 30 85 85 85
117 36 30 83 83 83
118 36 30 85 85 85
119 36 30 87 87 87
120 36 30 83 83 83
121 36 30 85 85 85
122 36 30 83 83 83
123 36 30 83 83 83
124 36 30 85 85 85
125 36 30 87 87 87
130 36 30 85 85 85
131 36 30 83 83 83
132 36 30 87 87 87
133 36 30 87 87 87
134 36 30 83 83 83
135 36 30 85 85 85
136 36 30 85 85 85
137 36 30 85 85 85
138 36 30 83 83 83
117 37 30 83 83 83
118 37 30 83 83 83
119 37 30 83 83 83
120 37 30 83 83 83
121 37 30 85 85 85
122 37 30 85 85 85
123 37 30 87 87 87
124 37 30 85 85 85
125 37 30 83 83 83
126 37 30 87 87 87
127 37 30 87 87 87
128 37 30 87 87 87
129 37 30 85 85 85
130 37 30 87 87 87
131 37 30 85 85 85
132 37 30 83 83 83
133 37 30 83 83 83
134 37 30 83 83 83
135 37 30 87 87 87
136 37 30 83 83 83
137 37 30 83 83 83
138 37 30 83 83 83
117 38 30 83 83 83
118 38 30 85 85 85
119 38 30 85 85 85
120 38 30 87 87 87
121 38 30 87 87 87
122 38 30 87 87 87
123 38 30 83 83 83
124 38 30 83 83 83
125 38 30 85 85 85
126 38 30 83 83 83
127 38 30 83 83 83
128 38 30 87 87 87
129 38 30 87 87 87
130 38 30 85 85 85
131 38 30 83 83 83
132 38 30 83 83 83
133 38 30 87 87 87
134 38 30 85 85 85
135 38 30 85 85 85
136 38 30 83 83 83
137 38 30 83 83 83
138 38 30 85 85 85
119 39 30 83 83 83
120 39 30 85 85 85
121 39 30 87 87 87
122 39 30 87 87 87
123 39 30 85 85 85
124 39 30 85 85 85
125 39 30 85 85 85
126 39 30 87 87 87
127 39 30 83 83 83
128 39 30 83 83 83
129 39 30 85 85 85
130 39 30 87 87 87
131 39 30 83 83 83
132 39 30 83 83 83
133 39 30 83 83 83
134 39 30 87 87 87
135 39 30 83 83 83
136 39 30 85 85 85
122 40 30 83 83 83
123 40 30 85 85 85
124 40 30 87 87 87
125 40 30 83 83 83
126 40 30 83 83 83
127 40 30 85 85 85
128 40 30 87 87 87
129 40 30 83 83 83
130 40 30 87 87 87
131 40 30 85 85 85
132 40 30 87 87 87
133 40 30 87 87 87
127 -26 31 85 85 85
128 -26 31 87 87 87
127 -25 31 87 87 87
128 -25 31 85 85 85
127 -24 31 85 85 85
128 -24 31 87 87 87
127 -23 31 83 83 83
128 -23 31 87 87 87
127 -22 31 85 85 85
128 -22 31 87 87 87
127 -21 31 83 83 83
128 -21 31 85 85 85
127 -20 31 83 83 83
128 -20 31 87 87 87
127 -19 31 83 83 83
128 -19 31 83 83 83
127 -18 31 87 87 87
128 -18 31 85 85 85
127 -17 31 85 85 85
128 -17 31 85 85 85
127 -16 31 83 83 83
128 -16 31 83 83 83
127 -15 31 83 83 83
128 -15 31 83 83 83
127 -14 31 83 83 83
128 -14 31 85 85 85
125 -13 31 87 87 87
127 -13 31 83 83 83
128 -13 31 87 87 87
130 -13 31 83 83 83
116 -12 31 83 83 83
117 -12 31 83 83 83
118 -12 31 85 85 85
124 -12 31 85 85 85
125 -12 31 83 83 83
126 -12 31 87 87 87
127 -12 31 87 87 87
128 -12 31 85 85 85
129 -12 31 85 85 85
130 -12 31 87 87 87
131 -12 31 85 85 85
137 -12 31 83 83 83
138 -12 31 87 87 87
139 -12 31 87 87 87
116 -11 31 83 83 83
117 -11 31 87 87 87
118 -11 31 85 85 85
119 -11 31 83 83 83
120 -11 31 87 87 87
121 -11 31 85 85 85
122 -11 31 83 83 83
123 -11 31 85 85 85
124 -11 31 85 85 85
125 -11 31 87 87 87
126 -11 31 87 87 87
127 -11 31 87 87 87
128 -11 31 85 85 85
129 -11 31 85 85 85
130 -11 31 83 83 83
131 -11 31 83 83 83
132 -11 31 83 83 83
133 -11 31 83 83 83
134 -11 31 85 85 85
135 -11 31 85 85 85
136 -11 31 85 85 85
137 -11 31 87 87 87
138 -11 31 83 83 83
139 -11 31 87 87 87
116 -10 31 87 87 87
117 -10 31 83 83 83
118 -10 31 85 85 85
119 -10 31 87 87 87
120 -10 31 85 85 85
121 -10 31 83 83 83
122 -10 31 85 85 85
123 -10 31 87 87 87
124 -10 31 83 83 83
125 -10 31 83 83 83
126 -10 31 87 87 87
127 -10 31 87 87 87
128 -10 31 83 83 83
129 -10 31 87 87 87
130 -10 31 87 87 87
131 -10 31 85 85 85
132 -10 31 85 85 85
133 -10 31 87 87 87
134 -10 31 85 85 85
135 -10 31 83 83 83
136 -10 31 85 85 85
137 -10 31 83 83 83
138 -10 31 87 87 87
139 -10 31 87 87 87
116 -9 31 87 87 87
117 -9 31 83 83 83
118 -9 31 83 83 83
119 -9 31 83 83 83
120 -9 31 83 83 83
121 -9 31 87 87 87
122 -9 31 85 85 85
123 -9 31 83 83 83
124 -9 31 87 87 87
125 -9 31 87 87 87
126 -9 31 83 83 83
127 -9 31 83 83 83
128 -9 31 83 83 83
129 -9 31 87 87 87
130 -9 31 83 83 83
131 -9 31 85 85 85
132 -9 31 85 85 85
133 -9 31 83 83 83
134 -9 31 83 83 83
135 -9 31 87 87 87
136 -9 31 87 87 87
137 -9 31 87 87 87
138 -9 31 85 85 85
139 -9 31 87 87 87
115 -4 31 83 83 83
140 -4 31 83 83 83
115 -3 31 83 83 83
116 -3 31 87 87 87
117 -3 31 83 83 83
118 -3 31 83 83 83
119 -3 31 83 83 83
120 -3 31 83 83 83
121 -3 31 87 87 87
122 -3 31 83 83 83
123 -3 31 83 83 83
124 -3 31 85 85 85
125 -3 31 87 87 87
126 -3 31 87 87 87
127 -3 31 85 85 85
128 -3 31 83 83 83
129 -3 31 87 87 87
130 -3 31 83 83 83
131 -3 31 85 85 85
132 -3 31 83 83 83
133 -3 31 83 83 83
134 -3 31 87 87 87
135 -3 31 87 87 87
136 -3 31 87 87 87
137 -3 31 87 87 87
138 -3 31 85 85 85
139 -3 31 85 85 85
140 -3 31 83 83 83
115 -2 31 83 83 83
140 -2 31 85 85 85
115 -1 31 85 85 85
140 -1 31 83 83 83
114 0 31 85 85 85
141 0 31 85 85 85
114 1 31 87 87 87
141 1 31 85 85 85
114 2 31 83 83 83
141 2 31 85 85 85
114 3 31 83 83 83
141 3 31 83 83 83
113 4 31 85 85 85
142 4 31 83 83 83
113 5 31 85 85 85
142 5 31 87 87 87
113 6 31 85 85 85
142 6 31 85 85 85
112 7 31 87 87 87
143 7 31 83 83 83
112 8 31 87 87 87
143 8 31 87 87 87
112 9 31 85 85 85
143 9 31 85 85 85
111 10 31 85 85 85
144 10 31 85 85 85
111 11 31 85 85 85
144 11 31 83 83 83
111 12 31 83 83 83
144 12 31 87 87 87
111 13 31 85 85 85
144 13 31 83 83 83
111 14 31 83 83 83
144 14 31 87 87 87
110 15 31 87 87 87
145 15 31 87 87 87
110 16 31 87 87 87
145 16 31 83 83 83
110 17 31 83 83 83
145 17 31 83 83 83
110 18 31 83 83 83
145 18 31 83 83 83
110 19 31 85 85 85
145 19 31 85 85 85
110 20 31 85 85 85
145 20 31 87 87 87
110 21 31 83 83 83
145 21 31 83 83 83
111 22 31 87 87 87
144 22 31 83 83 83
111 23 31 87 87 87
144 23 31 83 83 83
111 24 31 83 83 83
144 24 31 85 85 85
112 25 31 85 85 85
143 25 31 83 83 83
112 26 31 87 87 87
143 26 31 87 87 87
113 27 31 83 83 83
142 27 31 85 85 85
114 28 31 87 87 87
141 28 31 83 83 83
115 29 31 85 85 85
140 29 31 83 83 83
116 30 31 83 83 83
139 30 31 85 85 85
117 31 31 83 83 83
138 31 31 85 85 85
118 32 31 87 87 87
119 32 31 83 83 83
136 32 31 87 87 87
137 32 31 83 83 83
118 33 31 87 87 87
120 33 31 83 83 83
121 33 31 83 83 83
122 33 31 87 87 87
123 33 31 85 85 85
124 33 31 83 83 83
125 33 31 85 85 85
126 33 31 87 87 87
127 33 31 83 83 83
128 33 31 83 83 83
129 33 31 83 83 83
130 33 31 87 87 87
131 33 31 85 85 85
132 33 31 85 85 85
133 33 31 83 83 83
134 33 31 87 87 87
135 33 31 83 83 83
137 33 31 85 85 85
118 34 31 85 85 85
123 34 31 83 83 83
124 34 31 83 83 83
125 34 31 87 87 87
130 34 31 87 87 87
131 34 31 85 85 85
132 34 31 87 87 87
137 34 31 83 83 83
117 35 31 85 85 85
118 35 31 85 85 85
125 35 31 87 87 87
130 35 31 87 87 87
137 35 31 85 85 85
138 35 31 85 85 85
117 36 31 83 83 83
125 36 31 87 87 87
130 36 31 85 85 85
137 36 31 85 85 85
138 36 31 85 85 85
117 37 31 85 85 85
126 37 31 83 83 83
127 37 31 83 83 83
128 37 31 87 87 87
129 37 31 83 83 83
138 37 31 87 87 87
117 38 31 87 87 87
118 38 31 83 83 83
119 38 31 87 87 87
136 38 31 85 85 85
137 38 31 87 87 87
138 38 31 85 85 85
119 39 31 83 83 83
120 39 31 83 83 83
121 39 31 87 87 87
122 39 31 83 83 83
133 39 31 87 87 87
134 39 31 83 83 83
135 39 31 83 83 83
136 39 31 83 83 83
122 40 31 85 85 85
123 40 31 85 85 85
124 40 31 83 83 83
125 40 31 87 87 87
126 40 31 85 85 85
127 40 31 83 83 83
128 40 31 83 83 83
129 40 31 87 87 87
130 40 31 83 83 83
131 40 31 83 83 83
132 40 31 83 83 83
133 40 31 85 85 85
125 -68 32 85 85 85
126 -68 32 85 85 85
127 -68 32 83 83 83
128 -68 32 87 87 87
129 -68 32 85 85 85
130 -68 32 87 87 87
125 -67 32 85 85 85
126 -67 32 83 83 83
127 -67 32 87 87 87
128 -67 32 83 83 83
129 -67 32 87 87 87
130 -67 32 87 87 87
125 -66 32 87 87 87
126 -66 32 83 83 83
127 -66 32 85 85 85
128 -66 32 83 83 83
129 -66 32 87 87 87
130 -66 32 87 87 87
125 -65 32 85 85 85
126 -65 32 87 87 87
127 -65 32 83 83 83
128 -65 32 83 83 83
129 -65 32 87 87 87
130 -65 32 85 85 85
125 -64 32 87 87 87
126 -64 32 83 83 83
127 -64 32 85 85 85
128 -64 32 83 83 83
129 -64 32 83 83 83
130 -64 32 85 85 85
126 -63 32 87 87 87
127 -63 32 83 83 83
128 -63 32 85 85 85
129 -63 32 87 87 87
127 -62 32 83 83 83
128 -62 32 85 85 85
127 -61 32 83 83 83
128 -61 32 87 87 87
127 -60 32 83 83 83
128 -60 32 85 85 85
127 -59 32 87 87 87
128 -59 32 87 87 87
127 -58 32 83 83 83
128 -58 32 87 87 87
127 -57 32 85 85 85
128 -57 32 83 83 83
127 -56 32 83 83 83
128 -56 32 87 87 87
127 -55 32 83 83 83
128 -55 32 87 87 87
127 -54 32 87 87 87
128 -54 32 85 85 85
127 -53 32 87 87 87
128 -53 32 83 83 83
127 -52 32 87 87 87
128 -52 32 87 87 87
127 -51 32 83 83 83
128 -51 32 85 85 85
127 -50 32 85 85 85
128 -50 32 85 85 85
127 -49 32 85 85 85
128 -49 32 87 87 87
127 -48 32 87 87 87
128 -48 32 87 87 87
127 -47 32 87 87 87
128 -47 32 83 83 83
127 -46 32 87 87 87
128 -46 32 83 83 83
127 -45 32 83 83 83
128 -45 32 83 83 83
127 -44 32 83 83 83
128 -44 32 85 85 85
127 -43 32 85 85 85
128 -43 32 85 85 85
127 -42 32 83 83 83
128 -42 32 83 83 83
127 -41 32 85 85 85
128 -41 32 83 83 83
127 -40 32 83 83 83
128 -40 32 87 87 87
127 -39 32 85 85 85
128 -39 32 83 83 83
126 -38 32 85 85 85
127 -38 32 83 83 83
128 -38 32 83 83 83
129 -38 32 87 87 87
126 -37 32 85 85 85
127 -37 32 85 85 85
128 -37 32 87 87 87
129 -37 32 83 83 83
126 -36 32 87 87 87
127 -36 32 87 87 87
128 -36 32 85 85 85
129 -36 32 87 87 87
126 -35 32 83 83 83
127 -35 32 83 83 83
128 -35 32 83 83 83
129 -35 32 87 87 87
126 -34 32 83 83 83
127 -34 32 85 85 85
128 -34 32 85 85 85
129 -34 32 85 85 85
126 -33 32 85 85 85
127 -33 32 85 85 85
128 -33 32 85 85 85
129 -33 32 83 83 83
126 -32 32 85 85 85
127 -32 32 83 83 83
128 -32 32 85 85 85
129 -32 32 87 87 87
126 -31 32 83 83 83
127 -31 32 87 87 87
128 -31 32 83 83 83
129 -31 32 87 87 87
126 -30 32 83 83 83
127 -30 32 87 87 87
128 -30 32 87 87 87
129 -30 32 85 85 85
126 -29 32 87 87 87
127 -29 32 85 85 85
128 -29 32 83 83 83
129 -29 32 85 85 85
126 -28 32 87 87 87
127 -28 32 87 87 87
128 -28 32 83 83 83
129 -28 32 83 83 83
126 -27 32 83 83 83
127 -27 32 87 87 87
128 -27 32 83 83 83
129 -27 32 85 85 85
126 -26 32 83 83 83
127 -26 32 83 83 83
128 -26 32 83 83 83
129 -26 32 85 85 85
126 -25 32 83 83 83
127 -25 32 87 87 87
128 -25 32 85 85 85
129 -25 32 83 83 83
126 -24 32 85 85 85
127 -24 32 85 85 85
128 -24 32 85 85 85
129 -24 32 83 83 83
126 -23 32 87 87 87
127 -23 32 83 83 83
128 -23 32 83 83 83
129 -23 32 83 83 83
126 -22 32 83 83 83
127 -22 32 85 85 85
128 -22 32 87 87 87
129 -22 32 87 87 87
126 -21 32 87 87 87
127 -21 32 87 87 87
128 -21 32 87 87 87
129 -21 32 83 83 83
126 -20 32 83 83 83
127 -20 32 85 85 85
128 -20 32 85 85 85
129 -20 32 83 83 83
126 -19 32 83 83 83
127 -19 32 83 83 83
128 -19 32 83 83 83
129 -19 32 85 85 85
126 -18 32 85 85 85
127 -18 32 87 87 87
128 -18 32 85 85 85
129 -18 32 85 85 85
126 -17 32 85 85 85
127 -17 32 83 83 83
128 -17 32 87 87 87
129 -17 32 85 85 85
126 -16 32 87 87 87
127 -16 32 87 87 87
128 -16 32 85 85 85
129 -16 32 85 85 85
126 -15 32 85 85 85
127 -15 32 83 83 83
128 -15 32 83 83 83
129 -15 32 87 87 87
126 -14 32 85 85 85
127 -14 32 83 83 83
128 -14 32 83 83 83
129 -14 32 83 83 83
126 -13 32 87 87 87
127 -13 32 83 83 83
128 -13 32 83 83 83
129 -13 32 87 87 87
116 -12 32 83 83 83
117 -12 32 85 85 85
118 -12 32 87 87 87
123 -12 32 83 83 83
124 -12 32 85 85 85
125 -12 32 87 87 87
126 -12 32 83 83 83
127 -12 32 83 83 83
128 -12 32 87 87 87
129 -12 32 87 87 87
130 -12 32 87 87 87
131 -12 32 83 83 83
132 -12 32 83 83 83
137 -12 32 85 85 85
138 -12 32 85 85 85
139 -12 32 85 85 85
116 -11 32 87 87 87
117 -11 32 87 87 87
118 -11 32 85 85 85
119 -11 32 85 85 85
120 -11 32 83 83 83
121 -11 32 85 85 85
122 -11 32 87 87 87
123 -11 32 87 87 87
124 -11 32 85 85 85
125 -11 32 83 83 83
126 -11 32 83 83 83
127 -11 32 85 85 85
128 -11 32 87 87 87
129 -11 32 87 87 87
130 -11 32 83 83 83
131 -11 32 83 83 83
132 -11 32 83 83 83
133 -11 32 87 87 87
134 -11 32 87 87 87
135 -11 32 87 87 87
136 -11 32 83 83 83
137 -11 32 85 85 85
138 -11 32 85 85 85
139 -11 32 83 83 83
116 -10 32 87 87 87
117 -10 32 85 85 85
118 -10 32 87 87 87
119 -10 32 83 83 83
120 -10 32 85 85 85
121 -10 32 85 85 85
122 -10 32 83 83 83
123 -10 32 87 87 87
124 -10 32 83 83 83
125 -10 32 83 83 83
126 -10 32 83 83 83
127 -10 32 83 83 83
128 -10 32 87 87 87
129 -10 32 85 85 85
130 -10 32 83 83 83
131 -10 32 83 83 83
132 -10 32 87 87 87
133 -10 32 87 87 87
134 -10 32 85 85 85
135 -10 32 85 85 85
136 -10 32 83 83 83
137 -10 32 85 85 85
138 -10 32 83 83 83
139 -10 32 87 87 87
116 -9 32 87 87 87
117 -9 32 83 83 83
118 -9 32 83 83 83
119 -9 32 85 85 85
120 -9 32 83 83 83
121 -9 32 83 83 83
122 -9 32 85 85 85
123 -9 32 87 87 87
124 -9 32 87 87 87
125 -9 32 83 83 83
126 -9 32 83 83 83
127 -9 32 87 87 87
128 -9 32 83 83 83
129 -9 32 83 83 83
130 -9 32 83 83 83
131 -9 32 85 85 85
132 -9 32 83 83 83
133 -9 32 83 83 83
134 -9 32 85 85 85
135 -9 32 83 83 83
136 -9 32 87 87 87
137 -9 32 83 83 83
138 -9 32 85 85 85
139 -9 32 87 87 87
115 -5 32 87 87 87
140 -5 32 87 87 87
115 -4 32 85 85 85
140 -4 32 83 83 83
114 -3 32 83 83 83
115 -3 32 85 85 85
116 -3 32 83 83 83
117 -3 32 85 85 85
118 -3 32 85 85 85
119 -3 32 83 83 83
120 -3 32 87 87 87
121 -3 32 85 85 85
122 -3 32 83 83 83
123 -3 32 85 85 85
124 -3 32 83 83 83
125 -3 32 83 83 83
126 -3 32 87 87 87
127 -3 32 85 85 85
128 -3 32 85 85 85
129 -3 32 85 85 85
130 -3 32 85 85 85
131 -3 32 87 87 87
132 -3 32 87 87 87
133 -3 32 83 83 83
134 -3 32 85 85 85
135 -3 32 85 85 85
136 -3 32 87 87 87
137 -3 32 85 85 85
138 -3 32 83 83 83
139 -3 32 87 87 87
140 -3 32 87 87 87
141 -3 32 87 87 87
114 -2 32 83 83 83
115 -2 32 85 85 85
140 -2 32 87 87 87
141 -2 32 83 83 83
115 -1 32 83 83 83
140 -1 32 85 85 85
114 0 32 87 87 87
141 0 32 83 83 83
114 1 32 87 87 87
141 1 32 83 83 83
114 2 32 83 83 83
141 2 32 83 83 83
114 3 32 83 83 83
141 3 32 87 87 87
113 4 32 85 85 85
142 4 32 85 85 85
113 5 32 83 83 83
142 5 32 83 83 83
113 6 32 83 83 83
142 6 32 83 83 83
112 7 32 83 83 83
143 7 32 85 85 85
112 8 32 87 87 87
143 8 32 85 85 85
112 9 32 83 83 83
143 9 32 87 87 87
111 10 32 85 85 85
144 10 32 87 87 87
111 11 32 87 87 87
144 11 32 85 85 85
111 12 32 83 83 83
144 12 32 83 83 83
111 13 32 85 85 85
144 13 32 85 85 85
111 14 32 87 87 87
144 14 32 87 87 87
110 15 32 83 83 83
145 15 32 83 83 83
110 16 32 87 87 87
145 16 32 85 85 85
110 17 32 85 85 85
145 17 32 87 87 87
110 18 32 83 83 83
145 18 32 83 83 83
110 19 32 83 83 83
145 19 32 85 85 85
110 20 32 87 87 87
145 20 32 85 85 85
110 21 32 83 83 83
145 21 32 83 83 83
111 22 32 83 83 83
144 22 32 85 85 85
111 23 32 83 83 83
144 23 32 83 83 83
111 24 32 87 87 87
144 24 32 87 87 87
112 25 32 85 85 85
143 25 32 83 83 83
112 26 32 83 83 83
143 26 32 85 85 85
113 27 32 83 83 83
142 27 32 87 87 87
114 28 32 85 85 85
141 28 32 87 87 87
115 29 32 83 83 83
140 29 32 83 83 83
116 30 32 85 85 85
139 30 32 87 87 87
117 31 32 85 85 85
138 31 32 87 87 87
118 32 32 83 83 83
119 32 32 85 85 85
136 32 32 85 85 85
137 32 32 83 83 83
118 33 32 83 83 83
120 33 32 87 87 87
121 33 32 87 87 87
122 33 32 85 85 85
123 33 32 85 85 85
124 33 32 85 85 85
125 33 32 87 87 87
126 33 32 87 87 87
127 33 32 83 83 83
128 33 32 85 85 85
129 33 32 85 85 85
130 33 32 83 83 83
131 33 32 87 87 87
132 33 32 85 85 85
133 33 32 85 85 85
134 33 32 83 83 83
135 33 32 85 85 85
137 33 32 85 85 85
118 34 32 87 87 87
123 34 32 87 87 87
124 34 32 83 83 83
125 34 32 85 85 85
130 34 32 85 85 85
131 34 32 83 83 83
132 34 32 85 85 85
137 34 32 87 87 87
117 35 32 85 85 85
118 35 32 85 85 85
125 35 32 85 85 85
130 35 32 87 87 87
137 35 32 85 85 85
138 35 32 83 83 83
117 36 32 83 83 83
125 36 32 87 87 87
130 36 32 85 85 85
137 36 32 83 83 83
138 36 32 83 83 83
117 37 32 85 85 85
126 37 32 87 87 87
127 37 32 83 83 83
128 37 32 87 87 87
129 37 32 87 87 87
138 37 32 85 85 85
117 38 32 83 83 83
118 38 32 83 83 83
119 38 32 87 87 87
136 38 32 83 83 83
137 38 32 83 83 83
138 38 32 87 87 87
119 39 32 85 85 85
120 39 32 83 83 83
121 39 32 83 83 83
122 39 32 83 83 83
133 39 32 85 85 85
134 39 32 83 83 83
135 39 32 87 87 87
136 39 32 87 87 87
122 40 32 87 87 87
123 40 32 85 85 85
124 40 32 85 85 85
125 40 32 87 87 87
126 40 32 83 83 83
127 40 32 87 87 87
128 40 32 87 87 87
129 40 32 83 83 83
130 40 32 87 87 87
131 40 32 85 85 85
132 40 32 85 85 85
133 40 32 87 87 87
125 -68 33 83 83 83
126 -68 33 87 87 87
129 -68 33 85 85 85
130 -68 33 87 87 87
125 -64 33 87 87 87
130 -64 33 83 83 83
125 -63 33 87 87 87
126 -63 33 85 85 85
129 -63 33 85 85 85
130 -63 33 85 85 85
126 -62 33 87 87 87
129 -62 33 83 83 83
126 -61 33 83 83 83
129 -61 33 83 83 83
126 -60 33 87 87 87
129 -60 33 85 85 85
126 -59 33 87 87 87
129 -59 33 85 85 85
126 -58 33 83 83 83
129 -58 33 87 87 87
126 -57 33 85 85 85
129 -57 33 83 83 83
126 -56 33 85 85 85
129 -56 33 87 87 87
126 -55 33 85 85 85
129 -55 33 85 85 85
126 -54 33 85 85 85
129 -54 33 87 87 87
126 -53 33 85 85 85
129 -53 33 85 85 85
126 -52 33 85 85 85
129 -52 33 83 83 83
126 -51 33 83 83 83
129 -51 33 87 87 87
126 -50 33 87 87 87
129 -50 33 83 83 83
126 -49 33 85 85 85
129 -49 33 83 83 83
126 -48 33 83 83 83
129 -48 33 83 83 83
126 -47 33 87 87 87
129 -47 33 87 87 87
126 -46 33 83 83 83
129 -46 33 83 83 83
126 -45 33 85 85 85
129 -45 33 83 83 83
126 -44 33 87 87 87
129 -44 33 83 83 83
126 -43 33 87 87 87
129 -43 33 87 87 87
126 -42 33 83 83 83
129 -42 33 85 85 85
126 -41 33 83 83 83
129 -41 33 87 87 87
126 -40 33 87 87 87
129 -40 33 85 85 85
126 -39 33 87 87 87
129 -39 33 85 85 85
126 -38 33 83 83 83
129 -38 33 85 85 85
126 -37 33 87 87 87
129 -37 33 83 83 83
126 -36 33 83 83 83
129 -36 33 83 83 83
126 -35 33 87 87 87
129 -35 33 85 85 85
126 -34 33 83 83 83
129 -34 33 83 83 83
126 -33 33 83 83 83
129 -33 33 83 83 83
126 -32 33 87 87 87
129 -32 33 87 87 87
126 -31 33 83 83 83
129 -31 33 83 83 83
126 -30 33 87 87 87
129 -30 33 83 83 83
126 -29 33 83 83 83
129 -29 33 85 85 85
126 -28 33 87 87 87
129 -28 33 85 85 85
126 -27 33 87 87 87
129 -27 33 85 85 85
125 -26 33 83 83 83
126 -26 33 85 85 85
129 -26 33 83 83 83
130 -26 33 83 83 83
125 -25 33 83 83 83
126 -25 33 87 87 87
129 -25 33 83 83 83
130 -25 33 85 85 85
125 -24 33 83 83 83
126 -24 33 85 85 85
129 -24 33 85 85 85
130 -24 33 85 85 85
125 -23 33 85 85 85
126 -23 33 87 87 87
129 -23 33 87 87 87
130 -23 33 83 83 83
125 -22 33 83 83 83
126 -22 33 83 83 83
129 -22 33 87 87 87
130 -22 33 83 83 83
125 -21 33 83 83 83
126 -21 33 85 85 85
129 -21 33 83 83 83
130 -21 33 85 85 85
125 -20 33 83 83 83
126 -20 33 83 83 83
129 -20 33 85 85 85
130 -20 33 87 87 87
125 -19 33 83 83 83
126 -19 33 87 87 87
129 -19 33 87 87 87
130 -19 33 83 83 83
125 -18 33 87 87 87
126 -18 33 83 83 83
129 -18 33 85 85 85
130 -18 33 83 83 83
125 -17 33 83 83 83
126 -17 33 85 85 85
129 -17 33 85 85 85
130 -17 33 87 87 87
125 -16 33 85 85 85
126 -16 33 83 83 83
129 -16 33 83 83 83
130 -16 33 87 87 87
125 -15 33 83 83 83
126 -15 33 83 83 83
129 -15 33 83 83 83
130 -15 33 83 83 83
125 -14 33 83 83 83
126 -14 33 83 83 83
129 -14 33 87 87 87
130 -14 33 87 87 87
125 -13 33 83 83 83
126 -13 33 85 85 85
129 -13 33 85 85 85
130 -13 33 85 85 85
116 -12 33 83 83 83
117 -12 33 83 83 83
118 -12 33 83 83 83
123 -12 33 85 85 85
124 -12 33 85 85 85
125 -12 33 83 83 83
126 -12 33 83 83 83
129 -12 33 85 85 85
130 -12 33 85 85 85
131 -12 33 87 87 87
132 -12 33 83 83 83
137 -12 33 85 85 85
138 -12 33 87 87 87
139 -12 33 85 85 85
116 -11 33 85 85 85
117 -11 33 87 87 87
118 -11 33 83 83 83
119 -11 33 83 83 83
120 -11 33 87 87 87
121 -11 33 87 87 87
122 -11 33 87 87 87
123 -11 33 83 83 83
124 -11 33 85 85 85
125 -11 33 85 85 85
126 -11 33 87 87 87
129 -11 33 83 83 83
130 -11 33 83 83 83
131 -11 33 87 87 87
132 -11 33 83 83 83
133 -11 33 85 85 85
134 -11 33 83 83 83
135 -11 33 85 85 85
136 -11 33 87 87 87
137 -11 33 87 87 87
138 -11 33 85 85 85
139 -11 33 87 87 87
116 -10 33 87 87 87
117 -10 33 85 85 85
118 -10 33 85 85 85
119 -10 33 87 87 87
120 -10 33 83 83 83
121 -10 33 85 85 85
122 -10 33 83 83 83
123 -10 33 83 83 83
124 -10 33 85 85 85
125 -10 33 85 85 85
126 -10 33 87 87 87
129 -10 33 87 87 87
130 -10 33 85 85 85
131 -10 33 87 87 87
132 -10 33 83 83 83
133 -10 33 83 83 83
134 -10 33 85 85 85
135 -10 33 87 87 87
136 -10 33 85 85 85
137 -10 33 83 83 83
138 -10 33 83 83 83
139 -10 33 87 87 87
116 -9 33 87 87 87
117 -9 33 87 87 87
118 -9 33 83 83 83
119 -9 33 87 87 87
120 -9 33 83 83 83
121 -9 33 87 87 87
122 -9 33 85 85 85
123 -9 33 83 83 83
124 -9 33 83 83 83
125 -9 33 83 83 83
126 -9 33 83 83 83
127 -9 33 31 31 31
128 -9 33 31 31 31
129 -9 33 87 87 87
130 -9 33 87 87 87
131 -9 33 83 83 83
132 -9 33 83 83 83
133 -9 33 85 85 85
134 -9 33 83 83 83
135 -9 33 85 85 85
136 -9 33 85 85 85
137 -9 33 87 87 87
138 -9 33 87 87 87
139 -9 33 87 87 87
115 -5 33 87 87 87
140 -5 33 83 83 83
114 -4 33 87 87 87
115 -4 33 83 83 83
140 -4 33 85 85 85
141 -4 33 85 85 85
114 -3 33 85 85 85
115 -3 33 83 83 83
116 -3 33 87 87 87
117 -3 33 87 87 87
118 -3 33 85 85 85
119 -3 33 87 87 87
120 -3 33 85 85 85
121 -3 33 83 83 83
122 -3 33 85 85 85
123 -3 33 85 85 85
124 -3 33 83 83 83
125 -3 33 87 87 87
126 -3 33 83 83 83
127 -3 33 87 87 87
128 -3 33 87 87 87
129 -3 33 87 87 87
130 -3 33 83 83 83
131 -3 33 83 83 83
132 -3 33 85 85 85
133 -3 33 85 85 85
134 -3 33 87 87 87
135 -3 33 83 83 83
136 -3 33 87 87 87
137 -3 33 87 87 87
138 -3 33 87 87 87
139 -3 33 87 87 87
140 -3 33 83 83 83
141 -3 33 85 85 85
115 -2 33 83 83 83
140 -2 33 85 85 85
114 -1 33 85 85 85
115 -1 33 83 83 83
140 -1 33 87 87 87
141 -1 33 87 87 87
114 0 33 87 87 87
141 0 33 85 85 85
114 1 33 85 85 85
141 1 33 85 85 85
114 2 33 85 85 85
141 2 33 87 87 87
114 3 33 85 85 85
141 3 33 87 87 87
113 4 33 85 85 85
142 4 33 83 83 83
113 5 33 87 87 87
142 5 33 83 83 83
113 6 33 85 85 85
142 6 33 87 87 87
112 7 33 87 87 87
143 7 33 85 85 85
112 8 33 87 87 87
143 8 33 87 87 87
112 9 33 85 85 85
143 9 33 85 85 85
111 10 33 85 85 85
144 10 33 87 87 87
110 11 33 85 85 85
111 11 33 85 85 85
144 11 33 85 85 85
145 11 33 85 85 85
110 12 33 87 87 87
111 12 33 85 85 85
144 12 33 85 85 85
145 12 33 87 87 87
110 13 33 83 83 83
111 13 33 87 87 87
144 13 33 85 85 85
145 13 33 83 83 83
111 14 33 85 85 85
144 14 33 85 85 85
110 15 33 83 83 83
145 15 33 85 85 85
110 16 33 85 85 85
145 16 33 87 87 87
110 17 33 85 85 85
145 17 33 87 87 87
110 18 33 83 83 83
145 18 33 83 83 83
110 19 33 85 85 85
145 19 33 87 87 87
110 20 33 85 85 85
145 20 33 87 87 87
110 21 33 87 87 87
145 21 33 83 83 83
111 22 33 83 83 83
144 22 33 83 83 83
111 23 33 87 87 87
144 23 33 85 85 85
111 24 33 87 87 87
144 24 33 83 83 83
112 25 33 85 85 85
143 25 33 85 85 85
112 26 33 83 83 83
143 26 33 85 85 85
113 27 33 83 83 83
142 27 33 83 83 83
114 28 33 85 85 85
141 28 33 83 83 83
115 29 33 83 83 83
140 29 33 85 85 85
116 30 33 87 87 87
139 30 33 87 87 87
117 31 33 85 85 85
138 31 33 85 85 85
118 32 33 85 85 85
119 32 33 83 83 83
136 32 33 87 87 87
137 32 33 87 87 87
118 33 33 85 85 85
120 33 33 83 83 83
121 33 33 87 87 87
122 33 33 87 87 87
123 33 33 83 83 83
124 33 33 85 85 85
125 33 33 83 83 83
126 33 33 85 85 85
127 33 33 85 85 85
128 33 33 85 85 85
129 33 33 83 83 83
130 33 33 85 85 85
131 33 33 83 83 83
132 33 33 83 83 83
133 33 33 83 83 83
134 33 33 83 83 83
135 33 33 85 85 85
137 33 33 85 85 85
118 34 33 87 87 87
123 34 33 85 85 85
124 34 33 83 83 83
125 34 33 85 85 85
130 34 33 83 83 83
131 34 33 87 87 87
132 34 33 87 87 87
137 34 33 85 85 85
117 35 33 87 87 87
118 35 33 87 87 87
125 35 33 85 85 85
130 35 33 87 87 87
137 35 33 83 83 83
138 35 33 85 85 85
117 36 33 85 85 85
125 36 33 83 83 83
130 36 33 83 83 83
137 36 33 83 83 83
138 36 33 85 85 85
117 37 33 87 87 87
126 37 33 85 85 85
127 37 33 87 87 87
128 37 33 83 83 83
129 37 33 85 85 85
138 37 33 85 85 85
117 38 33 87 87 87
118 38 33 83 83 83
119 38 33 85 85 85
136 38 33 83 83 83
137 38 33 83 83 83
138 38 33 85 85 85
119 39 33 87 87 87
120 39 33 85 85 85
121 39 33 87 87 87
122 39 33 83 83 83
133 39 33 83 83 83
134 39 33 83 83 83
135 39 33 85 85 85
136 39 33 87 87 87
122 40 33 87 87 87
123 40 33 85 85 85
124 40 33 87 87 87
125 40 33 85 85 85
126 40 33 83 83 83
127 40 33 83 83 83
128 40 33 85 85 85
129 40 33 85 85 85
130 40 33 83 83 83
131 40 33 83 83 83
132 40 33 83 83 83
133 40 33 87 87 87
125 -68 34 87 87 87
126 -68 34 87 87 87
129 -68 34 85 85 85
130 -68 34 85 85 85
125 -64 34 85 85 85
130 -64 34 87 87 87
125 -63 34 87 87 87
126 -63 34 87 87 87
129 -63 34 83 83 83
130 -63 34 87 87 87
126 -62 34 85 85 85
129 -62 34 87 87 87
126 -61 34 83 83 83
129 -61 34 85 85 85
126 -60 34 83 83 83
129 -60 34 87 87 87
126 -59 34 85 85 85
129 -59 34 83 83 83
126 -58 34 85 85 85
129 -58 34 83 83 83
126 -57 34 83 83 83
129 -57 34 85 85 85
126 -56 34 85 85 85
129 -56 34 87 87 87
126 -55 34 85 85 85
129 -55 34 83 83 83
126 -54 34 83 83 83
129 -54 34 83 83 83
126 -53 34 85 85 85
129 -53 34 87 87 87
126 -52 34 83 83 83
129 -52 34 87 87 87
126 -51 34 83 83 83
129 -51 34 83 83 83
126 -50 34 87 87 87
129 -50 34 87 87 87
126 -49 34 87 87 87
129 -49 34 85 85 85
126 -48 34 85 85 85
129 -48 34 85 85 85
126 -47 34 83 83 83
129 -47 34 85 85 85
126 -46 34 83 83 83
129 -46 34 83 83 83
126 -45 34 83 83 83
129 -45 34 85 85 85
126 -44 34 85 85 85
129 -44 34 83 83 83
126 -43 34 85 85 85
129 -43 34 85 85 85
126 -42 34 85 85 85
129 -42 34 85 85 85
126 -41 34 87 87 87
129 -41 34 83 83 83
126 -40 34 85 85 85
129 -40 34 85 85 85
126 -39 34 83 83 83
129 -39 34 85 85 85
126 -38 34 83 83 83
129 -38 34 85 85 85
126 -37 34 83 83 83
129 -37 34 85 85 85
126 -36 34 87 87 87
129 -36 34 83 83 83
126 -35 34 87 87 87
129 -35 34 83 83 83
126 -34 34 87 87 87
129 -34 34 87 87 87
126 -33 34 83 83 83
129 -33 34 85 85 85
126 -32 34 83 83 83
129 -32 34 83 83 83
126 -31 34 83 83 83
129 -31 34 85 85 85
126 -30 34 87 87 87
129 -30 34 83 83 83
126 -29 34 85 85 85
129 -29 34 87 87 87
126 -28 34 87 87 87
129 -28 34 85 85 85
126 -27 34 87 87 87
129 -27 34 87 87 87
125 -26 34 85 85 85
126 -26 34 85 85 85
129 -26 34 83 83 83
130 -26 34 85 85 85
125 -25 34 87 87 87
126 -25 34 87 87 87
129 -25 34 83 83 83
130 -25 34 85 85 85
125 -24 34 83 83 83
126 -24 34 83 83 83
129 -24 34 87 87 87
130 -24 34 83 83 83
125 -23 34 85 85 85
126 -23 34 83 83 83
129 -23 34 85 85 85
130 -23 34 85 85 85
125 -22 34 87 87 87
126 -22 34 85 85 85
129 -22 34 85 85 85
130 -22 34 85 85 85
125 -21 34 87 87 87
126 -21 34 83 83 83
129 -21 34 83 83 83
130 -21 34 87 87 87
125 -20 34 83 83 83
126 -20 34 83 83 83
129 -20 34 87 87 87
130 -20 34 83 83 83
125 -19 34 87 87 87
126 -19 34 85 85 85
129 -19 34 87 87 87
130 -19 34 87 87 87
125 -18 34 87 87 87
126 -18 34 85 85 85
129 -18 34 87 87 87
130 -18 34 87 87 87
125 -17 34 87 87 87
126 -17 34 87 87 87
129 -17 34 87 87 87
130 -17 34 83 83 83
125 -16 34 85 85 85
126 -16 34 85 85 85
129 -16 34 85 85 85
130 -16 34 83 83 83
125 -15 34 83 83 83
126 -15 34 85 85 85
129 -15 34 85 85 85
130 -15 34 85 85 85
125 -14 34 83 83 83
126 -14 34 83 83 83
129 -14 34 87 87 87
130 -14 34 83 83 83
125 -13 34 83 83 83
126 -13 34 83 83 83
129 -13 34 83 83 83
130 -13 34 87 87 87
116 -12 34 85 85 85
117 -12 34 83 83 83
118 -12 34 85 85 85
123 -12 34 83 83 83
124 -12 34 83 83 83
125 -12 34 83 83 83
126 -12 34 83 83 83
129 -12 34 85 85 85
130 -12 34 83 83 83
131 -12 34 87 87 87
132 -12 34 83 83 83
137 -12 34 85 85 85
138 -12 34 87 87 87
139 -12 34 83 83 83
116 -11 34 83 83 83
117 -11 34 85 85 85
118 -11 34 83 83 83
119 -11 34 87 87 87
120 -11 34 87 87 87
121 -11 34 87 87 87
122 -11 34 85 85 85
123 -11 34 83 83 83
124 -11 34 87 87 87
125 -11 34 87 87 87
126 -11 34 87 87 87
129 -11 34 83 83 83
130 -11 34 87 87 87
131 -11 34 85 85 85
132 -11 34 85 85 85
133 -11 34 85 85 85
134 -11 34 85 85 85
135 -11 34 85 85 85
136 -11 34 83 83 83
137 -11 34 83 83 83
138 -11 34 87 87 87
139 -11 34 87 87 87
116 -10 34 87 87 87
117 -10 34 85 85 85
118 -10 34 85 85 85
119 -10 34 85 85 85
120 -10 34 85 85 85
121 -10 34 85 85 85
122 -10 34 83 83 83
123 -10 34 87 87 87
124 -10 34 83 83 83
125 -10 34 85 85 85
126 -10 34 83 83 83
129 -10 34 83 83 83
130 -10 34 87 87 87
131 -10 34 83 83 83
132 -10 34 83 83 83
133 -10 34 83 83 83
134 -10 34 85 85 85
135 -10 34 83 83 83
136 -10 34 85 85 85
137 -10 34 83 83 83
138 -10 34 85 85 85
139 -10 34 87 87 87
116 -9 34 87 87 87
117 -9 34 87 87 87
118 -9 34 83 83 83
119 -9 34 85 85 85
120 -9 34 85 85 85
121 -9 34 83 83 83
122 -9 34 87 87 87
123 -9 34 83 83 83
124 -9 34 83 83 83
125 -9 34 87 87 87
126 -9 34 85 85 85
127 -9 34 31 31 31
128 -9 34 31 31 31
129 -9 34 87 87 87
130 -9 34 87 87 87
131 -9 34 85 85 85
132 -9 34 87 87 87
133 -9 34 87 87 87
134 -9 34 83 83 83
135 -9 34 85 85 85
136 -9 34 85 85 85
137 -9 34 83 83 83
138 -9 34 85 85 85
139 -9 34 87 87 87
115 -5 34 85 85 85
140 -5 34 83 83 83
114 -4 34 87 87 87
115 -4 34 83 83 83
140 -4 34 87 87 87
141 -4 34 87 87 87
115 -3 34 87 87 87
116 -3 34 83 83 83
117 -3 34 83 83 83
118 -3 34 83 83 83
119 -3 34 83 83 83
120 -3 34 85 85 85
121 -3 34 85 85 85
122 -3 34 87 87 87
123 -3 34 85 85 85
124 -3 34 85 85 85
125 -3 34 83 83 83
126 -3 34 83 83 83
127 -3 34 87 87 87
128 -3 34 87 87 87
129 -3 34 83 83 83
130 -3 34 87 87 87
131 -3 34 83 83 83
132 -3 34 83 83 83
133 -3 34 83 83 83
134 -3 34 83 83 83
135 -3 34 83 83 83
136 -3 34 83 83 83
137 -3 34 87 87 87
138 -3 34 87 87 87
139 -3 34 87 87 87
140 -3 34 87 87 87
114 -2 34 87 87 87
115 -2 34 87 87 87
140 -2 34 83 83 83
141 -2 34 87 87 87
114 -1 34 85 85 85
115 -1 34 87 87 87
140 -1 34 85 85 85
141 -1 34 83 83 83
114 0 34 83 83 83
141 0 34 85 85 85
114 1 34 83 83 83
141 1 34 87 87 87
114 2 34 83 83 83
141 2 34 85 85 85
114 3 34 87 87 87
141 3 34 87 87 87
113 4 34 83 83 83
142 4 34 83 83 83
113 5 34 85 85 85
142 5 34 85 85 85
113 6 34 85 85 85
142 6 34 85 85 85
112 7 34 85 85 85
143 7 34 83 83 83
112 8 34 85 85 85
143 8 34 85 85 85
112 9 34 85 85 85
143 9 34 85 85 85
110 10 34 87 87 87
111 10 34 87 87 87
144 10 34 87 87 87
145 10 34 85 85 85
110 11 34 85 85 85
111 11 34 87 87 87
144 11 34 85 85 85
145 11 34 87 87 87
110 12 34 85 85 85
111 12 34 83 83 83
144 12 34 85 85 85
145 12 34 87 87 87
110 13 34 85 85 85
111 13 34 85 85 85
144 13 34 85 85 85
145 13 34 85 85 85
110 14 34 87 87 87
111 14 34 83 83 83
144 14 34 85 85 85
145 14 34 83 83 83
110 15 34 85 85 85
145 15 34 85 85 85
110 16 34 85 85 85
145 16 34 83 83 83
110 17 34 85 85 85
145 17 34 87 87 87
110 18 34 85 85 85
145 18 34 85 85 85
110 19 34 87 87 87
145 19 34 83 83 83
110 20 34 87 87 87
145 20 34 85 85 85
110 21 34 85 85 85
145 21 34 87 87 87
111 22 34 87 87 87
144 22 34 83 83 83
111 23 34 83 83 83
144 23 34 85 85 85
111 24 34 85 85 85
144 24 34 85 85 85
112 25 34 85 85 85
143 25 34 85 85 85
112 26 34 83 83 83
143 26 34 87 87 87
113 27 34 83 83 83
142 27 34 87 87 87
114 28 34 85 85 85
141 28 34 83 83 83
115 29 34 85 85 85
140 29 34 83 83 83
116 30 34 87 87 87
139 30 34 85 85 85
117 31 34 83 83 83
138 31 34 85 85 85
118 32 34 83 83 83
119 32 34 85 85 85
136 32 34 87 87 87
137 32 34 85 85 85
118 33 34 85 85 85
120 33 34 85 85 85
121 33 34 83 83 83
122 33 34 83 83 83
123 33 34 83 83 83
124 33 34 85 85 85
125 33 34 85 85 85
126 33 34 83 83 83
127 33 34 85 85 85
128 33 34 87 87 87
129 33 34 85 85 85
130 33 34 83 83 83
131 33 34 83 83 83
132 33 34 87 87 87
133 33 34 87 87 87
134 33 34 87 87 87
135 33 34 87 87 87
137 33 34 85 85 85
118 34 34 83 83 83
123 34 34 83 83 83
124 34 34 83 83 83
125 34 34 85 85 85
130 34 34 85 85 85
131 34 34 87 87 87
132 34 34 83 83 83
137 34 34 87 87 87
117 35 34 83 83 83
118 35 34 87 87 87
125 35 34 83 83 83
130 35 34 85 85 85
137 35 34 87 87 87
138 35 34 85 85 85
117 36 34 83 83 83
125 36 34 85 85 85
130 36 34 83 83 83
137 36 34 87 87 87
138 36 34 83 83 83
117 37 34 85 85 85
126 37 34 87 87 87
127 37 34 85 85 85
128 37 34 85 85 85
129 37 34 85 85 85
138 37 34 85 85 85
117 38 34 83 83 83
118 38 34 83 83 83
119 38 34 83 83 83
136 38 34 85 85 85
137 38 34 83 83 83
138 38 34 85 85 85
119 39 34 85 85 85
120 39 34 85 85 85
121 39 34 85 85 85
122 39 34 83 83 83
133 39 34 87 87 87
134 39 34 83 83 83
135 39 34 85 85 85
136 39 34 87 87 87
122 40 34 83 83 83
123 40 34 83 83 83
124 40 34 87 87 87
125 40 34 85 85 85
126 40 34 87 87 87
127 40 34 85 85 85
128 40 34 87 87 87
129 40 34 85 85 85
130 40 34 83 83 83
131 40 34 85 85 85
132 40 34 85 85 85
133 40 34 87 87 87
125 -68 35 85 85 85
126 -68 35 85 85 85
127 -68 35 83 83 83
128 -68 35 85 85 85
129 -68 35 85 85 85
130 -68 35 83 83 83
125 -67 35 87 87 87
126 -67 35 85 85 85
127 -67 35 85 85 85
128 -67 35 87 87 87
129 -67 35 87 87 87
130 -67 35 85 85 85
125 -66 35 85 85 85
126 -66 35 87 87 87
127 -66 35 87 87 87
128 -66 35 83 83 83
129 -66 35 83 83 83
130 -66 35 85 85 85
125 -65 35 83 83 83
126 -65 35 87 87 87
127 -65 35 85 85 85
128 -65 35 85 85 85
129 -65 35 83 83 83
130 -65 35 83 83 83
125 -64 35 83 83 83
126 -64 35 87 87 87
127 -64 35 87 87 87
128 -64 35 87 87 87
129 -64 35 87 87 87
130 -64 35 87 87 87
126 -63 35 87 87 87
127 -63 35 83 83 83
128 -63 35 87 87 87
129 -63 35 85 85 85
127 -62 35 87 87 87
128 -62 35 87 87 87
127 -61 35 87 87 87
128 -61 35 83 83 83
127 -60 35 87 87 87
128 -60 35 83 83 83
127 -59 35 83 83 83
128 -59 35 87 87 87
127 -58 35 85 85 85
128 -58 35 83 83 83
127 -57 35 83 83 83
128 -57 35 87 87 87
127 -56 35 85 85 85
128 -56 35 87 87 87
127 -55 35 87 87 87
128 -55 35 83 83 83
127 -54 35 85 85 85
128 -54 35 85 85 85
127 -53 35 87 87 87
128 -53 35 83 83 83
127 -52 35 83 83 83
128 -52 35 85 85 85
127 -51 35 83 83 83
128 -51 35 87 87 87
127 -50 35 83 83 83
128 -50 35 87 87 87
127 -49 35 83 83 83
128 -49 35 83 83 83
127 -48 35 85 85 85
128 -48 35 85 85 85
127 -47 35 85 85 85
128 -47 35 83 83 83
127 -46 35 83 83 83
128 -46 35 83 83 83
127 -45 35 87 87 87
128 -45 35 87 87 87
127 -44 35 87 87 87
128 -44 35 85 85 85
127 -43 35 85 85 85
128 -43 35 87 87 87
127 -42 35 85 85 85
128 -42 35 87 87 87
127 -41 35 83 83 83
128 -41 35 87 87 87
127 -40 35 85 85 85
128 -40 35 87 87 87
127 -39 35 83 83 83
128 -39 35 85 85 85
126 -38 35 83 83 83
127 -38 35 83 83 83
128 -38 35 85 85 85
129 -38 35 83 83 83
126 -37 35 83 83 83
127 -37 35 87 87 87
128 -37 35 83 83 83
129 -37 35 83 83 83
126 -36 35 83 83 83
127 -36 35 85 85 85
128 -36 35 83 83 83
129 -36 35 87 87 87
126 -35 35 87 87 87
127 -35 35 83 83 83
128 -35 35 87 87 87
129 -35 35 87 87 87
126 -34 35 87 87 87
127 -34 35 83 83 83
128 -34 35 85 85 85
129 -34 35 85 85 85
126 -33 35 85 85 85
127 -33 35 85 85 85
128 -33 35 83 83 83
129 -33 35 85 85 85
126 -32 35 87 87 87
127 -32 35 85 85 85
128 -32 35 87 87 87
129 -32 35 85 85 85
126 -31 35 87 87 87
127 -31 35 83 83 83
128 -31 35 87 87 87
129 -31 35 83 83 83
126 -30 35 85 85 85
127 -30 35 83 83 83
128 -30 35 83 83 83
129 -30 35 85 85 85
126 -29 35 83 83 83
127 -29 35 87 87 87
128 -29 35 83 83 83
129 -29 35 83 83 83
126 -28 35 87 87 87
127 -28 35 87 87 87
128 -28 35 85 85 85
129 -28 35 87 87 87
126 -27 35 87 87 87
127 -27 35 85 85 85
128 -27 35 83 83 83
129 -27 35 85 85 85
126 -26 35 85 85 85
127 -26 35 87 87 87
128 -26 35 83 83 83
129 -26 35 83 83 83
126 -25 35 85 85 85
127 -25 35 87 87 87
128 -25 35 83 83 83
129 -25 35 85 85 85
126 -24 35 87 87 87
127 -24 35 85 85 85
128 -24 35 87 87 87
129 -24 35 85 85 85
126 -23 35 83 83 83
127 -23 35 85 85 85
128 -23 35 85 85 85
129 -23 35 87 87 87
126 -22 35 85 85 85
127 -22 35 83 83 83
128 -22 35 87 87 87
129 -22 35 87 87 87
126 -21 35 87 87 87
127 -21 35 87 87 87
128 -21 35 83 83 83
129 -21 35 83 83 83
126 -20 35 83 83 83
127 -20 35 87 87 87
128 -20 35 87 87 87
129 -20 35 85 85 85
126 -19 35 85 85 85
127 -19 35 87 87 87
128 -19 35 85 85 85
129 -19 35 85 85 85
126 -18 35 83 83 83
127 -18 35 85 85 85
128 -18 35 85 85 85
129 -18 35 83 83 83
126 -17 35 83 83 83
127 -17 35 87 87 87
128 -17 35 87 87 87
129 -17 35 87 87 87
126 -16 35 87 87 87
127 -16 35 83 83 83
128 -16 35 87 87 87
129 -16 35 85 85 85
126 -15 35 83 83 83
127 -15 35 87 87 87
128 -15 35 83 83 83
129 -15 35 87 87 87
126 -14 35 83 83 83
127 -14 35 87 87 87
128 -14 35 85 85 85
129 -14 35 87 87 87
126 -13 35 87 87 87
127 -13 35 83 83 83
128 -13 35 83 83 83
129 -13 35 83 83 83
116 -12 35 83 83 83
117 -12 35 85 85 85
118 -12 35 85 85 85
123 -12 35 83 83 83
124 -12 35 87 87 87
125 -12 35 87 87 87
126 -12 35 83 83 83
127 -12 35 83 83 83
128 -12 35 85 85 85
129 -12 35 87 87 87
130 -12 35 83 83 83
131 -12 35 87 87 87
132 -12 35 87 87 87
137 -12 35 85 85 85
138 -12 35 83 83 83
139 -12 35 83 83 83
116 -11 35 83 83 83
117 -11 35 83 83 83
118 -11 35 85 85 85
119 -11 35 85 85 85
120 -11 35 87 87 87
122 -11 35 85 85 85
123 -11 35 85 85 85
124 -11 35 85 85 85
125 -11 35 85 85 85
126 -11 35 87 87 87
127 -11 35 83 83 83
128 -11 35 83 83 83
129 -11 35 83 83 83
130 -11 35 87 87 87
131 -11 35 85 85 85
132 -11 35 87 87 87
133 -11 35 87 87 87
134 -11 35 83 83 83
135 -11 35 85 85 85
136 -11 35 85 85 85
137 -11 35 85 85 85
138 -11 35 83 83 83
139 -11 35 83 83 83
116 -10 35 87 87 87
117 -10 35 83 83 83
118 -10 35 85 85 85
119 -10 35 87 87 87
120 -10 35 85 85 85
121 -10 35 31 31 31
122 -10 35 85 85 85
123 -10 35 83 83 83
124 -10 35 87 87 87
125 -10 35 85 85 85
126 -10 35 83 83 83
127 -10 35 87 87 87
128 -10 35 87 87 87
129 -10 35 83 83 83
130 -10 35 83 83 83
131 -10 35 83 83 83
132 -10 35 85 85 85
133 -10 35 87 87 87
134 -10 35 85 85 85
135 -10 35 87 87 87
136 -10 35 83 83 83
137 -10 35 87 87 87
138 -10 35 87 87 87
139 -10 35 87 87 87
116 -9 35 87 87 87
117 -9 35 87 87 87
118 -9 35 83 83 83
119 -9 35 83 83 83
120 -9 35 85 85 85
121 -9 35 85 85 85
122 -9 35 87 87 87
123 -9 35 87 87 87
124 -9 35 85 85 85
125 -9 35 87 87 87
126 -9 35 87 87 87
127 -9 35 87 87 87
128 -9 35 85 85 85
129 -9 35 83 83 83
130 -9 35 85 85 85
131 -9 35 83 83 83
132 -9 35 87 87 87
133 -9 35 83 83 83
134 -9 35 85 85 85
135 -9 35 85 85 85
136 -9 35 85 85 85
137 -9 35 83 83 83
138 -9 35 87 87 87
139 -9 35 87 87 87
115 -5 35 87 87 87
140 -5 35 85 85 85
115 -4 35 87 87 87
140 -4 35 87 87 87
114 -3 35 85 85 85
115 -3 35 87 87 87
116 -3 35 83 83 83
117 -3 35 85 85 85
118 -3 35 83 83 83
119 -3 35 87 87 87
120 -3 35 87 87 87
121 -3 35 85 85 85
122 -3 35 87 87 87
123 -3 35 87 87 87
124 -3 35 83 83 83
125 -3 35 87 87 87
126 -3 35 83 83 83
127 -3 35 85 85 85
128 -3 35 87 87 87
129 -3 35 87 87 87
130 -3 35 85 85 85
131 -3 35 87 87 87
132 -3 35 83 83 83
133 -3 35 83 83 83
134 -3 35 83 83 83
135 -3 35 87 87 87
136 -3 35 85 85 85
137 -3 35 85 85 85
138 -3 35 83 83 83
139 -3 35 87 87 87
140 -3 35 85 85 85
141 -3 35 83 83 83
114 -2 35 83 83 83
115 -2 35 85 85 85
140 -2 35 87 87 87
141 -2 35 85 85 85
115 -1 35 83 83 83
140 -1 35 83 83 83
114 0 35 87 87 87
141 0 35 83 83 83
114 1 35 83 83 83
141 1 35 85 85 85
114 2 35 87 87 87
141 2 35 87 87 87
114 3 35 85 85 85
141 3 35 87 87 87
113 4 35 83 83 83
142 4 35 83 83 83
113 5 35 87 87 87
142 5 35 83 83 83
113 6 35 87 87 87
142 6 35 85 85 85
112 7 35 83 83 83
143 7 35 87 87 87
112 8 35 87 87 87
143 8 35 85 85 85
112 9 35 87 87 87
143 9 35 85 85 85
110 10 35 87 87 87
111 10 35 85 85 85
144 10 35 87 87 87
145 10 35 85 85 85
111 11 35 83 83 83
144 11 35 83 83 83
111 12 35 87 87 87
144 12 35 85 85 85
111 13 35 87 87 87
144 13 35 83 83 83
110 14 35 87 87 87
111 14 35 87 87 87
144 14 35 85 85 85
145 14 35 87 87 87
110 15 35 85 85 85
145 15 35 85 85 85
110 16 35 83 83 83
145 16 35 87 87 87
110 17 35 85 85 85
145 17 35 87 87 87
110 18 35 87 87 87
145 18 35 83 83 83
110 19 35 83 83 83
145 19 35 87 87 87
110 20 35 87 87 87
145 20 35 87 87 87
110 21 35 87 87 87
145 21 35 85 85 85
111 22 35 85 85 85
144 22 35 83 83 83
111 23 35 83 83 83
144 23 35 87 87 87
111 24 35 83 83 83
144 24 35 85 85 85
112 25 35 87 87 87
143 25 35 87 87 87
112 26 35 83 83 83
143 26 35 85 85 85
113 27 35 83 83 83
142 27 35 87 87 87
114 28 35 85 85 85
141 28 35 87 87 87
115 29 35 85 85 85
140 29 35 85 85 85
116 30 35 85 85 85
139 30 35 87 87 87
117 31 35 83 83 83
138 31 35 85 85 85
118 32 35 83 83 83
119 32 35 85 85 85
136 32 35 85 85 85
137 32 35 87 87 87
118 33 35 87 87 87
120 33 35 85 85 85
121 33 35 85 85 85
122 33 35 85 85 85
123 33 35 87 87 87
124 33 35 87 87 87
125 33 35 85 85 85
126 33 35 83 83 83
127 33 35 87 87 87
128 33 35 83 83 83
129 33 35 87 87 87
130 33 35 87 87 87
131 33 35 85 85 85
132 33 35 85 85 85
133 33 35 83 83 83
134 33 35 83 83 83
135 33 35 87 87 87
137 33 35 83 83 83
118 34 35 83 83 83
123 34 35 87 87 87
124 34 35 83 83 83
125 34 35 87 87 87
130 34 35 85 85 85
131 34 35 87 87 87
132 34 35 87 87 87
137 34 35 87 87 87
117 35 35 83 83 83
118 35 35 87 87 87
125 35 35 85 85 85
130 35 35 87 87 87
137 35 35 87 87 87
138 35 35 87 87 87
117 36 35 83 83 83
125 36 35 87 87 87
130 36 35 87 87 87
137 36 35 83 83 83
138 36 35 87 87 87
117 37 35 83 83 83
126 37 35 87 87 87
127 37 35 85 85 85
128 37 35 83 83 83
129 37 35 85 85 85
138 37 35 83 83 83
117 38 35 87 87 87
118 38 35 87 87 87
119 38 35 87 87 87
136 38 35 85 85 85
137 38 35 83 83 83
138 38 35 87 87 87
119 39 35 83 83 83
120 39 35 83 83 83
121 39 35 87 87 87
122 39 35 83 83 83
133 39 35 87 87 87
134 39 35 85 85 85
135 39 35 83 83 83
136 39 35 85 85 85
122 40 35 87 87 87
123 40 35 87 87 87
124 40 35 87 87 87
125 40 35 83 83 83
126 40 35 87 87 87
127 40 35 85 85 85
128 40 35 83 83 83
129 40 35 83 83 83
130 40 35 87 87 87
131 40 35 87 87 87
132 40 35 87 87 87
133 40 35 87 87 87
127 -26 36 87 87 87
128 -26 36 87 87 87
127 -25 36 87 87 87
128 -25 36 85 85 85
127 -24 36 85 85 85
128 -24 36 87 87 87
127 -23 36 83 83 83
128 -23 36 87 87 87
127 -22 36 83 83 83
128 -22 36 83 83 83
127 -21 36 83 83 83
128 -21 36 87 87 87
127 -20 36 87 87 87
128 -20 36 83 83 83
127 -19 36 83 83 83
128 -19 36 87 87 87
127 -18 36 85 85 85
128 -18 36 83 83 83
127 -17 36 83 83 83
128 -17 36 83 83 83
127 -16 36 87 87 87
128 -16 36 83 83 83
127 -15 36 85 85 85
128 -15 36 85 85 85
127 -14 36 85 85 85
128 -14 36 87 87 87
125 -13 36 87 87 87
127 -13 36 83 83 83
128 -13 36 85 85 85
130 -13 36 83 83 83
116 -12 36 83 83 83
117 -12 36 83 83 83
118 -12 36 85 85 85
124 -12 36 83 83 83
125 -12 36 85 85 85
126 -12 36 83 83 83
127 -12 36 83 83 83
128 -12 36 85 85 85
129 -12 36 85 85 85
130 -12 36 83 83 83
131 -12 36 85 85 85
137 -12 36 87 87 87
138 -12 36 87 87 87
139 -12 36 87 87 87
116 -11 36 83 83 83
117 -11 36 85 85 85
118 -11 36 83 83 83
119 -11 36 85 85 85
120 -11 36 83 83 83
121 -11 36 85 85 85
122 -11 36 87 87 87
123 -11 36 83 83 83
124 -11 36 85 85 85
125 -11 36 85 85 85
126 -11 36 87 87 87
127 -11 36 87 87 87
128 -11 36 85 85 85
129 -11 36 87 87 87
130 -11 36 85 85 85
131 -11 36 87 87 87
132 -11 36 85 85 85
133 -11 36 83 83 83
134 -11 36 83 83 83
135 -11 36 87 87 87
136 -11 36 87 87 87
137 -11 36 87 87 87
138 -11 36 87 87 87
139 -11 36 87 87 87
116 -10 36 87 87 87
117 -10 36 83 83 83
118 -10 36 83 83 83
119 -10 36 85 85 85
120 -10 36 83 83 83
121 -10 36 87 87 87
122 -10 36 85 85 85
123 -10 36 83 83 83
124 -10 36 85 85 85
125 -10 36 87 87 87
126 -10 36 83 83 83
127 -10 36 85 85 85
128 -10 36 87 87 87
129 -10 36 87 87 87
130 -10 36 83 83 83
131 -10 36 83 83 83
132 -10 36 85 85 85
133 -10 36 85 85 85
134 -10 36 85 85 85
135 -10 36 85 85 85
136 -10 36 85 85 85
137 -10 36 83 83 83
138 -10 36 85 85 85
139 -10 36 87 87 87
116 -9 36 87 87 87
117 -9 36 87 87 87
118 -9 36 87 87 87
119 -9 36 87 87 87
120 -9 36 83 83 83
121 -9 36 85 85 85
122 -9 36 87 87 87
123 -9 36 83 83 83
124 -9 36 83 83 83
125 -9 36 87 87 87
126 -9 36 87 87 87
127 -9 36 85 85 85
128 -9 36 83 83 83
129 -9 36 87 87 87
130 -9 36 87 87 87
131 -9 36 87 87 87
132 -9 36 85 85 85
133 -9 36 87 87 87
134 -9 36 85 85 85
135 -9 36 87 87 87
136 -9 36 85 85 85
137 -9 36 83 83 83
138 -9 36 87 87 87
139 -9 36 87 87 87
115 -4 36 85 85 85
140 -4 36 83 83 83
115 -3 36 83 83 83
116 -3 36 87 87 87
117 -3 36 83 83 83
118 -3 36 83 83 83
119 -3 36 87 87 87
120 -3 36 83 83 83
121 -3 36 83 83 83
122 -3 36 87 87 87
123 -3 36 83 83 83
124 -3 36 87 87 87
125 -3 36 85 85 85
126 -3 36 85 85 85
127 -3 36 87 87 87
128 -3 36 85 85 85
129 -3 36 87 87 87
130 -3 36 85 85 85
131 -3 36 83 83 83
132 -3 36 83 83 83
133 -3 36 83 83 83
134 -3 36 85 85 85
135 -3 36 87 87 87
136 -3 36 83 83 83
137 -3 36 85 85 85
138 -3 36 83 83 83
139 -3 36 87 87 87
140 -3 36 83 83 83
115 -2 36 85 85 85
140 -2 36 87 87 87
115 -1 36 87 87 87
140 -1 36 85 85 85
114 0 36 87 87 87
141 0 36 85 85 85
114 1 36 83 83 83
141 1 36 83 83 83
114 2 36 83 83 83
141 2 36 83 83 83
114 3 36 85 85 85
141 3 36 87 87 87
113 4 36 83 83 83
142 4 36 85 85 85
113 5 36 83 83 83
142 5 36 85 85 85
113 6 36 83 83 83
142 6 36 85 85 85
112 7 36 85 85 85
143 7 36 87 87 87
112 8 36 87 87 87
143 8 36 85 85 85
112 9 36 83 83 83
143 9 36 87 87 87
110 10 36 83 83 83
111 10 36 87 87 87
144 10 36 83 83 83
145 10 36 87 87 87
110 11 36 85 85 85
111 11 36 83 83 83
144 11 36 87 87 87
145 11 36 83 83 83
110 12 36 87 87 87
111 12 36 83 83 83
144 12 36 87 87 87
145 12 36 87 87 87
110 13 36 83 83 83
111 13 36 85 85 85
144 13 36 87 87 87
145 13 36 85 85 85
110 14 36 87 87 87
111 14 36 85 85 85
144 14 36 85 85 85
145 14 36 87 87 87
110 15 36 85 85 85
145 15 36 87 87 87
110 16 36 87 87 87
145 16 36 83 83 83
110 17 36 83 83 83
145 17 36 87 87 87
110 18 36 83 83 83
145 18 36 87 87 87
110 19 36 83 83 83
145 19 36 85 85 85
110 20 36 83 83 83
145 20 36 87 87 87
110 21 36 85 85 85
145 21 36 87 87 87
111 22 36 87 87 87
144 22 36 87 87 87
111 23 36 83 83 83
144 23 36 87 87 87
111 24 36 85 85 85
144 24 36 83 83 83
112 25 36 83 83 83
143 25 36 83 83 83
112 26 36 85 85 85
143 26 36 85 85 85
113 27 36 85 85 85
142 27 36 85 85 85
114 28 36 87 87 87
141 28 36 83 83 83
115 29 36 83 83 83
140 29 36 85 85 85
116 30 36 87 87 87
139 30 36 83 83 83
117 31 36 85 85 85
138 31 36 85 85 85
118 32 36 85 85 85
119 32 36 87 87 87
136 32 36 85 85 85
137 32 36 83 83 83
118 33 36 85 85 85
120 33 36 83 83 83
121 33 36 87 87 87
122 33 36 87 87 87
123 33 36 87 87 87
124 33 36 83 83 83
125 33 36 87 87 87
126 33 36 83 83 83
127 33 36 83 83 83
128 33 36 83 83 83
129 33 36 83 83 83
130 33 36 83 83 83
131 33 36 83 83 83
132 33 36 87 87 87
133 33 36 83 83 83
134 33 36 83 83 83
135 33 36 83 83 83
137 33 36 85 85 85
118 34 36 85 85 85
123 34 36 85 85 85
124 34 36 87 87 87
125 34 36 85 85 85
130 34 36 85 85 85
131 34 36 87 87 87
132 34 36 87 87 87
137 34 36 85 85 85
117 35 36 83 83 83
118 35 36 85 85 85
125 35 36 83 83 83
130 35 36 83 83 83
137 35 36 85 85 85
138 35 36 83 83 83
117 36 36 83 83 83
125 36 36 83 83 83
130 36 36 87 87 87
137 36 36 87 87 87
138 36 36 83 83 83
117 37 36 85 85 85
126 37 36 87 87 87
127 37 36 83 83 83
128 37 36 87 87 87
129 37 36 83 83 83
138 37 36 83 83 83
117 38 36 87 87 87
118 38 36 87 87 87
119 38 36 83 83 83
136 38 36 83 83 83
137 38 36 87 87 87
138 38 36 83 83 83
119 39 36 83 83 83
120 39 36 85 85 85
121 39 36 87 87 87
122 39 36 87 87 87
133 39 36 83 83 83
134 39 36 85 85 85
135 39 36 85 85 85
136 39 36 87 87 87
122 40 36 87 87 87
123 40 36 87 87 87
124 40 36 85 85 85
125 40 36 83 83 83
126 40 36 83 83 83
127 40 36 85 85 85
128 40 36 83 83 83
129 40 36 87 87 87
130 40 36 87 87 87
131 40 36 87 87 87
132 40 36 85 85 85
133 40 36 87 87 87
116 -12 37 83 83 83
117 -12 37 85 85 85
118 -12 37 83 83 83
124 -12 37 83 83 83
125 -12 37 85 85 85
126 -12 37 87 87 87
127 -12 37 85 85 85
128 -12 37 83 83 83
129 -12 37 87 87 87
130 -12 37 83 83 83
131 -12 37 85 85 85
137 -12 37 87 87 87
138 -12 37 87 87 87
139 -12 37 85 85 85
116 -11 37 83 83 83
117 -11 37 83 83 83
118 -11 37 87 87 87
119 -11 37 87 87 87
120 -11 37 83 83 83
121 -11 37 87 87 87
122 -11 37 87 87 87
123 -11 37 83 83 83
124 -11 37 87 87 87
125 -11 37 87 87 87
126 -11 37 83 83 83
127 -11 37 83 83 83
128 -11 37 85 85 85
129 -11 37 83 83 83
130 -11 37 83 83 83
131 -11 37 87 87 87
132 -11 37 85 85 85
133 -11 37 85 85 85
134 -11 37 83 83 83
135 -11 37 83 83 83
136 -11 37 83 83 83
137 -11 37 83 83 83
138 -11 37 85 85 85
139 -11 37 83 83 83
115 -4 37 85 85 85
140 -4 37 83 83 83
115 -3 37 85 85 85
116 -3 37 87 87 87
117 -3 37 83 83 83
118 -3 37 85 85 85
119 -3 37 83 83 83
120 -3 37 87 87 87
121 -3 37 85 85 85
122 -3 37 87 87 87
123 -3 37 85 85 85
124 -3 37 85 85 85
125 -3 37 83 83 83
126 -3 37 83 83 83
127 -3 37 87 87 87
128 -3 37 85 85 85
129 -3 37 83 83 83
130 -3 37 83 83 83
131 -3 37 83 83 83
132 -3 37 85 85 85
133 -3 37 87 87 87
134 -3 37 85 85 85
135 -3 37 85 85 85
136 -3 37 85 85 85
137 -3 37 85 85 85
138 -3 37 83 83 83
139 -3 37 85 85 85
140 -3 37 83 83 83
115 -2 37 85 85 85
140 -2 37 85 85 85
115 -1 37 83 83 83
140 -1 37 87 87 87
114 0 37 87 87 87
141 0 37 85 85 85
114 1 37 85 85 85
141 1 37 87 87 87
114 2 37 87 87 87
141 2 37 83 83 83
114 3 37 83 83 83
141 3 37 85 85 85
113 4 37 85 85 85
142 4 37 85 85 85
113 5 37 83 83 83
142 5 37 87 87 87
113 6 37 87 87 87
142 6 37 83 83 83
112 7 37 83 83 83
143 7 37 87 87 87
112 8 37 87 87 87
143 8 37 83 83 83
112 9 37 87 87 87
143 9 37 85 85 85
111 10 37 83 83 83
144 10 37 85 85 85
110 11 37 87 87 87
111 11 37 85 85 85
144 11 37 83 83 83
145 11 37 83 83 83
110 12 37 87 87 87
111 12 37 85 85 85
144 12 37 85 85 85
145 12 37 85 85 85
110 13 37 85 85 85
111 13 37 85 85 85
144 13 37 83 83 83
145 13 37 83 83 83
111 14 37 87 87 87
144 14 37 87 87 87
110 15 37 87 87 87
145 15 37 85 85 85
110 16 37 83 83 83
145 16 37 85 85 85
110 17 37 85 85 85
145 17 37 83 83 83
110 18 37 87 87 87
145 18 37 85 85 85
110 19 37 83 83 83
145 19 37 83 83 83
110 20 37 85 85 85
145 20 37 85 85 85
110 21 37 87 87 87
145 21 37 87 87 87
111 22 37 85 85 85
144 22 37 83 83 83
111 23 37 83 83 83
144 23 37 87 87 87
111 24 37 85 85 85
144 24 37 83 83 83
112 25 37 85 85 85
143 25 37 83 83 83
112 26 37 85 85 85
143 26 37 87 87 87
113 27 37 85 85 85
142 27 37 87 87 87
114 28 37 85 85 85
141 28 37 85 85 85
115 29 37 83 83 83
140 29 37 85 85 85
116 30 37 83 83 83
139 30 37 83 83 83
117 31 37 83 83 83
138 31 37 85 85 85
118 32 37 85 85 85
119 32 37 85 85 85
136 32 37 85 85 85
137 32 37 85 85 85
118 33 37 85 85 85
120 33 37 83 83 83
121 33 37 83 83 83
122 33 37 87 87 87
123 33 37 87 87 87
124 33 37 87 87 87
125 33 37 85 85 85
126 33 37 87 87 87
127 33 37 83 83 83
128 33 37 85 85 85
129 33 37 83 83 83
130 33 37 87 87 87
131 33 37 87 87 87
132 33 37 85 85 85
133 33 37 85 85 85
134 33 37 87 87 87
135 33 37 83 83 83
137 33 37 87 87 87
118 34 37 83 83 83
123 34 37 85 85 85
124 34 37 83 83 83
125 34 37 85 85 85
130 34 37 85 85 85
131 34 37 85 85 85
132 34 37 87 87 87
137 34 37 87 87 87
117 35 37 87 87 87
118 35 37 87 87 87
125 35 37 85 85 85
130 35 37 85 85 85
137 35 37 85 85 85
138 35 37 85 85 85
117 36 37 87 87 87
125 36 37 85 85 85
130 36 37 83 83 83
137 36 37 83 83 83
138 36 37 85 85 85
117 37 37 85 85 85
126 37 37 83 83 83
127 37 37 83 83 83
128 37 37 83 83 83
129 37 37 85 85 85
138 37 37 85 85 85
117 38 37 87 87 87
118 38 37 87 87 87
119 38 37 85 85 85
136 38 37 85 85 85
137 38 37 87 87 87
138 38 37 83 83 83
119 39 37 87 87 87
120 39 37 87 87 87
121 39 37 85 85 85
122 39 37 83 83 83
133 39 37 83 83 83
134 39 37 85 85 85
135 39 37 85 85 85
136 39 37 83 83 83
122 40 37 87 87 87
123 40 37 85 85 85
124 40 37 85 85 85
125 40 37 85 85 85
126 40 37 87 87 87
127 40 37 83 83 83
128 40 37 85 85 85
129 40 37 83 83 83
130 40 37 87 87 87
131 40 37 83 83 83
132 40 37 85 85 85
133 40 37 83 83 83
116 -3 38 87 87 87
117 -3 38 87 87 87
118 -3 38 83 83 83
119 -3 38 87 87 87
120 -3 38 85 85 85
121 -3 38 83 83 83
122 -3 38 83 83 83
123 -3 38 83 83 83
124 -3 38 87 87 87
125 -3 38 83 83 83
126 -3 38 85 85 85
127 -3 38 87 87 87
128 -3 38 85 85 85
129 -3 38 83 83 83
130 -3 38 87 87 87
131 -3 38 87 87 87
132 -3 38 83 83 83
133 -3 38 85 85 85
134 -3 38 83 83 83
135 -3 38 85 85 85
136 -3 38 87 87 87
137 -3 38 85 85 85
138 -3 38 87 87 87
139 -3 38 85 85 85
116 -2 38 87 87 87
117 -2 38 87 87 87
118 -2 38 83 83 83
119 -2 38 85 85 85
120 -2 38 83 83 83
121 -2 38 87 87 87
122 -2 38 85 85 85
123 -2 38 85 85 85
124 -2 38 87 87 87
125 -2 38 83 83 83
126 -2 38 87 87 87
127 -2 38 85 85 85
128 -2 38 85 85 85
129 -2 38 83 83 83
130 -2 38 85 85 85
131 -2 38 87 87 87
132 -2 38 85 85 85
133 -2 38 83 83 83
134 -2 38 87 87 87
135 -2 38 87 87 87
136 -2 38 83 83 83
137 -2 38 85 85 85
138 -2 38 85 85 85
139 -2 38 83 83 83
115 -1 38 87 87 87
116 -1 38 83 83 83
117 -1 38 87 87 87
118 -1 38 87 87 87
119 -1 38 87 87 87
120 -1 38 83 83 83
121 -1 38 85 85 85
122 -1 38 85 85 85
123 -1 38 83 83 83
124 -1 38 83 83 83
125 -1 38 85 85 85
126 -1 38 85 85 85
127 -1 38 85 85 85
128 -1 38 87 87 87
129 -1 38 87 87 87
130 -1 38 85 85 85
131 -1 38 87 87 87
132 -1 38 83 83 83
133 -1 38 83 83 83
134 -1 38 85 85 85
135 -1 38 83 83 83
136 -1 38 87 87 87
137 -1 38 87 87 87
138 -1 38 87 87 87
139 -1 38 87 87 87
140 -1 38 85 85 85
114 0 38 87 87 87
141 0 38 85 85 85
114 1 38 83 83 83
141 1 38 87 87 87
114 2 38 83 83 83
141 2 38 83 83 83
114 3 38 87 87 87
141 3 38 85 85 85
113 4 38 85 85 85
142 4 38 85 85 85
113 5 38 85 85 85
142 5 38 83 83 83
113 6 38 87 87 87
142 6 38 87 87 87
112 7 38 83 83 83
143 7 38 85 85 85
112 8 38 87 87 87
143 8 38 87 87 87
112 9 38 83 83 83
143 9 38 85 85 85
111 10 38 83 83 83
144 10 38 83 83 83
111 11 38 85 85 85
144 11 38 87 87 87
111 12 38 83 83 83
144 12 38 85 85 85
111 13 38 87 87 87
144 13 38 83 83 83
111 14 38 87 87 87
144 14 38 83 83 83
110 15 38 87 87 87
145 15 38 87 87 87
110 16 38 83 83 83
145 16 38 87 87 87
110 17 38 87 87 87
145 17 38 85 85 85
110 18 38 85 85 85
145 18 38 85 85 85
110 19 38 87 87 87
145 19 38 85 85 85
110 20 38 83 83 83
145 20 38 87 87 87
110 21 38 83 83 83
145 21 38 87 87 87
111 22 38 87 87 87
144 22 38 85 85 85
111 23 38 83 83 83
144 23 38 83 83 83
111 24 38 83 83 83
144 24 38 87 87 87
112 25 38 85 85 85
143 25 38 87 87 87
112 26 38 85 85 85
143 26 38 83 83 83
113 27 38 83 83 83
142 27 38 83 83 83
114 28 38 85 85 85
141 28 38 85 85 85
115 29 38 83 83 83
140 29 38 83 83 83
116 30 38 85 85 85
139 30 38 87 87 87
117 31 38 85 85 85
138 31 38 87 87 87
118 32 38 87 87 87
119 32 38 85 85 85
136 32 38 87 87 87
137 32 38 83 83 83
118 33 38 85 85 85
120 33 38 87 87 87
121 33 38 87 87 87
122 33 38 87 87 87
123 33 38 87 87 87
124 33 38 83 83 83
125 33 38 85 85 85
126 33 38 87 87 87
127 33 38 87 87 87
128 33 38 85 85 85
129 33 38 83 83 83
130 33 38 83 83 83
131 33 38 83 83 83
132 33 38 85 85 85
133 33 38 85 85 85
134 33 38 83 83 83
135 33 38 87 87 87
137 33 38 87 87 87
118 34 38 85 85 85
123 34 38 83 83 83
124 34 38 87 87 87
125 34 38 83 83 83
130 34 38 87 87 87
131 34 38 83 83 83
132 34 38 85 85 85
137 34 38 87 87 87
117 35 38 85 85 85
118 35 38 83 83 83
125 35 38 83 83 83
130 35 38 85 85 85
137 35 38 83 83 83
138 35 38 83 83 83
117 36 38 83 83 83
125 36 38 85 85 85
130 36 38 87 87 87
137 36 38 87 87 87
138 36 38 87 87 87
117 37 38 85 85 85
126 37 38 85 85 85
127 37 38 87 87 87
128 37 38 87 87 87
129 37 38 83 83 83
138 37 38 85 85 85
117 38 38 87 87 87
118 38 38 85 85 85
119 38 38 83 83 83
136 38 38 85 85 85
137 38 38 83 83 83
138 38 38 85 85 85
119 39 38 83 83 83
120 39 38 83 83 83
121 39 38 85 85 85
122 39 38 83 83 83
133 39 38 87 87 87
134 39 38 85 85 85
135 39 38 85 85 85
136 39 38 87 87 87
122 40 38 83 83 83
123 40 38 83 83 83
124 40 38 87 87 87
125 40 38 85 85 85
126 40 38 85 85 85
127 40 38 85 85 85
128 40 38 85 85 85
129 40 38 83 83 83
130 40 38 87 87 87
131 40 38 87 87 87
132 40 38 83 83 83
133 40 38 83 83 83
115 0 39 85 85 85
116 0 39 83 83 83
117 0 39 85 85 85
118 0 39 87 87 87
119 0 39 83 83 83
120 0 39 83 83 83
121 0 39 87 87 87
122 0 39 85 85 85
123 0 39 83 83 83
124 0 39 85 85 85
125 0 39 83 83 83
126 0 39 83 83 83
127 0 39 87 87 87
128 0 39 83 83 83
129 0 39 85 85 85
130 0 39 83 83 83
131 0 39 87 87 87
132 0 39 83 83 83
133 0 39 83 83 83
134 0 39 83 83 83
135 0 39 85 85 85
136 0 39 85 85 85
137 0 39 85 85 85
138 0 39 87 87 87
139 0 39 83 83 83
140 0 39 87 87 87
115 1 39 83 83 83
116 1 39 87 87 87
117 1 39 83 83 83
118 1 39 87 87 87
119 1 39 87 87 87
120 1 39 87 87 87
121 1 39 87 87 87
122 1 39 83 83 83
123 1 39 85 85 85
124 1 39 87 87 87
125 1 39 87 87 87
126 1 39 87 87 87
127 1 39 87 87 87
128 1 39 83 83 83
129 1 39 83 83 83
130 1 39 83 83 83
131 1 39 85 85 85
132 1 39 83 83 83
133 1 39 85 85 85
134 1 39 85 85 85
135 1 39 83 83 83
136 1 39 85 85 85
137 1 39 83 83 83
138 1 39 83 83 83
139 1 39 85 85 85
140 1 39 87 87 87
114 2 39 87 87 87
115 2 39 85 85 85
116 2 39 85 85 85
117 2 39 85 85 85
118 2 39 85 85 85
119 2 39 87 87 87
120 2 39 85 85 85
121 2 39 83 83 83
122 2 39 85 85 85
123 2 39 83 83 83
124 2 39 83 83 83
125 2 39 85 85 85
126 2 39 83 83 83
127 2 39 87 87 87
128 2 39 83 83 83
129 2 39 87 87 87
130 2 39 83 83 83
131 2 39 87 87 87
132 2 39 83 83 83
133 2 39 83 83 83
134 2 39 85 85 85
135 2 39 83 83 83
136 2 39 87 87 87
137 2 39 83 83 83
138 2 39 85 85 85
139 2 39 87 87 87
140 2 39 83 83 83
141 2 39 83 83 83
114 3 39 87 87 87
115 3 39 85 85 85
116 3 39 83 83 83
117 3 39 87 87 87
118 3 39 87 87 87
119 3 39 83 83 83
120 3 39 83 83 83
121 3 39 85 85 85
122 3 39 85 85 85
123 3 39 85 85 85
124 3 39 83 83 83
125 3 39 83 83 83
126 3 39 85 85 85
127 3 39 85 85 85
128 3 39 83 83 83
129 3 39 87 87 87
130 3 39 85 85 85
131 3 39 87 87 87
132 3 39 83 83 83
133 3 39 85 85 85
134 3 39 87 87 87
135 3 39 83 83 83
136 3 39 87 87 87
137 3 39 83 83 83
138 3 39 83 83 83
139 3 39 87 87 87
140 3 39 83 83 83
141 3 39 85 85 85
113 4 39 83 83 83
114 4 39 83 83 83
115 4 39 83 83 83
116 4 39 83 83 83
117 4 39 87 87 87
118 4 39 87 87 87
119 4 39 83 83 83
120 4 39 85 85 85
121 4 39 85 85 85
122 4 39 87 87 87
123 4 39 87 87 87
124 4 39 83 83 83
125 4 39 85 85 85
126 4 39 87 87 87
127 4 39 87 87 87
128 4 39 85 85 85
129 4 39 83 83 83
130 4 39 87 87 87
131 4 39 85 85 85
132 4 39 87 87 87
133 4 39 85 85 85
134 4 39 87 87 87
135 4 39 87 87 87
136 4 39 87 87 87
137 4 39 83 83 83
138 4 39 87 87 87
139 4 39 83 83 83
140 4 39 87 87 87
141 4 39 87 87 87
142 4 39 83 83 83
113 5 39 85 85 85
114 5 39 83 83 83
115 5 39 87 87 87
116 5 39 85 85 85
117 5 39 87 87 87
118 5 39 83 83 83
119 5 39 87 87 87
120 5 39 87 87 87
121 5 39 83 83 83
122 5 39 85 85 85
123 5 39 87 87 87
124 5 39 87 87 87
125 5 39 87 87 87
126 5 39 87 87 87
127 5 39 87 87 87
128 5 39 87 87 87
129 5 39 85 85 85
130 5 39 87 87 87
131 5 39 87 87 87
132 5 39 83 83 83
133 5 39 87 87 87
134 5 39 83 83 83
135 5 39 83 83 83
136 5 39 87 87 87
137 5 39 87 87 87
138 5 39 85 85 85
139 5 39 83 83 83
140 5 39 83 83 83
141 5 39 85 85 85
142 5 39 87 87 87
113 6 39 87 87 87
142 6 39 85 85 85
112 7 39 87 87 87
143 7 39 87 87 87
112 8 39 83 83 83
143 8 39 85 85 85
112 9 39 85 85 85
143 9 39 83 83 83
111 10 39 87 87 87
144 10 39 85 85 85
111 11 39 87 87 87
144 11 39 83 83 83
111 12 39 87 87 87
144 12 39 87 87 87
111 13 39 87 87 87
144 13 39 83 83 83
111 14 39 83 83 83
144 14 39 85 85 85
110 15 39 87 87 87
145 15 39 83 83 83
110 16 39 85 85 85
145 16 39 87 87 87
110 17 39 85 85 85
145 17 39 83 83 83
110 18 39 85 85 85
145 18 39 85 85 85
110 19 39 85 85 85
145 19 39 83 83 83
110 20 39 85 85 85
145 20 39 83 83 83
110 21 39 87 87 87
145 21 39 85 85 85
111 22 39 87 87 87
144 22 39 87 87 87
111 23 39 87 87 87
144 23 39 83 83 83
111 24 39 87 87 87
144 24 39 87 87 87
112 25 39 83 83 83
143 25 39 87 87 87
112 26 39 87 87 87
143 26 39 83 83 83
113 27 39 83 83 83
142 27 39 87 87 87
114 28 39 85 85 85
141 28 39 85 85 85
115 29 39 87 87 87
140 29 39 87 87 87
116 30 39 83 83 83
139 30 39 87 87 87
117 31 39 85 85 85
138 31 39 83 83 83
118 32 39 87 87 87
119 32 39 85 85 85
136 32 39 83 83 83
137 32 39 87 87 87
118 33 39 87 87 87
120 33 39 87 87 87
121 33 39 85 85 85
122 33 39 85 85 85
123 33 39 87 87 87
124 33 39 83 83 83
125 33 39 85 85 85
126 33 39 87 87 87
127 33 39 85 85 85
128 33 39 87 87 87
129 33 39 85 85 85
130 33 39 87 87 87
131 33 39 85 85 85
132 33 39 87 87 87
133 33 39 87 87 87
134 33 39 87 87 87
135 33 39 83 83 83
137 33 39 83 83 83
118 34 39 87 87 87
119 34 39 87 87 87
120 34 39 83 83 83
121 34 39 85 85 85
122 34 39 83 83 83
123 34 39 85 85 85
124 34 39 85 85 85
125 34 39 87 87 87
130 34 39 83 83 83
131 34 39 87 87 87
132 34 39 85 85 85
133 34 39 83 83 83
134 34 39 83 83 83
135 34 39 87 87 87
136 34 39 87 87 87
137 34 39 85 85 85
117 35 39 83 83 83
118 35 39 83 83 83
122 35 39 83 83 83
123 35 39 87 87 87
125 35 39 85 85 85
130 35 39 83 83 83
131 35 39 83 83 83
132 35 39 87 87 87
133 35 39 87 87 87
137 35 39 87 87 87
138 35 39 85 85 85
117 36 39 87 87 87
123 36 39 83 83 83
124 36 39 83 83 83
125 36 39 85 85 85
130 36 39 83 83 83
131 36 39 83 83 83
137 36 39 85 85 85
138 36 39 83 83 83
117 37 39 87 87 87
124 37 39 87 87 87
126 37 39 85 85 85
127 37 39 83 83 83
128 37 39 85 85 85
129 37 39 87 87 87
131 37 39 85 85 85
138 37 39 85 85 85
117 38 39 83 83 83
118 38 39 87 87 87
119 38 39 83 83 83
124 38 39 85 85 85
131 38 39 83 83 83
136 38 39 87 87 87
137 38 39 83 83 83
138 38 39 85 85 85
119 39 39 87 87 87
120 39 39 87 87 87
121 39 39 85 85 85
122 39 39 85 85 85
124 39 39 83 83 83
131 39 39 85 85 85
133 39 39 87 87 87
134 39 39 87 87 87
135 39 39 83 83 83
136 39 39 83 83 83
122 40 39 87 87 87
123 40 39 83 83 83
124 40 39 87 87 87
125 40 39 85 85 85
126 40 39 83 83 83
127 40 39 85 85 85
128 40 39 85 85 85
129 40 39 87 87 87
130 40 39 85 85 85
131 40 39 85 85 85
132 40 39 83 83 83
133 40 39 83 83 83
113 5 40 85 85 85
114 5 40 85 85 85
115 5 40 83 83 83
116 5 40 83 83 83
117 5 40 87 87 87
118 5 40 83 83 83
119 5 40 83 83 83
120 5 40 87 87 87
121 5 40 83 83 83
122 5 40 85 85 85
123 5 40 87 87 87
124 5 40 83 83 83
125 5 40 83 83 83
126 5 40 85 85 85
127 5 40 85 85 85
128 5 40 87 87 87
129 5 40 87 87 87
130 5 40 85 85 85
131 5 40 83 83 83
132 5 40 83 83 83
133 5 40 87 87 87
134 5 40 83 83 83
135 5 40 85 85 85
136 5 40 85 85 85
137 5 40 85 85 85
138 5 40 85 85 85
139 5 40 85 85 85
140 5 40 83 83 83
141 5 40 85 85 85
142 5 40 85 85 85
113 6 40 87 87 87
114 6 40 87 87 87
115 6 40 85 85 85
116 6 40 85 85 85
117 6 40 85 85 85
118 6 40 83 83 83
119 6 40 85 85 85
120 6 40 87 87 87
121 6 40 87 87 87
122 6 40 83 83 83
123 6 40 87 87 87
124 6 40 83 83 83
125 6 40 87 87 87
126 6 40 87 87 87
127 6 40 83 83 83
128 6 40 87 87 87
129 6 40 85 85 85
130 6 40 85 85 85
131 6 40 85 85 85
132 6 40 85 85 85
133 6 40 87 87 87
134 6 40 87 87 87
135 6 40 83 83 83
136 6 40 87 87 87
137 6 40 87 87 87
138 6 40 85 85 85
139 6 40 85 85 85
140 6 40 87 87 87
141 6 40 85 85 85
142 6 40 83 83 83
112 7 40 87 87 87
113 7 40 87 87 87
114 7 40 83 83 83
115 7 40 87 87 87
116 7 40 83 83 83
117 7 40 83 83 83
118 7 40 83 83 83
119 7 40 83 83 83
120 7 40 87 87 87
121 7 40 87 87 87
122 7 40 83 83 83
123 7 40 87 87 87
124 7 40 87 87 87
125 7 40 85 85 85
126 7 40 85 85 85
127 7 40 85 85 85
128 7 40 83 83 83
129 7 40 87 87 87
130 7 40 83 83 83
131 7 40 85 85 85
132 7 40 83 83 83
133 7 40 87 87 87
134 7 40 87 87 87
135 7 40 87 87 87
136 7 40 87 87 87
137 7 40 87 87 87
138 7 40 87 87 87
139 7 40 87 87 87
140 7 40 87 87 87
141 7 40 83 83 83
142 7 40 87 87 87
143 7 40 85 85 85
112 8 40 87 87 87
113 8 40 83 83 83
114 8 40 83 83 83
115 8 40 85 85 85
116 8 40 83 83 83
117 8 40 83 83 83
118 8 40 85 85 85
119 8 40 85 85 85
120 8 40 83 83 83
121 8 40 85 85 85
122 8 40 83 83 83
123 8 40 85 85 85
124 8 40 83 83 83
125 8 40 83 83 83
126 8 40 85 85 85
127 8 40 83 83 83
128 8 40 83 83 83
129 8 40 87 87 87
130 8 40 87 87 87
131 8 40 83 83 83
132 8 40 87 87 87
133 8 40 87 87 87
134 8 40 83 83 83
135 8 40 85 85 85
136 8 40 87 87 87
137 8 40 87 87 87
138 8 40 87 87 87
139 8 40 83 83 83
140 8 40 83 83 83
141 8 40 85 85 85
142 8 40 85 85 85
143 8 40 87 87 87
112 9 40 83 83 83
113 9 40 85 85 85
114 9 40 83 83 83
115 9 40 85 85 85
116 9 40 87 87 87
117 9 40 85 85 85
118 9 40 83 83 83
119 9 40 83 83 83
120 9 40 83 83 83
121 9 40 83 83 83
122 9 40 83 83 83
123 9 40 85 85 85
124 9 40 87 87 87
125 9 40 87 87 87
126 9 40 87 87 87
127 9 40 87 87 87
128 9 40 85 85 85
129 9 40 85 85 85
130 9 40 87 87 87
131 9 40 83 83 83
132 9 40 85 85 85
133 9 40 87 87 87
134 9 40 85 85 85
135 9 40 85 85 85
136 9 40 85 85 85
137 9 40 87 87 87
138 9 40 85 85 85
139 9 40 87 87 87
140 9 40 85 85 85
141 9 40 83 83 83
142 9 40 83 83 83
143 9 40 83 83 83
111 10 40 85 85 85
112 10 40 87 87 87
113 10 40 83 83 83
114 10 40 85 85 85
115 10 40 83 83 83
116 10 40 87 87 87
117 10 40 83 83 83
118 10 40 83 83 83
119 10 40 83 83 83
120 10 40 87 87 87
121 10 40 87 87 87
122 10 40 85 85 85
123 10 40 87 87 87
124 10 40 85 85 85
125 10 40 83 83 83
126 10 40 85 85 85
127 10 40 87 87 87
128 10 40 87 87 87
129 10 40 87 87 87
130 10 40 87 87 87
131 10 40 83 83 83
132 10 40 85 85 85
133 10 40 83 83 83
134 10 40 85 85 85
135 10 40 87 87 87
136 10 40 85 85 85
137 10 40 87 87 87
138 10 40 83 83 83
139 10 40 83 83 83
140 10 40 85 85 85
141 10 40 83 83 83
142 10 40 83 83 83
143 10 40 87 87 87
144 10 40 83 83 83
111 11 40 87 87 87
112 11 40 85 85 85
113 11 40 85 85 85
114 11 40 87 87 87
115 11 40 85 85 85
116 11 40 83 83 83
117 11 40 83 83 83
118 11 40 83 83 83
119 11 40 83 83 83
120 11 40 87 87 87
121 11 40 87 87 87
122 11 40 83 83 83
123 11 40 83 83 83
124 11 40 83 83 83
125 11 40 85 85 85
126 11 40 83 83 83
127 11 40 85 85 85
128 11 40 85 85 85
129 11 40 87 87 87
130 11 40 85 85 85
131 11 40 85 85 85
132 11 40 87 87 87
133 11 40 87 87 87
134 11 40 85 85 85
135 11 40 83 83 83
136 11 40 85 85 85
137 11 40 87 87 87
138 11 40 87 87 87
139 11 40 85 85 85
140 11 40 87 87 87
141 11 40 85 85 85
142 11 40 83 83 83
143 11 40 83 83 83
144 11 40 85 85 85
111 12 40 85 85 85
112 12 40 83 83 83
113 12 40 85 85 85
114 12 40 87 87 87
115 12 40 85 85 85
116 12 40 85 85 85
117 12 40 85 85 85
118 12 40 83 83 83
119 12 40 87 87 87
120 12 40 87 87 87
121 12 40 87 87 87
122 12 40 83 83 83
123 12 40 83 83 83
124 12 40 85 85 85
125 12 40 85 85 85
126 12 40 87 87 87
127 12 40 85 85 85
128 12 40 85 85 85
129 12 40 83 83 83
130 12 40 83 83 83
131 12 40 87 87 87
132 12 40 87 87 87
133 12 40 87 87 87
134 12 40 85 85 85
135 12 40 87 87 87
136 12 40 87 87 87
137 12 40 83 83 83
138 12 40 85 85 85
139 12 40 85 85 85
140 12 40 87 87 87
141 12 40 87 87 87
142 12 40 87 87 87
143 12 40 87 87 87
144 12 40 85 85 85
111 13 40 87 87 87
112 13 40 85 85 85
113 13 40 87 87 87
114 13 40 85 85 85
115 13 40 87 87 87
116 13 40 85 85 85
117 13 40 83 83 83
118 13 40 83 83 83
119 13 40 83 83 83
120 13 40 83 83 83
121 13 40 87 87 87
122 13 40 85 85 85
123 13 40 83 83 83
124 13 40 87 87 87
125 13 40 85 85 85
126 13 40 83 83 83
127 13 40 85 85 85
128 13 40 85 85 85
129 13 40 83 83 83
130 13 40 83 83 83
131 13 40 87 87 87
132 13 40 85 85 85
133 13 40 85 85 85
134 13 40 85 85 85
135 13 40 85 85 85
136 13 40 83 83 83
137 13 40 83 83 83
138 13 40 87 87 87
139 13 40 85 85 85
140 13 40 83 83 83
141 13 40 87 87 87
142 13 40 87 87 87
143 13 40 87 87 87
144 13 40 87 87 87
111 14 40 83 83 83
112 14 40 87 87 87
113 14 40 83 83 83
114 14 40 83 83 83
115 14 40 83 83 83
116 14 40 87 87 87
117 14 40 85 85 85
118 14 40 85 85 85
119 14 40 87 87 87
120 14 40 83 83 83
121 14 40 83 83 83
122 14 40 87 87 87
123 14 40 83 83 83
124 14 40 85 85 85
125 14 40 85 85 85
126 14 40 85 85 85
127 14 40 87 87 87
128 14 40 83 83 83
129 14 40 87 87 87
130 14 40 83 83 83
131 14 40 85 85 85
132 14 40 85 85 85
133 14 40 85 85 85
134 14 40 87 87 87
135 14 40 85 85 85
136 14 40 83 83 83
137 14 40 83 83 83
138 14 40 85 85 85
139 14 40 83 83 83
140 14 40 83 83 83
141 14 40 85 85 85
142 14 40 83 83 83
143 14 40 83 83 83
144 14 40 83 83 83
110 15 40 83 83 83
111 15 40 85 85 85
112 15 40 87 87 87
113 15 40 83 83 83
114 15 40 83 83 83
115 15 40 83 83 83
116 15 40 85 85 85
117 15 40 83 83 83
118 15 40 83 83 83
119 15 40 85 85 85
120 15 40 83 83 83
121 15 40 87 87 87
122 15 40 83 83 83
123 15 40 83 83 83
124 15 40 83 83 83
125 15 40 83 83 83
126 15 40 87 87 87
127 15 40 85 85 85
128 15 40 85 85 85
129 15 40 87 87 87
130 15 40 85 85 85
131 15 40 83 83 83
132 15 40 85 85 85
133 15 40 83 83 83
134 15 40 83 83 83
135 15 40 83 83 83
136 15 40 83 83 83
137 15 40 87 87 87
138 15 40 87 87 87
139 15 40 85 85 85
140 15 40 87 87 87
141 15 40 85 85 85
142 15 40 87 87 87
143 15 40 83 83 83
144 15 40 83 83 83
145 15 40 85 85 85
110 16 40 85 85 85
111 16 40 83 83 83
112 16 40 87 87 87
113 16 40 85 85 85
114 16 40 87 87 87
115 16 40 85 85 85
116 16 40 85 85 85
117 16 40 85 85 85
118 16 40 85 85 85
119 16 40 87 87 87
120 16 40 85 85 85
121 16 40 83 83 83
122 16 40 85 85 85
123 16 40 83 83 83
124 16 40 83 83 83
125 16 40 87 87 87
126 16 40 83 83 83
127 16 40 85 85 85
128 16 40 87 87 87
129 16 40 85 85 85
130 16 40 83 83 83
131 16 40 85 85 85
132 16 40 87 87 87
133 16 40 85 85 85
134 16 40 87 87 87
135 16 40 83 83 83
136 16 40 83 83 83
137 16 40 87 87 87
138 16 40 83 83 83
139 16 40 83 83 83
140 16 40 83 83 83
141 16 40 83 83 83
142 16 40 85 85 85
143 16 40 83 83 83
144 16 40 85 85 85
145 16 40 87 87 87
110 17 40 85 85 85
111 17 40 85 85 85
112 17 40 87 87 87
113 17 40 85 85 85
114 17 40 87 87 87
115 17 40 83 83 83
116 17 40 83 83 83
117 17 40 87 87 87
118 17 40 85 85 85
119 17 40 85 85 85
120 17 40 87 87 87
121 17 40 85 85 85
122 17 40 87 87 87
123 17 40 87 87 87
124 17 40 87 87 87
125 17 40 87 87 87
126 17 40 83 83 83
127 17 40 87 87 87
128 17 40 87 87 87
129 17 40 87 87 87
130 17 40 83 83 83
131 17 40 87 87 87
132 17 40 85 85 85
133 17 40 83 83 83
134 17 40 87 87 87
135 17 40 87 87 87
136 17 40 87 87 87
137 17 40 83 83 83
138 17 40 85 85 85
139 17 40 83 83 83
140 17 40 83 83 83
141 17 40 87 87 87
142 17 40 85 85 85
143 17 40 85 85 85
144 17 40 87 87 87
145 17 40 85 85 85
110 18 40 85 85 85
111 18 40 83 83 83
112 18 40 83 83 83
113 18 40 85 85 85
114 18 40 83 83 83
115 18 40 83 83 83
116 18 40 87 87 87
117 18 40 87 87 87
118 18 40 83 83 83
119 18 40 85 85 85
120 18 40 83 83 83
121 18 40 83 83 83
122 18 40 85 85 85
123 18 40 85 85 85
124 18 40 87 87 87
125 18 40 87 87 87
126 18 40 83 83 83
127 18 40 83 83 83
128 18 40 83 83 83
129 18 40 83 83 83
130 18 40 83 83 83
131 18 40 83 83 83
132 18 40 85 85 85
133 18 40 83 83 83
134 18 40 85 85 85
135 18 40 83 83 83
136 18 40 83 83 83
137 18 40 87 87 87
138 18 40 83 83 83
139 18 40 85 85 85
140 18 40 85 85 85
141 18 40 87 87 87
142 18 40 85 85 85
143 18 40 85 85 85
144 18 40 87 87 87
145 18 40 83 83 83
110 19 40 85 85 85
111 19 40 83 83 83
112 19 40 85 85 85
113 19 40 87 87 87
114 19 40 87 87 87
115 19 40 83 83 83
116 19 40 83 83 83
117 19 40 85 85 85
118 19 40 87 87 87
119 19 40 85 85 85
120 19 40 87 87 87
121 19 40 87 87 87
122 19 40 83 83 83
123 19 40 85 85 85
124 19 40 87 87 87
125 19 40 87 87 87
126 19 40 87 87 87
127 19 40 83 83 83
128 19 40 85 85 85
129 19 40 85 85 85
130 19 40 85 85 85
138 19 40 85 85 85
139 19 40 83 83 83
140 19 40 87 87 87
141 19 40 87 87 87
142 19 40 83 83 83
143 19 40 83 83 83
144 19 40 87 87 87
145 19 40 85 85 85
110 20 40 85 85 85
111 20 40 85 85 85
112 20 40 85 85 85
113 20 40 87 87 87
114 20 40 83 83 83
115 20 40 87 87 87
116 20 40 83 83 83
117 20 40 85 85 85
118 20 40 87 87 87
119 20 40 87 87 87
120 20 40 87 87 87
121 20 40 83 83 83
122 20 40 83 83 83
123 20 40 83 83 83
124 20 40 87 87 87
125 20 40 85 85 85
126 20 40 85 85 85
127 20 40 87 87 87
128 20 40 87 87 87
129 20 40 85 85 85
139 20 40 85 85 85
140 20 40 83 83 83
141 20 40 85 85 85
142 20 40 85 85 85
143 20 40 85 85 85
144 20 40 85 85 85
145 20 40 83 83 83
110 21 40 87 87 87
111 21 40 83 83 83
112 21 40 87 87 87
113 21 40 85 85 85
114 21 40 85 85 85
115 21 40 87 87 87
116 21 40 83 83 83
117 21 40 85 85 85
118 21 40 85 85 85
119 21 40 83 83 83
120 21 40 83 83 83
121 21 40 83 83 83
122 21 40 85 85 85
123 21 40 83 83 83
124 21 40 83 83 83
125 21 40 87 87 87
126 21 40 87 87 87
127 21 40 83 83 83
128 21 40 83 83 83
140 21 40 87 87 87
141 21 40 87 87 87
142 21 40 87 87 87
143 21 40 83 83 83
144 21 40 87 87 87
145 21 40 83 83 83
111 22 40 83 83 83
112 22 40 85 85 85
113 22 40 85 85 85
114 22 40 85 85 85
115 22 40 83 83 83
116 22 40 83 83 83
117 22 40 85 85 85
118 22 40 83 83 83
119 22 40 85 85 85
120 22 40 83 83 83
121 22 40 83 83 83
122 22 40 85 85 85
123 22 40 87 87 87
124 22 40 87 87 87
125 22 40 83 83 83
126 22 40 85 85 85
127 22 40 83 83 83
128 22 40 83 83 83
140 22 40 83 83 83
141 22 40 83 83 83
142 22 40 87 87 87
143 22 40 83 83 83
144 22 40 87 87 87
111 23 40 85 85 85
112 23 40 85 85 85
113 23 40 85 85 85
114 23 40 87 87 87
115 23 40 83 83 83
116 23 40 87 87 87
117 23 40 83 83 83
118 23 40 87 87 87
119 23 40 85 85 85
120 23 40 87 87 87
121 23 40 83 83 83
122 23 40 87 87 87
123 23 40 83 83 83
124 23 40 85 85 85
125 23 40 83 83 83
126 23 40 85 85 85
127 23 40 85 85 85
128 23 40 85 85 85
140 23 40 85 85 85
141 23 40 85 85 85
142 23 40 83 83 83
143 23 40 85 85 85
144 23 40 83 83 83
111 24 40 83 83 83
112 24 40 83 83 83
113 24 40 83 83 83
114 24 40 87 87 87
115 24 40 87 87 87
116 24 40 83 83 83
117 24 40 83 83 83
118 24 40 83 83 83
119 24 40 87 87 87
120 24 40 85 85 85
121 24 40 83 83 83
122 24 40 85 85 85
123 24 40 83 83 83
124 24 40 85 85 85
125 24 40 85 85 85
126 24 40 87 87 87
127 24 40 87 87 87
128 24 40 83 83 83
140 24 40 87 87 87
141 24 40 83 83 83
142 24 40 85 85 85
143 24 40 87 87 87
144 24 40 85 85 85
112 25 40 83 83 83
113 25 40 87 87 87
114 25 40 87 87 87
115 25 40 83 83 83
116 25 40 85 85 85
117 25 40 87 87 87
118 25 40 85 85 85
119 25 40 87 87 87
120 25 40 83 83 83
121 25 40 87 87 87
122 25 40 85 85 85
123 25 40 87 87 87
124 25 40 83 83 83
125 25 40 85 85 85
126 25 40 85 85 85
127 25 40 83 83 83
128 25 40 87 87 87
140 25 40 85 85 85
141 25 40 85 85 85
142 25 40 83 83 83
143 25 40 83 83 83
112 26 40 87 87 87
113 26 40 83 83 83
114 26 40 83 83 83
115 26 40 83 83 83
116 26 40 87 87 87
117 26 40 85 85 85
118 26 40 83 83 83
119 26 40 85 85 85
120 26 40 87 87 87
121 26 40 85 85 85
122 26 40 85 85 85
123 26 40 85 85 85
124 26 40 85 85 85
125 26 40 85 85 85
126 26 40 87 87 87
127 26 40 83 83 83
128 26 40 83 83 83
140 26 40 87 87 87
141 26 40 87 87 87
142 26 40 83 83 83
143 26 40 85 85 85
113 27 40 83 83 83
114 27 40 83 83 83
115 27 40 87 87 87
116 27 40 83 83 83
117 27 40 85 85 85
118 27 40 87 87 87
119 27 40 83 83 83
120 27 40 87 87 87
121 27 40 83 83 83
122 27 40 83 83 83
123 27 40 85 85 85
124 27 40 83 83 83
125 27 40 85 85 85
126 27 40 83 83 83
127 27 40 87 87 87
128 27 40 87 87 87
140 27 40 83 83 83
141 27 40 87 87 87
142 27 40 83 83 83
114 28 40 85 85 85
115 28 40 83 83 83
116 28 40 85 85 85
117 28 40 83 83 83
118 28 40 87 87 87
119 28 40 87 87 87
120 28 40 83 83 83
121 28 40 85 85 85
122 28 40 83 83 83
123 28 40 83 83 83
124 28 40 83 83 83
125 28 40 85 85 85
126 28 40 83 83 83
127 28 40 83 83 83
128 28 40 85 85 85
129 28 40 83 83 83
139 28 40 87 87 87
140 28 40 85 85 85
141 28 40 83 83 83
115 29 40 87 87 87
116 29 40 87 87 87
117 29 40 87 87 87
118 29 40 87 87 87
119 29 40 87 87 87
120 29 40 83 83 83
121 29 40 87 87 87
122 29 40 85 85 85
123 29 40 83 83 83
124 29 40 83 83 83
125 29 40 87 87 87
126 29 40 87 87 87
127 29 40 83 83 83
128 29 40 85 85 85
129 29 40 87 87 87
130 29 40 83 83 83
138 29 40 87 87 87
139 29 40 85 85 85
140 29 40 83 83 83
116 30 40 83 83 83
117 30 40 83 83 83
118 30 40 87 87 87
119 30 40 83 83 83
120 30 40 85 85 85
121 30 40 85 85 85
122 30 40 83 83 83
123 30 40 83 83 83
124 30 40 87 87 87
125 30 40 87 87 87
126 30 40 83 83 83
127 30 40 85 85 85
128 30 40 85 85 85
129 30 40 87 87 87
130 30 40 85 85 85
131 30 40 85 85 85
132 30 40 87 87 87
133 30 40 85 85 85
134 30 40 87 87 87
135 30 40 85 85 85
136 30 40 85 85 85
137 30 40 83 83 83
138 30 40 87 87 87
139 30 40 87 87 87
117 31 40 83 83 83
118 31 40 83 83 83
119 31 40 85 85 85
120 31 40 83 83 83
121 31 40 87 87 87
122 31 40 87 87 87
123 31 40 83 83 83
124 31 40 83 83 83
125 31 40 87 87 87
126 31 40 83 83 83
127 31 40 83 83 83
128 31 40 83 83 83
129 31 40 83 83 83
130 31 40 87 87 87
131 31 40 87 87 87
132 31 40 87 87 87
133 31 40 87 87 87
134 31 40 83 83 83
135 31 40 87 87 87
136 31 40 85 85 85
137 31 40 87 87 87
138 31 40 83 83 83
118 32 40 85 85 85
119 32 40 85 85 85
120 32 40 87 87 87
121 32 40 85 85 85
122 32 40 85 85 85
123 32 40 85 85 85
124 32 40 85 85 85
125 32 40 85 85 85
126 32 40 87 87 87
127 32 40 85 85 85
128 32 40 83 83 83
129 32 40 83 83 83
130 32 40 85 85 85
131 32 40 83 83 83
132 32 40 87 87 87
133 32 40 83 83 83
134 32 40 83 83 83
135 32 40 83 83 83
136 32 40 85 85 85
137 32 40 85 85 85
118 33 40 87 87 87
119 33 40 83 83 83
120 33 40 87 87 87
121 33 40 85 85 85
122 33 40 83 83 83
123 33 40 87 87 87
124 33 40 83 83 83
125 33 40 87 87 87
126 33 40 83 83 83
127 33 40 83 83 83
128 33 40 87 87 87
129 33 40 83 83 83
130 33 40 87 87 87
131 33 40 87 87 87
132 33 40 85 85 85
133 33 40 87 87 87
134 33 40 85 85 85
135 33 40 83 83 83
136 33 40 83 83 83
137 33 40 85 85 85
118 34 40 87 87 87
122 34 40 83 83 83
123 34 40 85 85 85
124 34 40 85 85 85
125 34 40 87 87 87
130 34 40 83 83 83
131 34 40 85 85 85
132 34 40 83 83 83
133 34 40 85 85 85
137 34 40 85 85 85
117 35 40 83 83 83
118 35 40 85 85 85
119 35 40 87 87 87
120 35 40 87 87 87
121 35 40 87 87 87
124 35 40 85 85 85
125 35 40 83 83 83
130 35 40 83 83 83
131 35 40 87 87 87
134 35 40 87 87 87
135 35 40 83 83 83
136 35 40 83 83 83
137 35 40 83 83 83
138 35 40 87 87 87
117 36 40 83 83 83
118 36 40 87 87 87
119 36 40 83 83 83
120 36 40 85 85 85
121 36 40 83 83 83
122 36 40 83 83 83
123 36 40 87 87 87
125 36 40 87 87 87
130 36 40 87 87 87
132 36 40 87 87 87
133 36 40 87 87 87
134 36 40 85 85 85
135 36 40 83 83 83
136 36 40 83 83 83
137 36 40 83 83 83
138 36 40 83 83 83
117 37 40 83 83 83
118 37 40 83 83 83
119 37 40 83 83 83
120 37 40 85 85 85
121 37 40 87 87 87
122 37 40 85 85 85
123 37 40 87 87 87
125 37 40 85 85 85
126 37 40 85 85 85
127 37 40 85 85 85
128 37 40 87 87 87
129 37 40 85 85 85
130 37 40 83 83 83
132 37 40 83 83 83
133 37 40 83 83 83
134 37 40 85 85 85
135 37 40 87 87 87
136 37 40 85 85 85
137 37 40 83 83 83
138 37 40 83 83 83
117 38 40 83 83 83
118 38 40 87 87 87
119 38 40 83 83 83
120 38 40 83 83 83
121 38 40 83 83 83
122 38 40 85 85 85
123 38 40 85 85 85
125 38 40 87 87 87
126 38 40 83 83 83
127 38 40 85 85 85
128 38 40 87 87 87
129 38 40 83 83 83
130 38 40 87 87 87
132 38 40 83 83 83
133 38 40 85 85 85
134 38 40 87 87 87
135 38 40 85 85 85
136 38 40 83 83 83
137 38 40 85 85 85
138 38 40 87 87 87
119 39 40 85 85 85
120 39 40 85 85 85
121 39 40 85 85 85
122 39 40 87 87 87
123 39 40 87 87 87
125 39 40 87 87 87
126 39 40 87 87 87
127 39 40 85 85 85
128 39 40 87 87 87
129 39 40 83 83 83
130 39 40 87 87 87
132 39 40 87 87 87
133 39 40 85 85 85
134 39 40 83 83 83
135 39 40 85 85 85
136 39 40 83 83 83
122 40 40 87 87 87
123 40 40 87 87 87
124 40 40 87 87 87
125 40 40 83 83 83
126 40 40 83 83 83
127 40 40 87 87 87
128 40 40 83 83 83
129 40 40 83 83 83
130 40 40 83 83 83
131 40 40 85 85 85
132 40 40 83 83 83
133 40 40 83 83 83
115 13 41 85 85 85
116 13 41 85 85 85
118 13 41 87 87 87
119 13 41 83 83 83
113 14 41 87 87 87
114 14 41 83 83 83
115 14 41 83 83 83
116 14 41 83 83 83
117 14 41 85 85 85
118 14 41 87 87 87
119 14 41 85 85 85
120 14 41 83 83 83
121 14 41 85 85 85
112 15 41 83 83 83
113 15 41 83 83 83
114 15 41 83 83 83
115 15 41 87 87 87
116 15 41 85 85 85
117 15 41 85 85 85
118 15 41 83 83 83
119 15 41 85 85 85
120 15 41 83 83 83
121 15 41 85 85 85
122 15 41 85 85 85
112 16 41 85 85 85
113 16 41 85 85 85
114 16 41 87 87 87
115 16 41 85 85 85
116 16 41 83 83 83
117 16 41 85 85 85
118 16 41 85 85 85
119 16 41 85 85 85
120 16 41 85 85 85
121 16 41 83 83 83
122 16 41 83 83 83
112 17 41 85 85 85
113 17 41 85 85 85
114 17 41 83 83 83
115 17 41 85 85 85
116 17 41 87 87 87
117 17 41 87 87 87
118 17 41 85 85 85
119 17 41 87 87 87
120 17 41 85 85 85
121 17 41 83 83 83
122 17 41 85 85 85
112 18 41 83 83 83
113 18 41 83 83 83
114 18 41 83 83 83
115 18 41 83 83 83
116 18 41 87 87 87
117 18 41 87 87 87
118 18 41 83 83 83
119 18 41 85 85 85
120 18 41 83 83 83
121 18 41 87 87 87
122 18 41 85 85 85
131 18 41 87 87 87
132 18 41 85 85 85
133 18 41 87 87 87
134 18 41 85 85 85
135 18 41 83 83 83
136 18 41 83 83 83
137 18 41 85 85 85
112 19 41 83 83 83
113 19 41 87 87 87
114 19 41 87 87 87
115 19 41 85 85 85
116 19 41 83 83 83
117 19 41 83 83 83
118 19 41 87 87 87
119 19 41 83 83 83
120 19 41 83 83 83
121 19 41 87 87 87
122 19 41 87 87 87
130 19 41 85 85 85
138 19 41 83 83 83
112 20 41 83 83 83
113 20 41 83 83 83
114 20 41 85 85 85
115 20 41 87 87 87
116 20 41 83 83 83
117 20 41 85 85 85
118 20 41 85 85 85
119 20 41 85 85 85
120 20 41 83 83 83
121 20 41 83 83 83
122 20 41 87 87 87
129 20 41 87 87 87
139 20 41 85 85 85
113 21 41 83 83 83
114 21 41 87 87 87
115 21 41 83 83 83
116 21 41 85 85 85
117 21 41 87 87 87
118 21 41 85 85 85
119 21 41 83 83 83
120 21 41 85 85 85
121 21 41 83 83 83
128 21 41 87 87 87
140 21 41 87 87 87
128 22 41 87 87 87
140 22 41 85 85 85
128 23 41 83 83 83
140 23 41 87 87 87
128 24 41 87 87 87
140 24 41 85 85 85
118 25 41 85 85 85
119 25 41 83 83 83
120 25 41 85 85 85
128 25 41 83 83 83
140 25 41 87 87 87
117 26 41 83 83 83
118 26 41 85 85 85
119 26 41 85 85 85
120 26 41 85 85 85
121 26 41 87 87 87
128 26 41 85 85 85
140 26 41 83 83 83
117 27 41 83 83 83
118 27 41 87 87 87
119 27 41 87 87 87
120 27 41 87 87 87
121 27 41 87 87 87
128 27 41 87 87 87
140 27 41 83 83 83
117 28 41 83 83 83
118 28 41 87 87 87
119 28 41 83 83 83
120 28 41 85 85 85
121 28 41 85 85 85
129 28 41 83 83 83
139 28 41 85 85 85
118 29 41 87 87 87
119 29 41 87 87 87
120 29 41 83 83 83
130 29 41 85 85 85
138 29 41 87 87 87
131 30 41 87 87 87
132 30 41 83 83 83
133 30 41 87 87 87
134 30 41 87 87 87
135 30 41 85 85 85
136 30 41 85 85 85
137 30 41 87 87 87
115 13 42 87 87 87
116 13 42 83 83 83
118 13 42 87 87 87
119 13 42 83 83 83
115 14 42 85 85 85
116 14 42 83 83 83
118 14 42 85 85 85
119 14 42 83 83 83
115 15 42 83 83 83
116 15 42 83 83 83
118 15 42 87 87 87
119 15 42 85 85 85
115 16 42 87 87 87
116 16 42 87 87 87
118 16 42 87 87 87
119 16 42 83 83 83
131 18 42 83 83 83
132 18 42 87 87 87
136 18 42 87 87 87
137 18 42 83 83 83
115 19 42 85 85 85
116 19 42 83 83 83
117 19 42 87 87 87
118 19 42 83 83 83
119 19 42 85 85 85
130 19 42 83 83 83
133 19 42 31 31 31
134 19 42 31 31 31
135 19 42 31 31 31
138 19 42 85 85 85
129 20 42 83 83 83
139 20 42 83 83 83
128 21 42 87 87 87
140 21 42 85 85 85
128 22 42 83 83 83
140 22 42 85 85 85
129 23 42 31 31 31
139 23 42 31 31 31
129 24 42 31 31 31
139 24 42 31 31 31
129 25 42 31 31 31
139 25 42 31 31 31
128 26 42 87 87 87
140 26 42 83 83 83
118 27 42 87 87 87
119 27 42 83 83 83
120 27 42 85 85 85
128 27 42 85 85 85
140 27 42 83 83 83
129 28 42 87 87 87
139 28 42 85 85 85
130 29 42 83 83 83
133 29 42 31 31 31
134 29 42 31 31 31
135 29 42 31 31 31
138 29 42 85 85 85
131 30 42 85 85 85
132 30 42 87 87 87
136 30 42 85 85 85
137 30 42 85 85 85
132 18 43 83 83 83
133 18 43 83 83 83
134 18 43 87 87 87
135 18 43 85 85 85
136 18 43 85 85 85
131 19 43 83 83 83
132 19 43 87 87 87
133 19 43 83 83 83
134 19 43 87 87 87
135 19 43 87 87 87
136 19 43 87 87 87
137 19 43 87 87 87
130 20 43 85 85 85
131 20 43 85 85 85
132 20 43 87 87 87
133 20 43 85 85 85
134 20 43 83 83 83
135 20 43 85 85 85
136 20 43 83 83 83
137 20 43 87 87 87
138 20 43 85 85 85
129 21 43 87 87 87
130 21 43 87 87 87
131 21 43 87 87 87
132 21 43 85 85 85
133 21 43 83 83 83
134 21 43 85 85 85
135 21 43 83 83 83
136 21 43 85 85 85
137 21 43 83 83 83
138 21 43 87 87 87
139 21 43 87 87 87
128 22 43 85 85 85
129 22 43 83 83 83
130 22 43 85 85 85
131 22 43 85 85 85
132 22 43 85 85 85
133 22 43 85 85 85
134 22 43 85 85 85
135 22 43 85 85 85
136 22 43 85 85 85
137 22 43 83 83 83
138 22 43 83 83 83
139 22 43 85 85 85
140 22 43 85 85 85
128 23 43 83 83 83
129 23 43 85 85 85
130 23 43 87 87 87
131 23 43 83 83 83
132 23 43 85 85 85
133 23 43 87 87 87
134 23 43 83 83 83
135 23 43 87 87 87
136 23 43 85 85 85
137 23 43 85 85 85
138 23 43 85 85 85
139 23 43 83 83 83
140 23 43 87 87 87
128 24 43 85 85 85
129 24 43 83 83 83
130 24 43 83 83 83
131 24 43 83 83 83
132 24 43 85 85 85
133 24 43 85 85 85
134 24 43 87 87 87
135 24 43 85 85 85
136 24 43 83 83 83
137 24 43 85 85 85
138 24 43 87 87 87
139 24 43 87 87 87
140 24 43 85 85 85
128 25 43 85 85 85
129 25 43 85 85 85
130 25 43 83 83 83
131 25 43 83 83 83
132 25 43 87 87 87
133 25 43 87 87 87
134 25 43 85 85 85
135 25 43 83 83 83
136 25 43 83 83 83
137 25 43 83 83 83
138 25 43 83 83 83
139 25 43 83 83 83
140 25 43 87 87 87
128 26 43 83 83 83
129 26 43 85 85 85
130 26 43 87 87 87
131 26 43 85 85 85
132 26 43 87 87 87
133 26 43 83 83 83
134 26 43 83 83 83
135 26 43 87 87 87
136 26 43 87 87 87
137 26 43 87 87 87
138 26 43 85 85 85
139 26 43 83 83 83
140 26 43 83 83 83
129 27 43 83 83 83
130 27 43 83 83 83
131 27 43 83 83 83
132 27 43 83 83 83
133 27 43 87 87 87
134 27 43 87 87 87
135 27 43 87 87 87
136 27 43 87 87 87
137 27 43 85 85 85
138 27 43 83 83 83
139 27 43 87 87 87
130 28 43 85 85 85
131 28 43 83 83 83
132 28 43 85 85 85
133 28 43 87 87 87
134 28 43 83 83 83
135 28 43 83 83 83
136 28 43 87 87 87
137 28 43 85 85 85
138 28 43 85 85 85
131 29 43 87 87 87
132 29 43 83 83 83
133 29 43 85 85 85
134 29 43 87 87 87
135 29 43 85 85 85
136 29 43 83 83 83
137 29 43 87 87 87
132 30 43 83 83 83
133 30 43 85 85 85
134 30 43 85 85 85
135 30 43 85 85 85
136 30 43 85 85 85
132 18 44 83 83 83
133 18 44 85 85 85
134 18 44 87 87 87
135 18 44 83 83 83
136 18 44 85 85 85
131 19 44 87 87 87
137 19 44 85 85 85
130 20 44 87 87 87
132 20 44 87 87 87
133 20 44 87 87 87
134 20 44 83 83 83
135 20 44 87 87 87
136 20 44 87 87 87
138 20 44 85 85 85
129 21 44 85 85 85
131 21 44 85 85 85
132 21 44 83 83 83
133 21 44 85 85 85
134 21 44 85 85 85
135 21 44 85 85 85
136 21 44 87 87 87
137 21 44 83 83 83
139 21 44 87 87 87
128 22 44 87 87 87
130 22 44 87 87 87
131 22 44 85 85 85
132 22 44 85 85 85
133 22 44 87 87 87
134 22 44 85 85 85
135 22 44 87 87 87
136 22 44 87 87 87
137 22 44 83 83 83
138 22 44 83 83 83
140 22 44 87 87 87
128 23 44 83 83 83
130 23 44 87 87 87
131 23 44 85 85 85
132 23 44 83 83 83
133 23 44 85 85 85
134 23 44 85 85 85
135 23 44 83 83 83
136 23 44 85 85 85
137 23 44 87 87 87
138 23 44 85 85 85
140 23 44 85 85 85
128 24 44 85 85 85
130 24 44 83 83 83
131 24 44 83 83 83
132 24 44 85 85 85
133 24 44 83 83 83
134 24 44 87 87 87
135 24 44 85 85 85
136 24 44 87 87 87
137 24 44 85 85 85
138 24 44 85 85 85
140 24 44 87 87 87
128 25 44 85 85 85
130 25 44 85 85 85
131 25 44 83 83 83
132 25 44 85 85 85
133 25 44 87 87 87
134 25 44 87 87 87
135 25 44 85 85 85
136 25 44 87 87 87
137 25 44 85 85 85
138 25 44 83 83 83
140 25 44 85 85 85
128 26 44 85 85 85
130 26 44 87 87 87
131 26 44 83 83 83
132 26 44 87 87 87
133 26 44 87 87 87
134 26 44 83 83 83
135 26 44 87 87 87
136 26 44 87 87 87
137 26 44 83 83 83
138 26 44 83 83 83
140 26 44 83 83 83
129 27 44 87 87 87
131 27 44 85 85 85
132 27 44 87 87 87
133 27 44 85 85 85
134 27 44 85 85 85
135 27 44 83 83 83
136 27 44 85 85 85
137 27 44 85 85 85
139 27 44 83 83 83
130 28 44 83 83 83
132 28 44 85 85 85
133 28 44 83 83 83
134 28 44 87 87 87
135 28 44 85 85 85
136 28 44 85 85 85
138 28 44 83 83 83
131 29 44 83 83 83
137 29 44 85 85 85
132 30 44 83 83 83
133 30 44 87 87 87
134 30 44 83 83 83
135 30 44 83 83 83
136 30 44 87 87 87
